Workbook
Name solver_adj: 'Formação de Preço de Venda'!$G$14
Name solver_cvg: 0.0001
Name solver_drv: 1
Name solver_eng: 1
Name solver_est: 1
Name solver_itr: 2147483647
Name solver_mip: 2147483647
Name solver_mni: 30
Name solver_mrt: 0.075
Name solver_msl: 2
Name solver_neg: 1
Name solver_nod: 2147483647
Name solver_num: 0
Name solver_nwt: 1
Name solver_opt: 'Formação de Preço de Venda'!$BH$14
Name solver_pre: 0.000001
Name solver_rbv: 1
Name solver_rlx: 2
Name solver_rsd: 0
Name solver_scl: 1
Name solver_sho: 2
Name solver_ssz: 100
Name solver_tim: 2147483647
Name solver_tol: 0.01
Name solver_typ: 3
Name solver_val: 0.2
Name solver_ver: 3

Sheet Formação de Preço de Venda
AZ2: =SUM(AZ14:AZ455) -> 5867.17 | BA2: =SUM(BA14:BA455) -> 0 | BB2: =SUM(BB14:BB455) -> 0 | BC2: =SUM(BC14:BC455) -> 0 | BD2: =SUM(BD14:BD455) -> 910.3367 | BE2: =SUM(BE14:BE455) -> 650.2405 | BF2: =SUM(BF14:BF455) -> 7427.7472 | BG2: =SUM(BG14:BG455) -> 5577.0628 | BH2: =BG2/I2 -> #DIV/0!
A3: Preencher | B3: Fórmula | F3: Fórmula | G3: Preencher | H3: Preencher | I3: Fórmula | AZ3: Fórmula | BA3: Fórmula | BE3: Fórmula | BG3: Fórmula | BH3: Fórmula
A4: Código | B4: Descrição do Produto | D4: Tipo | E4: Tempo de ciclo (Qtd Hora) | F4: Preço de | G4: Preço | H4: Qtd | I4: Faturamento | AZ4: Decomposição do Preço Calculado
J5: 1. Materia prima | N5: TTL (1) | O5: 2.Processo | R5: TTL (2) | S5: 3.Embalagem | W5: TTL (3) | X5: 4.Refugo | Y5: TTL (4) | Z5: 5.Outras custos Industriais | AD5: TTL (5) | AE5: 6.Mark up | AF5: TTL (6) | AG5: 7.Outros Despesas (Indireto) - 15% | AL5: TTL (7) | AN5: 8.Impostos(Fora) | AP5: TTL (8) | AQ5: 9.Impostos(Dentro) | AT5: TTL (9) | AU5: 10.Comissao | AV5: TTL (10) | AW5: TTL (11) PRECO MINIMO SUGERIDO | BA5: Impostos
F6: Venda Mínimo | G6: Praticado | J6: Insumo | K6: Frete | L6: TCIF | M6: FTI | O6: Mao de obra direta (Hora/homem) | S6: Balde | T6: Pallet | U6: Filme | V6: Chapa tex | X6: Perda no processo | Z6: Energia | AA6: Agua | AB6: Equipamento Maquina | AC6: 0 | AE6: 0.25 | AG6: Mao de obra Ind | AH6: Frete Expedicao | AI6: Aluguel 2 | AJ6: IPTU | AK6: Comunicacao | AL6: 0.15 | AM6: CUSTO LIQUIDO TOTAL | AN6: IRPJ | AO6: CSLL | AQ6: ICMS (FMPES+UEA) | AR6: PIS | AS6: COFINS | AY6: DIFERENCA | BA6: PIS | BB6: COFINS | BC6: IPI | BD6: ICMS | BE6: Comissão | BF6: Custos Total | BG6: R$ Lucro | BH6: % Lucro Efetivo
S7: Galao | T7: 110 | U7: 110 | V7: 110 | AA7: Custo mês | AB7: Custo mês | AC7: 0 | AE7: 0.25 | AL7: 0 | AY7: CUSTO TOTAL | AZ7: Custos Diretos
S8: Balde | T8: 36 | U8: 36 | V8: 36 | AA8: 4000 | AB8: 3800 | AC8: 0 | AY8: VS
S9: Latao | T9: 40 | U9: 40 | V9: 36 | AA9: Qtd hora mês | AB9: Qtd hora mês | AC9: Qtd hora mês | AY9: PRECO PRATICADO
S10: Lata | T10: 36 | U10: 36 | V10: 36 | AA10: 192 | AB10: 192 | AC10: 192
O11: Operador | P11: Lider | Q11: Logistica | S11: Latinha | T11: 240 | U11: 110 | V11: 110 | Z11: KWH | AA11: C/ Hora | AB11: C/ Hora | AC11: C/ Hora
L12: 0.01 | M12: 0.01 | O12: 18.1 | P12: 28.29 | Q12: 28.29 | T12: 25 | U12: 43 | V12: 12 | X12: 0.01 | Z12: 0.83 | AA12: =AA8/AA10 -> 20.833333 | AB12: =AB8/AB10 -> 19.791667 | AC12: =AC8/AC10 -> 0 | AG12: =SUM('Despesas Fixas'!F46:F50,Salários!J7,Salários!J21) -> 65735.04 | AH12: =1740+800 -> 2540 | AI12: ='Despesas Fixas'!F9+'Despesas Fixas'!F10 -> 16980 | AJ12: =1410 -> 1410 | AK12: =388+61.61+15000+3212 -> 18661.61 | AN12: 0.012 | AO12: 0.0108 | AQ12: 0.0835 | AR12: 0 | AS12: 0 | AU12: 0.05 | BA12: 0 | BB12: 0 | BC12: 0 | BD12: 0.07 | BE12: 0.05
O13: 2 | P13: 1 | Q13: 1
A14: PRD00001 | B14: =IFERROR(VLOOKUP(A14,'Tabela de Produtos'!A:B,2,0),"Preencher Cód. Produto") -> BRAZIMIL MASSA CORRIDA 4,0KG | D14: Galao | E14: 100 | F14: =IF(A14=0,0,VLOOKUP(A14,'Tabela de Produtos'!A:W,23,0)) -> 8.3 | G14: 15.99 | H14: 1 | I14: =G14*H14 -> 15.99 | J14: =VLOOKUP(B14,'Tabela de Produtos'!B:M,12,FALSE()) -> 3 | K14: =VLOOKUP(B14,'Tabela de Produtos'!B:P,15,FALSE()) -> 1.24 | L14: =J14*1% -> 0.03 | M14: =J14*1% -> 0.03 | N14: =J14+K14+L14+M14 -> 4.3 | O14: =($O$12/E14)*$O$13 -> 0.362 | P14: =($P$12/E14)*$P$13 -> 0.2829 | Q14: =($Q$12/E14)*$Q$13 -> 0.2829 | R14: =O14+P14+Q14 -> 0.9278 | S14: =VLOOKUP(B14,'Tabela de Produtos'!B:N,13,FALSE()) -> 3.06 | T14: =$T$12/$T$7 -> 0.22727273 | U14: =$U$12/$U$7 -> 0.39090909 | V14: =$V$12/$V$7 -> 0.10909091 | W14: =S14+T14+U14+V14 -> 3.7872727 | X14: =(N14+R14+W14)*1% -> 0.090150727 | Y14: =X14 -> 0.090150727 | Z14: =$Z$12/E14 -> 0.0083 | AA14: =$AA$12/E14 -> 0.20833333 | AB14: =$AB$12/E14 -> 0.19791667 | AC14: =$AC$12/E14 -> 0 | AD14: =Z14+AA14+AB14+AC14 -> 0.41455 | AE14: =(AD14+Y14+W14+R14+N14)*$AE$7 -> 2.3799434 | AF14: =AE14 -> 2.3799434 | AL14: =(AD14+Y14+W14+R14+N14)*$AL$7 -> 0 | AM14: =AL14+AF14+AD14+Y14+W14+R14+N14 -> 11.899717 | AN14: =AM14*$AN$12 -> 0.1427966 | AO14: =AM14*$AO$12 -> 0.12851694 | AP14: =AO14+AN14 -> 0.27131354 | AQ14: =AM14*$AQ$12 -> 0.99362635 | AR14: =AM14*$AR$12 -> 0 | AS14: =AM14*$AS$12 -> 0 | AT14: =AQ14+AR14+AS14 -> 0.99362635 | AU14: =AM14*$AU$12 -> 0.59498584 | AV14: =AU14 -> 0.59498584 | AW14: =AM14+AP14+AT14+AV14 -> 13.759643 | AX14: =AY14/AW14 -> 0.16209414 | AY14: =I14-AW14 -> 2.2303574 | AZ14: =IFERROR(H14*VLOOKUP(A14,'Tabela de Produtos'!A:Q,17,0),0) -> 7.3 | BA14: =$I14*BA$12 -> 0 | BB14: =$I14*BB$12 -> 0 | BC14: =$I14*BC$12 -> 0 | BD14: =$I14*BD$12 -> 1.1193 | BE14: =I14*$BE$12 -> 0.7995 | BF14: =SUM(AZ14:BE14) -> 9.2188 | BG14: =I14-BF14 -> 6.7712 | BH14: =IF(F14="Cadastrar Ficha de Produção",0,IFERROR(BG14/I14,0)) -> 0.42346467
A15: PRD00002 | B15: =IFERROR(VLOOKUP(A15,'Tabela de Produtos'!A:B,2,0),"Preencher Cód. Produto") -> BRAZIMIL MASSA CORRIDA 20,0 KG | D15: Balde | E15: 33 | F15: =IF(A15=0,0,VLOOKUP(A15,'Tabela de Produtos'!A:W,23,0)) -> 33.88 | G15: 37.5 | H15: 1 | I15: =G15*H15 -> 37.5 | J15: =VLOOKUP(B15,'Tabela de Produtos'!B:M,12,FALSE()) -> 15 | K15: =VLOOKUP(B15,'Tabela de Produtos'!B:P,15,FALSE()) -> 6.2 | L15: =J15*1% -> 0.15 | M15: =J15*1% -> 0.15 | N15: =J15+K15+L15+M15 -> 21.5 | O15: =0.54*$O$13 -> 1.08 | P15: =0.85*$P$13 -> 0.85 | Q15: =0.85*$Q$13 -> 0.85 | R15: =O15+P15+Q15 -> 2.78 | S15: =VLOOKUP(B15,'Tabela de Produtos'!B:N,13,FALSE()) -> 8.61 | T15: =$T$12/$T$8 -> 0.69444444 | U15: =$U$12/$U$8 -> 1.1944444 | V15: =$V$12/$V$8 -> 0.33333333 | W15: =S15+T15+U15+V15 -> 10.832222 | X15: =(N15+R15+W15)*1% -> 0.35112222 | Y15: =X15 -> 0.35112222 | Z15: =$Z$12/E15 -> 0.025151515 | AA15: =$AA$12/E15 -> 0.63131313 | AB15: =$AB$12/E15 -> 0.59974747 | AC15: =$AC$12/E15 -> 0 | AD15: =Z15+AA15+AB15+AC15 -> 1.2562121 | AE15: =(AD15+Y15+W15+R15+N15)*$AE$7 -> 9.1798891 | AF15: =AE15 -> 9.1798891 | AL15: =(AD15+Y15+W15+R15+N15)*$AL$7 -> 0 | AM15: =AL15+AF15+AD15+Y15+W15+R15+N15 -> 45.899446 | AN15: =AM15*$AN$12 -> 0.55079335 | AO15: =AM15*$AO$12 -> 0.49571401 | AP15: =AO15+AN15 -> 1.0465074 | AQ15: =AM15*$AQ$12 -> 3.8326037 | AR15: =AM15*$AR$12 -> 0 | AS15: =AM15*$AS$12 -> 0 | AT15: =AQ15+AR15+AS15 -> 3.8326037 | AU15: =AM15*$AU$12 -> 2.2949723 | AV15: =AU15 -> 2.2949723 | AW15: =AM15+AP15+AT15+AV15 -> 53.073529 | AX15: =AY15/AW15 -> -0.29343308 | AY15: =I15-AW15 -> -15.573529 | AZ15: =IFERROR(H15*VLOOKUP(A15,'Tabela de Produtos'!A:Q,17,0),0) -> 29.81 | BA15: =$I15*BA$12 -> 0 | BB15: =$I15*BB$12 -> 0 | BC15: =$I15*BC$12 -> 0 | BD15: =$I15*BD$12 -> 2.625 | BE15: =I15*$BE$12 -> 1.875 | BF15: =SUM(AZ15:BE15) -> 34.31 | BG15: =I15-BF15 -> 3.19 | BH15: =IF(F15="Cadastrar Ficha de Produção",0,IFERROR(BG15/I15,0)) -> 0.085066667
A16: PRD00003 | B16: =IFERROR(VLOOKUP(A16,'Tabela de Produtos'!A:B,2,0),"Preencher Cód. Produto") -> BRAZIMIL SELADOR ACRILICO 3L | D16: Galao | E16: 100 | F16: =IF(A16=0,0,VLOOKUP(A16,'Tabela de Produtos'!A:W,23,0)) -> 7.54 | G16: 17.99 | H16: 1 | I16: =G16*H16 -> 17.99 | J16: =VLOOKUP(B16,'Tabela de Produtos'!B:M,12,FALSE()) -> 2.64 | K16: =VLOOKUP(B16,'Tabela de Produtos'!B:P,15,FALSE()) -> 0.93 | L16: =J16*1% -> 0.0264 | M16: =J16*1% -> 0.0264 | N16: =J16+K16+L16+M16 -> 3.6228 | O16: =($O$12/E16)*$O$13 -> 0.362 | P16: =($P$12/E16)*$P$13 -> 0.2829 | Q16: =($Q$12/E16)*$Q$13 -> 0.2829 | R16: =O16+P16+Q16 -> 0.9278 | S16: =VLOOKUP(B16,'Tabela de Produtos'!B:N,13,FALSE()) -> 3.06 | T16: =$T$12/$T$7 -> 0.22727273 | U16: =$U$12/$U$7 -> 0.39090909 | V16: =$V$12/$V$7 -> 0.10909091 | W16: =S16+T16+U16+V16 -> 3.7872727 | X16: =(N16+R16+W16)*1% -> 0.083378727 | Y16: =X16 -> 0.083378727 | Z16: =$Z$12/E16 -> 0.0083 | AA16: =$AA$12/E16 -> 0.20833333 | AB16: =$AB$12/E16 -> 0.19791667 | AC16: =$AC$12/E16 -> 0 | AD16: =Z16+AA16+AB16+AC16 -> 0.41455 | AE16: =(AD16+Y16+W16+R16+N16)*$AE$7 -> 2.2089504 | AF16: =AE16 -> 2.2089504 | AL16: =(AD16+Y16+W16+R16+N16)*$AL$7 -> 0 | AM16: =AL16+AF16+AD16+Y16+W16+R16+N16 -> 11.044752 | AN16: =AM16*$AN$12 -> 0.13253702 | AO16: =AM16*$AO$12 -> 0.11928332 | AP16: =AO16+AN16 -> 0.25182034 | AQ16: =AM16*$AQ$12 -> 0.92223678 | AR16: =AM16*$AR$12 -> 0 | AS16: =AM16*$AS$12 -> 0 | AT16: =AQ16+AR16+AS16 -> 0.92223678 | AU16: =AM16*$AU$12 -> 0.55223759 | AV16: =AU16 -> 0.55223759 | AW16: =AM16+AP16+AT16+AV16 -> 12.771047 | AX16: =AY16/AW16 -> 0.40865511 | AY16: =I16-AW16 -> 5.2189535 | AZ16: =IFERROR(H16*VLOOKUP(A16,'Tabela de Produtos'!A:Q,17,0),0) -> 6.63 | BA16: =$I16*BA$12 -> 0 | BB16: =$I16*BB$12 -> 0 | BC16: =$I16*BC$12 -> 0 | BD16: =$I16*BD$12 -> 1.2593 | BE16: =I16*$BE$12 -> 0.8995 | BF16: =SUM(AZ16:BE16) -> 8.7888 | BG16: =I16-BF16 -> 9.2012 | BH16: =IF(F16="Cadastrar Ficha de Produção",0,IFERROR(BG16/I16,0)) -> 0.51146192
A17: PRD00004 | B17: =IFERROR(VLOOKUP(A17,'Tabela de Produtos'!A:B,2,0),"Preencher Cód. Produto") -> BRAZIMIL SELADOR ACRILICO 15L | D17: Balde | E17: 28 | F17: =IF(A17=0,0,VLOOKUP(A17,'Tabela de Produtos'!A:W,23,0)) -> 30.07 | G17: 66.49 | H17: 1 | I17: =G17*H17 -> 66.49 | J17: =VLOOKUP(B17,'Tabela de Produtos'!B:M,12,FALSE()) -> 13.2 | K17: =VLOOKUP(B17,'Tabela de Produtos'!B:P,15,FALSE()) -> 4.65 | L17: =J17*1% -> 0.132 | M17: =J17*1% -> 0.132 | N17: =J17+K17+L17+M17 -> 18.114 | O17: =($O$12/E17)*$O$13 -> 1.2928571 | P17: =($P$12/E17)*$P$13 -> 1.0103571 | Q17: =($Q$12/E17)*$Q$13 -> 1.0103571 | R17: =O17+P17+Q17 -> 3.3135714 | S17: =VLOOKUP(B17,'Tabela de Produtos'!B:N,13,FALSE()) -> 8.61 | T17: =$T$12/$T$8 -> 0.69444444 | U17: =$U$12/$U$8 -> 1.1944444 | V17: =$V$12/$V$8 -> 0.33333333 | W17: =S17+T17+U17+V17 -> 10.832222 | X17: =(N17+R17+W17)*1% -> 0.32259794 | Y17: =X17 -> 0.32259794 | Z17: =$Z$12/E17 -> 0.029642857 | AA17: =$AA$12/E17 -> 0.74404762 | AB17: =$AB$12/E17 -> 0.70684524 | AC17: =$AC$12/E17 -> 0 | AD17: =Z17+AA17+AB17+AC17 -> 1.4805357 | AE17: =(AD17+Y17+W17+R17+N17)*$AE$7 -> 8.5157318 | AF17: =AE17 -> 8.5157318 | AL17: =(AD17+Y17+W17+R17+N17)*$AL$7 -> 0 | AM17: =AL17+AF17+AD17+Y17+W17+R17+N17 -> 42.578659 | AN17: =AM17*$AN$12 -> 0.51094391 | AO17: =AM17*$AO$12 -> 0.45984952 | AP17: =AO17+AN17 -> 0.97079343 | AQ17: =AM17*$AQ$12 -> 3.555318 | AR17: =AM17*$AR$12 -> 0 | AS17: =AM17*$AS$12 -> 0 | AT17: =AQ17+AR17+AS17 -> 3.555318 | AU17: =AM17*$AU$12 -> 2.128933 | AV17: =AU17 -> 2.128933 | AW17: =AM17+AP17+AT17+AV17 -> 49.233704 | AX17: =AY17/AW17 -> 0.35049763 | AY17: =I17-AW17 -> 17.256296 | AZ17: =IFERROR(H17*VLOOKUP(A17,'Tabela de Produtos'!A:Q,17,0),0) -> 26.46 | BA17: =$I17*BA$12 -> 0 | BB17: =$I17*BB$12 -> 0 | BC17: =$I17*BC$12 -> 0 | BD17: =$I17*BD$12 -> 4.6543 | BE17: =I17*$BE$12 -> 3.3245 | BF17: =SUM(AZ17:BE17) -> 34.4388 | BG17: =I17-BF17 -> 32.0512 | BH17: =IF(F17="Cadastrar Ficha de Produção",0,IFERROR(BG17/I17,0)) -> 0.48204542
A18: PRD00005 | B18: =IFERROR(VLOOKUP(A18,'Tabela de Produtos'!A:B,2,0),"Preencher Cód. Produto") -> BRAZIMIL SELADORA PARA MADEIRA 0,75L INCOLOR | F18: =IF(A18=0,0,VLOOKUP(A18,'Tabela de Produtos'!A:W,23,0)) -> Cadastrar Ficha de Produção | G18: 0 | H18: 1 | I18: =G18*H18 -> 0 | J18: =VLOOKUP(B18,'Tabela de Produtos'!B:M,12,FALSE()) -> 0 | AY18: =I18-AW18 -> 0 | AZ18: =IFERROR(H18*VLOOKUP(A18,'Tabela de Produtos'!A:Q,17,0),0) -> 0 | BA18: =$I18*BA$12 -> 0 | BB18: =$I18*BB$12 -> 0 | BC18: =$I18*BC$12 -> 0 | BD18: =$I18*BD$12 -> 0 | BE18: =I18*$BE$12 -> 0 | BF18: =SUM(AZ18:BE18) -> 0 | BG18: =I18-BF18 -> 0 | BH18: =IF(F18="Cadastrar Ficha de Produção",0,IFERROR(BG18/I18,0)) -> 0
A19: PRD00006 | B19: =IFERROR(VLOOKUP(A19,'Tabela de Produtos'!A:B,2,0),"Preencher Cód. Produto") -> BRAZIMIL SELADORA PARA MADEIRA 3L INCOLOR | D19: Galao | F19: =IF(A19=0,0,VLOOKUP(A19,'Tabela de Produtos'!A:W,23,0)) -> Cadastrar Ficha de Produção | G19: 0 | H19: 1 | I19: =G19*H19 -> 0 | J19: =VLOOKUP(B19,'Tabela de Produtos'!B:M,12,FALSE()) -> 0 | AY19: =I19-AW19 -> 0 | AZ19: =IFERROR(H19*VLOOKUP(A19,'Tabela de Produtos'!A:Q,17,0),0) -> 0 | BA19: =$I19*BA$12 -> 0 | BB19: =$I19*BB$12 -> 0 | BC19: =$I19*BC$12 -> 0 | BD19: =$I19*BD$12 -> 0 | BE19: =I19*$BE$12 -> 0 | BF19: =SUM(AZ19:BE19) -> 0 | BG19: =I19-BF19 -> 0 | BH19: =IF(F19="Cadastrar Ficha de Produção",0,IFERROR(BG19/I19,0)) -> 0
A20: PRD00007 | B20: =IFERROR(VLOOKUP(A20,'Tabela de Produtos'!A:B,2,0),"Preencher Cód. Produto") -> BRAZIMIL MASSA ACRÍLICA 4KG | D20: Galao | E20: 100 | F20: =IF(A20=0,0,VLOOKUP(A20,'Tabela de Produtos'!A:W,23,0)) -> 12.21 | G20: 19.99 | H20: 1 | I20: =G20*H20 -> 19.99 | J20: =VLOOKUP(B20,'Tabela de Produtos'!B:M,12,FALSE()) -> 6.44 | K20: =VLOOKUP(B20,'Tabela de Produtos'!B:P,15,FALSE()) -> 1.24 | L20: =J20*1% -> 0.0644 | M20: =J20*1% -> 0.0644 | N20: =J20+K20+L20+M20 -> 7.8088 | O20: =($O$12/E20)*$O$13 -> 0.362 | P20: =($P$12/E20)*$P$13 -> 0.2829 | Q20: =($Q$12/E20)*$Q$13 -> 0.2829 | R20: =O20+P20+Q20 -> 0.9278 | S20: =VLOOKUP(B20,'Tabela de Produtos'!B:N,13,FALSE()) -> 3.06 | T20: =$T$12/$T$7 -> 0.22727273 | U20: =$U$12/$U$7 -> 0.39090909 | V20: =$V$12/$V$7 -> 0.10909091 | W20: =S20+T20+U20+V20 -> 3.7872727 | X20: =(N20+R20+W20)*1% -> 0.12523873 | Y20: =X20 -> 0.12523873 | Z20: =$Z$12/E20 -> 0.0083 | AA20: =$AA$12/E20 -> 0.20833333 | AB20: =$AB$12/E20 -> 0.19791667 | AC20: =$AC$12/E20 -> 0 | AD20: =Z20+AA20+AB20+AC20 -> 0.41455 | AE20: =(AD20+Y20+W20+R20+N20)*$AE$7 -> 3.2659154 | AF20: =AE20 -> 3.2659154 | AL20: =(AD20+Y20+W20+R20+N20)*$AL$7 -> 0 | AM20: =AL20+AF20+AD20+Y20+W20+R20+N20 -> 16.329577 | AN20: =AM20*$AN$12 -> 0.19595492 | AO20: =AM20*$AO$12 -> 0.17635943 | AP20: =AO20+AN20 -> 0.37231435 | AQ20: =AM20*$AQ$12 -> 1.3635197 | AR20: =AM20*$AR$12 -> 0 | AS20: =AM20*$AS$12 -> 0 | AT20: =AQ20+AR20+AS20 -> 1.3635197 | AU20: =AM20*$AU$12 -> 0.81647884 | AV20: =AU20 -> 0.81647884 | AW20: =AM20+AP20+AT20+AV20 -> 18.88189 | AX20: =AY20/AW20 -> 0.05868641 | AY20: =I20-AW20 -> 1.1081103 | AZ20: =IFERROR(H20*VLOOKUP(A20,'Tabela de Produtos'!A:Q,17,0),0) -> 10.74 | BA20: =$I20*BA$12 -> 0 | BB20: =$I20*BB$12 -> 0 | BC20: =$I20*BC$12 -> 0 | BD20: =$I20*BD$12 -> 1.3993 | BE20: =I20*$BE$12 -> 0.9995 | BF20: =SUM(AZ20:BE20) -> 13.1388 | BG20: =I20-BF20 -> 6.8512 | BH20: =IF(F20="Cadastrar Ficha de Produção",0,IFERROR(BG20/I20,0)) -> 0.34273137
A21: PRD00008 | B21: =IFERROR(VLOOKUP(A21,'Tabela de Produtos'!A:B,2,0),"Preencher Cód. Produto") -> BRAZIMIL MASSA ACRÍLICA 20KG | D21: Balde | E21: 33 | F21: =IF(A21=0,0,VLOOKUP(A21,'Tabela de Produtos'!A:W,23,0)) -> 53.43 | G21: 72.9 | H21: 1 | I21: =G21*H21 -> 72.9 | J21: =VLOOKUP(B21,'Tabela de Produtos'!B:M,12,FALSE()) -> 32.2 | K21: =VLOOKUP(B21,'Tabela de Produtos'!B:P,15,FALSE()) -> 6.2 | L21: =J21*1% -> 0.322 | M21: =J21*1% -> 0.322 | N21: =J21+K21+L21+M21 -> 39.044 | O21: =0.54*$O$13 -> 1.08 | P21: =0.85*$P$13 -> 0.85 | Q21: =0.85*$Q$13 -> 0.85 | R21: =O21+P21+Q21 -> 2.78 | S21: =VLOOKUP(B21,'Tabela de Produtos'!B:N,13,FALSE()) -> 8.61 | T21: =$T$12/$T$8 -> 0.69444444 | U21: =$U$12/$U$8 -> 1.1944444 | V21: =$V$12/$V$8 -> 0.33333333 | W21: =S21+T21+U21+V21 -> 10.832222 | X21: =(N21+R21+W21)*1% -> 0.52656222 | Y21: =X21 -> 0.52656222 | Z21: =$Z$12/E21 -> 0.025151515 | AA21: =$AA$12/E21 -> 0.63131313 | AB21: =$AB$12/E21 -> 0.59974747 | AC21: =$AC$12/E21 -> 0 | AD21: =Z21+AA21+AB21+AC21 -> 1.2562121 | AE21: =(AD21+Y21+W21+R21+N21)*$AE$7 -> 13.609749 | AF21: =AE21 -> 13.609749 | AL21: =(AD21+Y21+W21+R21+N21)*$AL$7 -> 0 | AM21: =AL21+AF21+AD21+Y21+W21+R21+N21 -> 68.048746 | AN21: =AM21*$AN$12 -> 0.81658495 | AO21: =AM21*$AO$12 -> 0.73492645 | AP21: =AO21+AN21 -> 1.5515114 | AQ21: =AM21*$AQ$12 -> 5.6820703 | AR21: =AM21*$AR$12 -> 0 | AS21: =AM21*$AS$12 -> 0 | AT21: =AQ21+AR21+AS21 -> 5.6820703 | AU21: =AM21*$AU$12 -> 3.4024373 | AV21: =AU21 -> 3.4024373 | AW21: =AM21+AP21+AT21+AV21 -> 78.684765 | AX21: =AY21/AW21 -> -0.07351823 | AY21: =I21-AW21 -> -5.7847647 | AZ21: =IFERROR(H21*VLOOKUP(A21,'Tabela de Produtos'!A:Q,17,0),0) -> 47.01 | BA21: =$I21*BA$12 -> 0 | BB21: =$I21*BB$12 -> 0 | BC21: =$I21*BC$12 -> 0 | BD21: =$I21*BD$12 -> 5.103 | BE21: =I21*$BE$12 -> 3.645 | BF21: =SUM(AZ21:BE21) -> 55.758 | BG21: =I21-BF21 -> 17.142 | BH21: =IF(F21="Cadastrar Ficha de Produção",0,IFERROR(BG21/I21,0)) -> 0.23514403
A22: PRD00009 | B22: =IFERROR(VLOOKUP(A22,'Tabela de Produtos'!A:B,2,0),"Preencher Cód. Produto") -> BRAZIMIL LÁTEX ECONÔMICO INT FOSCO 3L BRANCO NEVE | D22: Galao | E22: 100 | F22: =IF(A22=0,0,VLOOKUP(A22,'Tabela de Produtos'!A:W,23,0)) -> 9.1 | G22: 17.99 | H22: 1 | I22: =G22*H22 -> 17.99 | J22: =VLOOKUP(B22,'Tabela de Produtos'!B:M,12,FALSE()) -> 3.63 | K22: =VLOOKUP(B22,'Tabela de Produtos'!B:P,15,FALSE()) -> 0.93 | L22: =J22*1% -> 0.0363 | M22: =J22*1% -> 0.0363 | N22: =J22+K22+L22+M22 -> 4.6326 | O22: =($O$12/E22)*$O$13 -> 0.362 | P22: =($P$12/E22)*$P$13 -> 0.2829 | Q22: =($Q$12/E22)*$Q$13 -> 0.2829 | R22: =O22+P22+Q22 -> 0.9278 | S22: =VLOOKUP(B22,'Tabela de Produtos'!B:N,13,FALSE()) -> 3.44 | T22: =$T$12/$T$7 -> 0.22727273 | U22: =$U$12/$U$7 -> 0.39090909 | V22: =$V$12/$V$7 -> 0.10909091 | W22: =S22+T22+U22+V22 -> 4.1672727 | X22: =(N22+R22+W22)*1% -> 0.097276727 | Y22: =X22 -> 0.097276727 | Z22: =$Z$12/E22 -> 0.0083 | AA22: =$AA$12/E22 -> 0.20833333 | AB22: =$AB$12/E22 -> 0.19791667 | AC22: =$AC$12/E22 -> 0 | AD22: =Z22+AA22+AB22+AC22 -> 0.41455 | AE22: =(AD22+Y22+W22+R22+N22)*$AE$7 -> 2.5598749 | AF22: =AE22 -> 2.5598749 | AL22: =(AD22+Y22+W22+R22+N22)*$AL$7 -> 0 | AM22: =AL22+AF22+AD22+Y22+W22+R22+N22 -> 12.799374 | AN22: =AM22*$AN$12 -> 0.15359249 | AO22: =AM22*$AO$12 -> 0.13823324 | AP22: =AO22+AN22 -> 0.29182573 | AQ22: =AM22*$AQ$12 -> 1.0687478 | AR22: =AM22*$AR$12 -> 0 | AS22: =AM22*$AS$12 -> 0 | AT22: =AQ22+AR22+AS22 -> 1.0687478 | AU22: =AM22*$AU$12 -> 0.63996872 | AV22: =AU22 -> 0.63996872 | AW22: =AM22+AP22+AT22+AV22 -> 14.799917 | AX22: =AY22/AW22 -> 0.2155474 | AY22: =I22-AW22 -> 3.1900835 | AZ22: =IFERROR(H22*VLOOKUP(A22,'Tabela de Produtos'!A:Q,17,0),0) -> 8 | BA22: =$I22*BA$12 -> 0 | BB22: =$I22*BB$12 -> 0 | BC22: =$I22*BC$12 -> 0 | BD22: =$I22*BD$12 -> 1.2593 | BE22: =I22*$BE$12 -> 0.8995 | BF22: =SUM(AZ22:BE22) -> 10.1588 | BG22: =I22-BF22 -> 7.8312 | BH22: =IF(F22="Cadastrar Ficha de Produção",0,IFERROR(BG22/I22,0)) -> 0.4353085
A23: PRD00010 | B23: =IFERROR(VLOOKUP(A23,'Tabela de Produtos'!A:B,2,0),"Preencher Cód. Produto") -> BRAZIMIL LÁTEX ECONÔMICO INT FOSCO 3L BRANCO GELO | D23: Galao | E23: 100 | F23: =IF(A23=0,0,VLOOKUP(A23,'Tabela de Produtos'!A:W,23,0)) -> 10.39 | G23: 17.99 | H23: 1 | I23: =G23*H23 -> 17.99 | J23: =VLOOKUP(B23,'Tabela de Produtos'!B:M,12,FALSE()) -> 4.77 | K23: =VLOOKUP(B23,'Tabela de Produtos'!B:P,15,FALSE()) -> 0.93 | L23: =J23*1% -> 0.0477 | M23: =J23*1% -> 0.0477 | N23: =J23+K23+L23+M23 -> 5.7954 | O23: =($O$12/E23)*$O$13 -> 0.362 | P23: =($P$12/E23)*$P$13 -> 0.2829 | Q23: =($Q$12/E23)*$Q$13 -> 0.2829 | R23: =O23+P23+Q23 -> 0.9278 | S23: =VLOOKUP(B23,'Tabela de Produtos'!B:N,13,FALSE()) -> 3.44 | T23: =$T$12/$T$7 -> 0.22727273 | U23: =$U$12/$U$7 -> 0.39090909 | V23: =$V$12/$V$7 -> 0.10909091 | W23: =S23+T23+U23+V23 -> 4.1672727 | X23: =(N23+R23+W23)*1% -> 0.10890473 | Y23: =X23 -> 0.10890473 | Z23: =$Z$12/E23 -> 0.0083 | AA23: =$AA$12/E23 -> 0.20833333 | AB23: =$AB$12/E23 -> 0.19791667 | AC23: =$AC$12/E23 -> 0 | AD23: =Z23+AA23+AB23+AC23 -> 0.41455 | AE23: =(AD23+Y23+W23+R23+N23)*$AE$7 -> 2.8534819 | AF23: =AE23 -> 2.8534819 | AL23: =(AD23+Y23+W23+R23+N23)*$AL$7 -> 0 | AM23: =AL23+AF23+AD23+Y23+W23+R23+N23 -> 14.267409 | AN23: =AM23*$AN$12 -> 0.17120891 | AO23: =AM23*$AO$12 -> 0.15408802 | AP23: =AO23+AN23 -> 0.32529693 | AQ23: =AM23*$AQ$12 -> 1.1913287 | AR23: =AM23*$AR$12 -> 0 | AS23: =AM23*$AS$12 -> 0 | AT23: =AQ23+AR23+AS23 -> 1.1913287 | AU23: =AM23*$AU$12 -> 0.71337047 | AV23: =AU23 -> 0.71337047 | AW23: =AM23+AP23+AT23+AV23 -> 16.497405 | AX23: =AY23/AW23 -> 0.090474506 | AY23: =I23-AW23 -> 1.4925946 | AZ23: =IFERROR(H23*VLOOKUP(A23,'Tabela de Produtos'!A:Q,17,0),0) -> 9.14 | BA23: =$I23*BA$12 -> 0 | BB23: =$I23*BB$12 -> 0 | BC23: =$I23*BC$12 -> 0 | BD23: =$I23*BD$12 -> 1.2593 | BE23: =I23*$BE$12 -> 0.8995 | BF23: =SUM(AZ23:BE23) -> 11.2988 | BG23: =I23-BF23 -> 6.6912 | BH23: =IF(F23="Cadastrar Ficha de Produção",0,IFERROR(BG23/I23,0)) -> 0.37193997
A24: PRD00011 | B24: =IFERROR(VLOOKUP(A24,'Tabela de Produtos'!A:B,2,0),"Preencher Cód. Produto") -> BRAZIMIL LÁTEX ECONÔMICO INT FOSCO 3L AREIA | D24: Galao | E24: 100 | F24: =IF(A24=0,0,VLOOKUP(A24,'Tabela de Produtos'!A:W,23,0)) -> 10.87 | G24: 17.99 | H24: 1 | I24: =G24*H24 -> 17.99 | J24: =VLOOKUP(B24,'Tabela de Produtos'!B:M,12,FALSE()) -> 5.19 | K24: =VLOOKUP(B24,'Tabela de Produtos'!B:P,15,FALSE()) -> 0.93 | L24: =J24*1% -> 0.0519 | M24: =J24*1% -> 0.0519 | N24: =J24+K24+L24+M24 -> 6.2238 | O24: =($O$12/E24)*$O$13 -> 0.362 | P24: =($P$12/E24)*$P$13 -> 0.2829 | Q24: =($Q$12/E24)*$Q$13 -> 0.2829 | R24: =O24+P24+Q24 -> 0.9278 | S24: =VLOOKUP(B24,'Tabela de Produtos'!B:N,13,FALSE()) -> 3.44 | T24: =$T$12/$T$7 -> 0.22727273 | U24: =$U$12/$U$7 -> 0.39090909 | V24: =$V$12/$V$7 -> 0.10909091 | W24: =S24+T24+U24+V24 -> 4.1672727 | X24: =(N24+R24+W24)*1% -> 0.11318873 | Y24: =X24 -> 0.11318873 | Z24: =$Z$12/E24 -> 0.0083 | AA24: =$AA$12/E24 -> 0.20833333 | AB24: =$AB$12/E24 -> 0.19791667 | AC24: =$AC$12/E24 -> 0 | AD24: =Z24+AA24+AB24+AC24 -> 0.41455 | AE24: =(AD24+Y24+W24+R24+N24)*$AE$7 -> 2.9616529 | AF24: =AE24 -> 2.9616529 | AL24: =(AD24+Y24+W24+R24+N24)*$AL$7 -> 0 | AM24: =AL24+AF24+AD24+Y24+W24+R24+N24 -> 14.808264 | AN24: =AM24*$AN$12 -> 0.17769917 | AO24: =AM24*$AO$12 -> 0.15992925 | AP24: =AO24+AN24 -> 0.33762843 | AQ24: =AM24*$AQ$12 -> 1.2364901 | AR24: =AM24*$AR$12 -> 0 | AS24: =AM24*$AS$12 -> 0 | AT24: =AQ24+AR24+AS24 -> 1.2364901 | AU24: =AM24*$AU$12 -> 0.74041322 | AV24: =AU24 -> 0.74041322 | AW24: =AM24+AP24+AT24+AV24 -> 17.122796 | AX24: =AY24/AW24 -> 0.050646166 | AY24: =I24-AW24 -> 0.86720397 | AZ24: =IFERROR(H24*VLOOKUP(A24,'Tabela de Produtos'!A:Q,17,0),0) -> 9.56 | BA24: =$I24*BA$12 -> 0 | BB24: =$I24*BB$12 -> 0 | BC24: =$I24*BC$12 -> 0 | BD24: =$I24*BD$12 -> 1.2593 | BE24: =I24*$BE$12 -> 0.8995 | BF24: =SUM(AZ24:BE24) -> 11.7188 | BG24: =I24-BF24 -> 6.2712 | BH24: =IF(F24="Cadastrar Ficha de Produção",0,IFERROR(BG24/I24,0)) -> 0.34859366
A25: PRD00012 | B25: =IFERROR(VLOOKUP(A25,'Tabela de Produtos'!A:B,2,0),"Preencher Cód. Produto") -> BRAZIMIL LÁTEX ECONÔMICO INT FOSCO 3L PALHA | D25: Galao | E25: 100 | F25: =IF(A25=0,0,VLOOKUP(A25,'Tabela de Produtos'!A:W,23,0)) -> 10.56 | G25: 17.99 | H25: 1 | I25: =G25*H25 -> 17.99 | J25: =VLOOKUP(B25,'Tabela de Produtos'!B:M,12,FALSE()) -> 4.92 | K25: =VLOOKUP(B25,'Tabela de Produtos'!B:P,15,FALSE()) -> 0.93 | L25: =J25*1% -> 0.0492 | M25: =J25*1% -> 0.0492 | N25: =J25+K25+L25+M25 -> 5.9484 | O25: =($O$12/E25)*$O$13 -> 0.362 | P25: =($P$12/E25)*$P$13 -> 0.2829 | Q25: =($Q$12/E25)*$Q$13 -> 0.2829 | R25: =O25+P25+Q25 -> 0.9278 | S25: =VLOOKUP(B25,'Tabela de Produtos'!B:N,13,FALSE()) -> 3.44 | T25: =$T$12/$T$7 -> 0.22727273 | U25: =$U$12/$U$7 -> 0.39090909 | V25: =$V$12/$V$7 -> 0.10909091 | W25: =S25+T25+U25+V25 -> 4.1672727 | X25: =(N25+R25+W25)*1% -> 0.11043473 | Y25: =X25 -> 0.11043473 | Z25: =$Z$12/E25 -> 0.0083 | AA25: =$AA$12/E25 -> 0.20833333 | AB25: =$AB$12/E25 -> 0.19791667 | AC25: =$AC$12/E25 -> 0 | AD25: =Z25+AA25+AB25+AC25 -> 0.41455 | AE25: =(AD25+Y25+W25+R25+N25)*$AE$7 -> 2.8921144 | AF25: =AE25 -> 2.8921144 | AL25: =(AD25+Y25+W25+R25+N25)*$AL$7 -> 0 | AM25: =AL25+AF25+AD25+Y25+W25+R25+N25 -> 14.460572 | AN25: =AM25*$AN$12 -> 0.17352686 | AO25: =AM25*$AO$12 -> 0.15617418 | AP25: =AO25+AN25 -> 0.32970104 | AQ25: =AM25*$AQ$12 -> 1.2074577 | AR25: =AM25*$AR$12 -> 0 | AS25: =AM25*$AS$12 -> 0 | AT25: =AQ25+AR25+AS25 -> 1.2074577 | AU25: =AM25*$AU$12 -> 0.72302859 | AV25: =AU25 -> 0.72302859 | AW25: =AM25+AP25+AT25+AV25 -> 16.720759 | AX25: =AY25/AW25 -> 0.075908085 | AY25: =I25-AW25 -> 1.2692408 | AZ25: =IFERROR(H25*VLOOKUP(A25,'Tabela de Produtos'!A:Q,17,0),0) -> 9.29 | BA25: =$I25*BA$12 -> 0 | BB25: =$I25*BB$12 -> 0 | BC25: =$I25*BC$12 -> 0 | BD25: =$I25*BD$12 -> 1.2593 | BE25: =I25*$BE$12 -> 0.8995 | BF25: =SUM(AZ25:BE25) -> 11.4488 | BG25: =I25-BF25 -> 6.5412 | BH25: =IF(F25="Cadastrar Ficha de Produção",0,IFERROR(BG25/I25,0)) -> 0.363602
A26: PRD00013 | B26: =IFERROR(VLOOKUP(A26,'Tabela de Produtos'!A:B,2,0),"Preencher Cód. Produto") -> BRAZIMIL LÁTEX ECONÔMICO INT FOSCO 3L VERDE PRIMAVERA | D26: Galao | E26: 100 | F26: =IF(A26=0,0,VLOOKUP(A26,'Tabela de Produtos'!A:W,23,0)) -> 11.52 | G26: 17.99 | H26: 1 | I26: =G26*H26 -> 17.99 | J26: =VLOOKUP(B26,'Tabela de Produtos'!B:M,12,FALSE()) -> 5.76 | K26: =VLOOKUP(B26,'Tabela de Produtos'!B:P,15,FALSE()) -> 0.93 | L26: =J26*1% -> 0.0576 | M26: =J26*1% -> 0.0576 | N26: =J26+K26+L26+M26 -> 6.8052 | O26: =($O$12/E26)*$O$13 -> 0.362 | P26: =($P$12/E26)*$P$13 -> 0.2829 | Q26: =($Q$12/E26)*$Q$13 -> 0.2829 | R26: =O26+P26+Q26 -> 0.9278 | S26: =VLOOKUP(B26,'Tabela de Produtos'!B:N,13,FALSE()) -> 3.44 | T26: =$T$12/$T$7 -> 0.22727273 | U26: =$U$12/$U$7 -> 0.39090909 | V26: =$V$12/$V$7 -> 0.10909091 | W26: =S26+T26+U26+V26 -> 4.1672727 | X26: =(N26+R26+W26)*1% -> 0.11900273 | Y26: =X26 -> 0.11900273 | Z26: =$Z$12/E26 -> 0.0083 | AA26: =$AA$12/E26 -> 0.20833333 | AB26: =$AB$12/E26 -> 0.19791667 | AC26: =$AC$12/E26 -> 0 | AD26: =Z26+AA26+AB26+AC26 -> 0.41455 | AE26: =(AD26+Y26+W26+R26+N26)*$AE$7 -> 3.1084564 | AF26: =AE26 -> 3.1084564 | AL26: =(AD26+Y26+W26+R26+N26)*$AL$7 -> 0 | AM26: =AL26+AF26+AD26+Y26+W26+R26+N26 -> 15.542282 | AN26: =AM26*$AN$12 -> 0.18650738 | AO26: =AM26*$AO$12 -> 0.16785664 | AP26: =AO26+AN26 -> 0.35436403 | AQ26: =AM26*$AQ$12 -> 1.2977805 | AR26: =AM26*$AR$12 -> 0 | AS26: =AM26*$AS$12 -> 0 | AT26: =AQ26+AR26+AS26 -> 1.2977805 | AU26: =AM26*$AU$12 -> 0.77711409 | AV26: =AU26 -> 0.77711409 | AW26: =AM26+AP26+AT26+AV26 -> 17.97154 | AX26: =AY26/AW26 -> 0.0010271537 | AY26: =I26-AW26 -> 0.018459534 | AZ26: =IFERROR(H26*VLOOKUP(A26,'Tabela de Produtos'!A:Q,17,0),0) -> 10.13 | BA26: =$I26*BA$12 -> 0 | BB26: =$I26*BB$12 -> 0 | BC26: =$I26*BC$12 -> 0 | BD26: =$I26*BD$12 -> 1.2593 | BE26: =I26*$BE$12 -> 0.8995 | BF26: =SUM(AZ26:BE26) -> 12.2888 | BG26: =I26-BF26 -> 5.7012 | BH26: =IF(F26="Cadastrar Ficha de Produção",0,IFERROR(BG26/I26,0)) -> 0.31690939
A27: PRD00014 | B27: =IFERROR(VLOOKUP(A27,'Tabela de Produtos'!A:B,2,0),"Preencher Cód. Produto") -> BRAZIMIL LÁTEX ECONÔMICO INT FOSCO 3L VERDE FOLHA | D27: Galao | E27: 100 | F27: =IF(A27=0,0,VLOOKUP(A27,'Tabela de Produtos'!A:W,23,0)) -> 12.78 | G27: 17.99 | H27: 1 | I27: =G27*H27 -> 17.99 | J27: =VLOOKUP(B27,'Tabela de Produtos'!B:M,12,FALSE()) -> 6.87 | K27: =VLOOKUP(B27,'Tabela de Produtos'!B:P,15,FALSE()) -> 0.93 | L27: =J27*1% -> 0.0687 | M27: =J27*1% -> 0.0687 | N27: =J27+K27+L27+M27 -> 7.9374 | O27: =($O$12/E27)*$O$13 -> 0.362 | P27: =($P$12/E27)*$P$13 -> 0.2829 | Q27: =($Q$12/E27)*$Q$13 -> 0.2829 | R27: =O27+P27+Q27 -> 0.9278 | S27: =VLOOKUP(B27,'Tabela de Produtos'!B:N,13,FALSE()) -> 3.44 | T27: =$T$12/$T$7 -> 0.22727273 | U27: =$U$12/$U$7 -> 0.39090909 | V27: =$V$12/$V$7 -> 0.10909091 | W27: =S27+T27+U27+V27 -> 4.1672727 | X27: =(N27+R27+W27)*1% -> 0.13032473 | Y27: =X27 -> 0.13032473 | Z27: =$Z$12/E27 -> 0.0083 | AA27: =$AA$12/E27 -> 0.20833333 | AB27: =$AB$12/E27 -> 0.19791667 | AC27: =$AC$12/E27 -> 0 | AD27: =Z27+AA27+AB27+AC27 -> 0.41455 | AE27: =(AD27+Y27+W27+R27+N27)*$AE$7 -> 3.3943369 | AF27: =AE27 -> 3.3943369 | AL27: =(AD27+Y27+W27+R27+N27)*$AL$7 -> 0 | AM27: =AL27+AF27+AD27+Y27+W27+R27+N27 -> 16.971684 | AN27: =AM27*$AN$12 -> 0.20366021 | AO27: =AM27*$AO$12 -> 0.18329419 | AP27: =AO27+AN27 -> 0.3869544 | AQ27: =AM27*$AQ$12 -> 1.4171356 | AR27: =AM27*$AR$12 -> 0 | AS27: =AM27*$AS$12 -> 0 | AT27: =AQ27+AR27+AS27 -> 1.4171356 | AU27: =AM27*$AU$12 -> 0.84858422 | AV27: =AU27 -> 0.84858422 | AW27: =AM27+AP27+AT27+AV27 -> 19.624359 | AX27: =AY27/AW27 -> -0.08328214 | AY27: =I27-AW27 -> -1.6343586 | AZ27: =IFERROR(H27*VLOOKUP(A27,'Tabela de Produtos'!A:Q,17,0),0) -> 11.24 | BA27: =$I27*BA$12 -> 0 | BB27: =$I27*BB$12 -> 0 | BC27: =$I27*BC$12 -> 0 | BD27: =$I27*BD$12 -> 1.2593 | BE27: =I27*$BE$12 -> 0.8995 | BF27: =SUM(AZ27:BE27) -> 13.3988 | BG27: =I27-BF27 -> 4.5912 | BH27: =IF(F27="Cadastrar Ficha de Produção",0,IFERROR(BG27/I27,0)) -> 0.25520845
A28: PRD00015 | B28: =IFERROR(VLOOKUP(A28,'Tabela de Produtos'!A:B,2,0),"Preencher Cód. Produto") -> BRAZIMIL LÁTEX ECONÔMICO INT FOSCO 3L AZUL CEU | D28: Galao | E28: 100 | F28: =IF(A28=0,0,VLOOKUP(A28,'Tabela de Produtos'!A:W,23,0)) -> 10.49 | G28: 17.99 | H28: 1 | I28: =G28*H28 -> 17.99 | J28: =VLOOKUP(B28,'Tabela de Produtos'!B:M,12,FALSE()) -> 4.86 | K28: =VLOOKUP(B28,'Tabela de Produtos'!B:P,15,FALSE()) -> 0.93 | L28: =J28*1% -> 0.0486 | M28: =J28*1% -> 0.0486 | N28: =J28+K28+L28+M28 -> 5.8872 | O28: =($O$12/E28)*$O$13 -> 0.362 | P28: =($P$12/E28)*$P$13 -> 0.2829 | Q28: =($Q$12/E28)*$Q$13 -> 0.2829 | R28: =O28+P28+Q28 -> 0.9278 | S28: =VLOOKUP(B28,'Tabela de Produtos'!B:N,13,FALSE()) -> 3.44 | T28: =$T$12/$T$7 -> 0.22727273 | U28: =$U$12/$U$7 -> 0.39090909 | V28: =$V$12/$V$7 -> 0.10909091 | W28: =S28+T28+U28+V28 -> 4.1672727 | X28: =(N28+R28+W28)*1% -> 0.10982273 | Y28: =X28 -> 0.10982273 | Z28: =$Z$12/E28 -> 0.0083 | AA28: =$AA$12/E28 -> 0.20833333 | AB28: =$AB$12/E28 -> 0.19791667 | AC28: =$AC$12/E28 -> 0 | AD28: =Z28+AA28+AB28+AC28 -> 0.41455 | AE28: =(AD28+Y28+W28+R28+N28)*$AE$7 -> 2.8766614 | AF28: =AE28 -> 2.8766614 | AL28: =(AD28+Y28+W28+R28+N28)*$AL$7 -> 0 | AM28: =AL28+AF28+AD28+Y28+W28+R28+N28 -> 14.383307 | AN28: =AM28*$AN$12 -> 0.17259968 | AO28: =AM28*$AO$12 -> 0.15533971 | AP28: =AO28+AN28 -> 0.3279394 | AQ28: =AM28*$AQ$12 -> 1.2010061 | AR28: =AM28*$AR$12 -> 0 | AS28: =AM28*$AS$12 -> 0 | AT28: =AQ28+AR28+AS28 -> 1.2010061 | AU28: =AM28*$AU$12 -> 0.71916534 | AV28: =AU28 -> 0.71916534 | AW28: =AM28+AP28+AT28+AV28 -> 16.631418 | AX28: =AY28/AW28 -> 0.081687704 | AY28: =I28-AW28 -> 1.3585823 | AZ28: =IFERROR(H28*VLOOKUP(A28,'Tabela de Produtos'!A:Q,17,0),0) -> 9.23 | BA28: =$I28*BA$12 -> 0 | BB28: =$I28*BB$12 -> 0 | BC28: =$I28*BC$12 -> 0 | BD28: =$I28*BD$12 -> 1.2593 | BE28: =I28*$BE$12 -> 0.8995 | BF28: =SUM(AZ28:BE28) -> 11.3888 | BG28: =I28-BF28 -> 6.6012 | BH28: =IF(F28="Cadastrar Ficha de Produção",0,IFERROR(BG28/I28,0)) -> 0.36693719
A29: PRD00016 | B29: =IFERROR(VLOOKUP(A29,'Tabela de Produtos'!A:B,2,0),"Preencher Cód. Produto") -> BRAZIMIL LÁTEX ECONÔMICO INT FOSCO 3L AZUL OCEANO | D29: Galao | E29: 100 | F29: =IF(A29=0,0,VLOOKUP(A29,'Tabela de Produtos'!A:W,23,0)) -> 11.82 | G29: 17.99 | H29: 1 | I29: =G29*H29 -> 17.99 | J29: =VLOOKUP(B29,'Tabela de Produtos'!B:M,12,FALSE()) -> 6.03 | K29: =VLOOKUP(B29,'Tabela de Produtos'!B:P,15,FALSE()) -> 0.93 | L29: =J29*1% -> 0.0603 | M29: =J29*1% -> 0.0603 | N29: =J29+K29+L29+M29 -> 7.0806 | O29: =($O$12/E29)*$O$13 -> 0.362 | P29: =($P$12/E29)*$P$13 -> 0.2829 | Q29: =($Q$12/E29)*$Q$13 -> 0.2829 | R29: =O29+P29+Q29 -> 0.9278 | S29: =VLOOKUP(B29,'Tabela de Produtos'!B:N,13,FALSE()) -> 3.44 | T29: =$T$12/$T$7 -> 0.22727273 | U29: =$U$12/$U$7 -> 0.39090909 | V29: =$V$12/$V$7 -> 0.10909091 | W29: =S29+T29+U29+V29 -> 4.1672727 | X29: =(N29+R29+W29)*1% -> 0.12175673 | Y29: =X29 -> 0.12175673 | Z29: =$Z$12/E29 -> 0.0083 | AA29: =$AA$12/E29 -> 0.20833333 | AB29: =$AB$12/E29 -> 0.19791667 | AC29: =$AC$12/E29 -> 0 | AD29: =Z29+AA29+AB29+AC29 -> 0.41455 | AE29: =(AD29+Y29+W29+R29+N29)*$AE$7 -> 3.1779949 | AF29: =AE29 -> 3.1779949 | AL29: =(AD29+Y29+W29+R29+N29)*$AL$7 -> 0 | AM29: =AL29+AF29+AD29+Y29+W29+R29+N29 -> 15.889974 | AN29: =AM29*$AN$12 -> 0.19067969 | AO29: =AM29*$AO$12 -> 0.17161172 | AP29: =AO29+AN29 -> 0.36229141 | AQ29: =AM29*$AQ$12 -> 1.3268129 | AR29: =AM29*$AR$12 -> 0 | AS29: =AM29*$AS$12 -> 0 | AT29: =AQ29+AR29+AS29 -> 1.3268129 | AU29: =AM29*$AU$12 -> 0.79449872 | AV29: =AU29 -> 0.79449872 | AW29: =AM29+AP29+AT29+AV29 -> 18.373577 | AX29: =AY29/AW29 -> -0.020876572 | AY29: =I29-AW29 -> -0.3835773 | AZ29: =IFERROR(H29*VLOOKUP(A29,'Tabela de Produtos'!A:Q,17,0),0) -> 10.4 | BA29: =$I29*BA$12 -> 0 | BB29: =$I29*BB$12 -> 0 | BC29: =$I29*BC$12 -> 0 | BD29: =$I29*BD$12 -> 1.2593 | BE29: =I29*$BE$12 -> 0.8995 | BF29: =SUM(AZ29:BE29) -> 12.5588 | BG29: =I29-BF29 -> 5.4312 | BH29: =IF(F29="Cadastrar Ficha de Produção",0,IFERROR(BG29/I29,0)) -> 0.30190106
A30: PRD00017 | B30: =IFERROR(VLOOKUP(A30,'Tabela de Produtos'!A:B,2,0),"Preencher Cód. Produto") -> BRAZIMIL LÁTEX ECONÔMICO INT FOSCO 3L AMARELO CANARIO | D30: Galao | E30: 100 | F30: =IF(A30=0,0,VLOOKUP(A30,'Tabela de Produtos'!A:W,23,0)) -> 10.8 | G30: 17.99 | H30: 1 | I30: =G30*H30 -> 17.99 | J30: =VLOOKUP(B30,'Tabela de Produtos'!B:M,12,FALSE()) -> 5.13 | K30: =VLOOKUP(B30,'Tabela de Produtos'!B:P,15,FALSE()) -> 0.93 | L30: =J30*1% -> 0.0513 | M30: =J30*1% -> 0.0513 | N30: =J30+K30+L30+M30 -> 6.1626 | O30: =($O$12/E30)*$O$13 -> 0.362 | P30: =($P$12/E30)*$P$13 -> 0.2829 | Q30: =($Q$12/E30)*$Q$13 -> 0.2829 | R30: =O30+P30+Q30 -> 0.9278 | S30: =VLOOKUP(B30,'Tabela de Produtos'!B:N,13,FALSE()) -> 3.44 | T30: =$T$12/$T$7 -> 0.22727273 | U30: =$U$12/$U$7 -> 0.39090909 | V30: =$V$12/$V$7 -> 0.10909091 | W30: =S30+T30+U30+V30 -> 4.1672727 | X30: =(N30+R30+W30)*1% -> 0.11257673 | Y30: =X30 -> 0.11257673 | Z30: =$Z$12/E30 -> 0.0083 | AA30: =$AA$12/E30 -> 0.20833333 | AB30: =$AB$12/E30 -> 0.19791667 | AC30: =$AC$12/E30 -> 0 | AD30: =Z30+AA30+AB30+AC30 -> 0.41455 | AE30: =(AD30+Y30+W30+R30+N30)*$AE$7 -> 2.9461999 | AF30: =AE30 -> 2.9461999 | AL30: =(AD30+Y30+W30+R30+N30)*$AL$7 -> 0 | AM30: =AL30+AF30+AD30+Y30+W30+R30+N30 -> 14.730999 | AN30: =AM30*$AN$12 -> 0.17677199 | AO30: =AM30*$AO$12 -> 0.15909479 | AP30: =AO30+AN30 -> 0.33586678 | AQ30: =AM30*$AQ$12 -> 1.2300384 | AR30: =AM30*$AR$12 -> 0 | AS30: =AM30*$AS$12 -> 0 | AT30: =AQ30+AR30+AS30 -> 1.2300384 | AU30: =AM30*$AU$12 -> 0.73654997 | AV30: =AU30 -> 0.73654997 | AW30: =AM30+AP30+AT30+AV30 -> 17.033455 | AX30: =AY30/AW30 -> 0.05615687 | AY30: =I30-AW30 -> 0.95654549 | AZ30: =IFERROR(H30*VLOOKUP(A30,'Tabela de Produtos'!A:Q,17,0),0) -> 9.5 | BA30: =$I30*BA$12 -> 0 | BB30: =$I30*BB$12 -> 0 | BC30: =$I30*BC$12 -> 0 | BD30: =$I30*BD$12 -> 1.2593 | BE30: =I30*$BE$12 -> 0.8995 | BF30: =SUM(AZ30:BE30) -> 11.6588 | BG30: =I30-BF30 -> 6.3312 | BH30: =IF(F30="Cadastrar Ficha de Produção",0,IFERROR(BG30/I30,0)) -> 0.35192885
A31: PRD00018 | B31: =IFERROR(VLOOKUP(A31,'Tabela de Produtos'!A:B,2,0),"Preencher Cód. Produto") -> BRAZIMIL LÁTEX ECONÔMICO INT FOSCO 3L CROMO SUAVE | D31: Galao | E31: 100 | F31: =IF(A31=0,0,VLOOKUP(A31,'Tabela de Produtos'!A:W,23,0)) -> 11.62 | G31: 17.99 | H31: 1 | I31: =G31*H31 -> 17.99 | J31: =VLOOKUP(B31,'Tabela de Produtos'!B:M,12,FALSE()) -> 5.85 | K31: =VLOOKUP(B31,'Tabela de Produtos'!B:P,15,FALSE()) -> 0.93 | L31: =J31*1% -> 0.0585 | M31: =J31*1% -> 0.0585 | N31: =J31+K31+L31+M31 -> 6.897 | O31: =($O$12/E31)*$O$13 -> 0.362 | P31: =($P$12/E31)*$P$13 -> 0.2829 | Q31: =($Q$12/E31)*$Q$13 -> 0.2829 | R31: =O31+P31+Q31 -> 0.9278 | S31: =VLOOKUP(B31,'Tabela de Produtos'!B:N,13,FALSE()) -> 3.44 | T31: =$T$12/$T$7 -> 0.22727273 | U31: =$U$12/$U$7 -> 0.39090909 | V31: =$V$12/$V$7 -> 0.10909091 | W31: =S31+T31+U31+V31 -> 4.1672727 | X31: =(N31+R31+W31)*1% -> 0.11992073 | Y31: =X31 -> 0.11992073 | Z31: =$Z$12/E31 -> 0.0083 | AA31: =$AA$12/E31 -> 0.20833333 | AB31: =$AB$12/E31 -> 0.19791667 | AC31: =$AC$12/E31 -> 0 | AD31: =Z31+AA31+AB31+AC31 -> 0.41455 | AE31: =(AD31+Y31+W31+R31+N31)*$AE$7 -> 3.1316359 | AF31: =AE31 -> 3.1316359 | AL31: =(AD31+Y31+W31+R31+N31)*$AL$7 -> 0 | AM31: =AL31+AF31+AD31+Y31+W31+R31+N31 -> 15.658179 | AN31: =AM31*$AN$12 -> 0.18789815 | AO31: =AM31*$AO$12 -> 0.16910834 | AP31: =AO31+AN31 -> 0.35700649 | AQ31: =AM31*$AQ$12 -> 1.307458 | AR31: =AM31*$AR$12 -> 0 | AS31: =AM31*$AS$12 -> 0 | AT31: =AQ31+AR31+AS31 -> 1.307458 | AU31: =AM31*$AU$12 -> 0.78290897 | AV31: =AU31 -> 0.78290897 | AW31: =AM31+AP31+AT31+AV31 -> 18.105553 | AX31: =AY31/AW31 -> -0.0063821717 | AY31: =I31-AW31 -> -0.11555275 | AZ31: =IFERROR(H31*VLOOKUP(A31,'Tabela de Produtos'!A:Q,17,0),0) -> 10.22 | BA31: =$I31*BA$12 -> 0 | BB31: =$I31*BB$12 -> 0 | BC31: =$I31*BC$12 -> 0 | BD31: =$I31*BD$12 -> 1.2593 | BE31: =I31*$BE$12 -> 0.8995 | BF31: =SUM(AZ31:BE31) -> 12.3788 | BG31: =I31-BF31 -> 5.6112 | BH31: =IF(F31="Cadastrar Ficha de Produção",0,IFERROR(BG31/I31,0)) -> 0.31190661
A32: PRD00019 | B32: =IFERROR(VLOOKUP(A32,'Tabela de Produtos'!A:B,2,0),"Preencher Cód. Produto") -> BRAZIMIL LÁTEX ECONÔMICO INT FOSCO 3L ROSA BEBE | D32: Galao | E32: 100 | F32: =IF(A32=0,0,VLOOKUP(A32,'Tabela de Produtos'!A:W,23,0)) -> 10.6 | G32: 17.99 | H32: 1 | I32: =G32*H32 -> 17.99 | J32: =VLOOKUP(B32,'Tabela de Produtos'!B:M,12,FALSE()) -> 4.95 | K32: =VLOOKUP(B32,'Tabela de Produtos'!B:P,15,FALSE()) -> 0.93 | L32: =J32*1% -> 0.0495 | M32: =J32*1% -> 0.0495 | N32: =J32+K32+L32+M32 -> 5.979 | O32: =($O$12/E32)*$O$13 -> 0.362 | P32: =($P$12/E32)*$P$13 -> 0.2829 | Q32: =($Q$12/E32)*$Q$13 -> 0.2829 | R32: =O32+P32+Q32 -> 0.9278 | S32: =VLOOKUP(B32,'Tabela de Produtos'!B:N,13,FALSE()) -> 3.44 | T32: =$T$12/$T$7 -> 0.22727273 | U32: =$U$12/$U$7 -> 0.39090909 | V32: =$V$12/$V$7 -> 0.10909091 | W32: =S32+T32+U32+V32 -> 4.1672727 | X32: =(N32+R32+W32)*1% -> 0.11074073 | Y32: =X32 -> 0.11074073 | Z32: =$Z$12/E32 -> 0.0083 | AA32: =$AA$12/E32 -> 0.20833333 | AB32: =$AB$12/E32 -> 0.19791667 | AC32: =$AC$12/E32 -> 0 | AD32: =Z32+AA32+AB32+AC32 -> 0.41455 | AE32: =(AD32+Y32+W32+R32+N32)*$AE$7 -> 2.8998409 | AF32: =AE32 -> 2.8998409 | AL32: =(AD32+Y32+W32+R32+N32)*$AL$7 -> 0 | AM32: =AL32+AF32+AD32+Y32+W32+R32+N32 -> 14.499204 | AN32: =AM32*$AN$12 -> 0.17399045 | AO32: =AM32*$AO$12 -> 0.15659141 | AP32: =AO32+AN32 -> 0.33058186 | AQ32: =AM32*$AQ$12 -> 1.2106836 | AR32: =AM32*$AR$12 -> 0 | AS32: =AM32*$AS$12 -> 0 | AT32: =AQ32+AR32+AS32 -> 1.2106836 | AU32: =AM32*$AU$12 -> 0.72496022 | AV32: =AU32 -> 0.72496022 | AW32: =AM32+AP32+AT32+AV32 -> 16.76543 | AX32: =AY32/AW32 -> 0.073041374 | AY32: =I32-AW32 -> 1.22457 | AZ32: =IFERROR(H32*VLOOKUP(A32,'Tabela de Produtos'!A:Q,17,0),0) -> 9.32 | BA32: =$I32*BA$12 -> 0 | BB32: =$I32*BB$12 -> 0 | BC32: =$I32*BC$12 -> 0 | BD32: =$I32*BD$12 -> 1.2593 | BE32: =I32*$BE$12 -> 0.8995 | BF32: =SUM(AZ32:BE32) -> 11.4788 | BG32: =I32-BF32 -> 6.5112 | BH32: =IF(F32="Cadastrar Ficha de Produção",0,IFERROR(BG32/I32,0)) -> 0.36193441
A33: PRD00020 | B33: =IFERROR(VLOOKUP(A33,'Tabela de Produtos'!A:B,2,0),"Preencher Cód. Produto") -> BRAZIMIL LÁTEX ECONÔMICO INT FOSCO 3L MARFIM | D33: Galao | E33: 100 | F33: =IF(A33=0,0,VLOOKUP(A33,'Tabela de Produtos'!A:W,23,0)) -> 10.63 | G33: 17.99 | H33: 1 | I33: =G33*H33 -> 17.99 | J33: =VLOOKUP(B33,'Tabela de Produtos'!B:M,12,FALSE()) -> 4.98 | K33: =VLOOKUP(B33,'Tabela de Produtos'!B:P,15,FALSE()) -> 0.93 | L33: =J33*1% -> 0.0498 | M33: =J33*1% -> 0.0498 | N33: =J33+K33+L33+M33 -> 6.0096 | O33: =($O$12/E33)*$O$13 -> 0.362 | P33: =($P$12/E33)*$P$13 -> 0.2829 | Q33: =($Q$12/E33)*$Q$13 -> 0.2829 | R33: =O33+P33+Q33 -> 0.9278 | S33: =VLOOKUP(B33,'Tabela de Produtos'!B:N,13,FALSE()) -> 3.44 | T33: =$T$12/$T$7 -> 0.22727273 | U33: =$U$12/$U$7 -> 0.39090909 | V33: =$V$12/$V$7 -> 0.10909091 | W33: =S33+T33+U33+V33 -> 4.1672727 | X33: =(N33+R33+W33)*1% -> 0.11104673 | Y33: =X33 -> 0.11104673 | Z33: =$Z$12/E33 -> 0.0083 | AA33: =$AA$12/E33 -> 0.20833333 | AB33: =$AB$12/E33 -> 0.19791667 | AC33: =$AC$12/E33 -> 0 | AD33: =Z33+AA33+AB33+AC33 -> 0.41455 | AE33: =(AD33+Y33+W33+R33+N33)*$AE$7 -> 2.9075674 | AF33: =AE33 -> 2.9075674 | AL33: =(AD33+Y33+W33+R33+N33)*$AL$7 -> 0 | AM33: =AL33+AF33+AD33+Y33+W33+R33+N33 -> 14.537837 | AN33: =AM33*$AN$12 -> 0.17445404 | AO33: =AM33*$AO$12 -> 0.15700864 | AP33: =AO33+AN33 -> 0.33146268 | AQ33: =AM33*$AQ$12 -> 1.2139094 | AR33: =AM33*$AR$12 -> 0 | AS33: =AM33*$AS$12 -> 0 | AT33: =AQ33+AR33+AS33 -> 1.2139094 | AU33: =AM33*$AU$12 -> 0.72689184 | AV33: =AU33 -> 0.72689184 | AW33: =AM33+AP33+AT33+AV33 -> 16.810101 | AX33: =AY33/AW33 -> 0.0701899 | AY33: =I33-AW33 -> 1.1798993 | AZ33: =IFERROR(H33*VLOOKUP(A33,'Tabela de Produtos'!A:Q,17,0),0) -> 9.35 | BA33: =$I33*BA$12 -> 0 | BB33: =$I33*BB$12 -> 0 | BC33: =$I33*BC$12 -> 0 | BD33: =$I33*BD$12 -> 1.2593 | BE33: =I33*$BE$12 -> 0.8995 | BF33: =SUM(AZ33:BE33) -> 11.5088 | BG33: =I33-BF33 -> 6.4812 | BH33: =IF(F33="Cadastrar Ficha de Produção",0,IFERROR(BG33/I33,0)) -> 0.36026681
... A36: PRD00023 | B36: =IFERROR(VLOOKUP(A36,'Tabela de Produtos'!A:B,2,0),"Preencher Cód. Produto") -> BRAZIMIL LÁTEX ECONÔMICO INT FOSCO 3L PEROLA | D36: Galao | E36: 100 | F36: =IF(A36=0,0,VLOOKUP(A36,'Tabela de Produtos'!A:W,23,0)) -> 10.56 | G36: 17.99 | H36: 1 | I36: =G36*H36 -> 17.99 | J36: =VLOOKUP(B36,'Tabela de Produtos'!B:M,12,FALSE()) -> 4.92 | K36: =VLOOKUP(B36,'Tabela de Produtos'!B:P,15,FALSE()) -> 0.93 | L36: =J36*1% -> 0.0492 | M36: =J36*1% -> 0.0492 | N36: =J36+K36+L36+M36 -> 5.9484 | O36: =($O$12/E36)*$O$13 -> 0.362 | P36: =($P$12/E36)*$P$13 -> 0.2829 | Q36: =($Q$12/E36)*$Q$13 -> 0.2829 | R36: =O36+P36+Q36 -> 0.9278 | S36: =VLOOKUP(B36,'Tabela de Produtos'!B:N,13,FALSE()) -> 3.44 | T36: =$T$12/$T$7 -> 0.22727273 | U36: =$U$12/$U$7 -> 0.39090909 | V36: =$V$12/$V$7 -> 0.10909091 | W36: =S36+T36+U36+V36 -> 4.1672727 | X36: =(N36+R36+W36)*1% -> 0.11043473 | Y36: =X36 -> 0.11043473 | Z36: =$Z$12/E36 -> 0.0083 | AA36: =$AA$12/E36 -> 0.20833333 | AB36: =$AB$12/E36 -> 0.19791667 | AC36: =$AC$12/E36 -> 0 | AD36: =Z36+AA36+AB36+AC36 -> 0.41455 | AE36: =(AD36+Y36+W36+R36+N36)*$AE$7 -> 2.8921144 | AF36: =AE36 -> 2.8921144 | AL36: =(AD36+Y36+W36+R36+N36)*$AL$7 -> 0 | AM36: =AL36+AF36+AD36+Y36+W36+R36+N36 -> 14.460572 | AN36: =AM36*$AN$12 -> 0.17352686 | AO36: =AM36*$AO$12 -> 0.15617418 | AP36: =AO36+AN36 -> 0.32970104 | AQ36: =AM36*$AQ$12 -> 1.2074577 | AR36: =AM36*$AR$12 -> 0 | AS36: =AM36*$AS$12 -> 0 | AT36: =AQ36+AR36+AS36 -> 1.2074577 | AU36: =AM36*$AU$12 -> 0.72302859 | AV36: =AU36 -> 0.72302859 | AW36: =AM36+AP36+AT36+AV36 -> 16.720759 | AX36: =AY36/AW36 -> 0.075908085 | AY36: =I36-AW36 -> 1.2692408 | AZ36: =IFERROR(H36*VLOOKUP(A36,'Tabela de Produtos'!A:Q,17,0),0) -> 9.29 | BA36: =$I36*BA$12 -> 0 | BB36: =$I36*BB$12 -> 0 | BC36: =$I36*BC$12 -> 0 | BD36: =$I36*BD$12 -> 1.2593 | BE36: =I36*$BE$12 -> 0.8995 | BF36: =SUM(AZ36:BE36) -> 11.4488 | BG36: =I36-BF36 -> 6.5412 | BH36: =IF(F36="Cadastrar Ficha de Produção",0,IFERROR(BG36/I36,0)) -> 0.363602
A37: PRD00024 | B37: =IFERROR(VLOOKUP(A37,'Tabela de Produtos'!A:B,2,0),"Preencher Cód. Produto") -> BRAZIMIL LÁTEX ECONÔMICO INT/EXT SEMIBRILHO 3L BRANCO NEVE | D37: Galao | F37: =IF(A37=0,0,VLOOKUP(A37,'Tabela de Produtos'!A:W,23,0)) -> Cadastrar Ficha de Produção | G37: 0 | H37: 1 | I37: =G37*H37 -> 0 | J37: =VLOOKUP(B37,'Tabela de Produtos'!B:M,12,FALSE()) -> 0 | AY37: =I37-AW37 -> 0 | AZ37: =IFERROR(H37*VLOOKUP(A37,'Tabela de Produtos'!A:Q,17,0),0) -> 0 | BA37: =$I37*BA$12 -> 0 | BB37: =$I37*BB$12 -> 0 | BC37: =$I37*BC$12 -> 0 | BD37: =$I37*BD$12 -> 0 | BE37: =I37*$BE$12 -> 0 | BF37: =SUM(AZ37:BE37) -> 0 | BG37: =I37-BF37 -> 0 | BH37: =IF(F37="Cadastrar Ficha de Produção",0,IFERROR(BG37/I37,0)) -> 0
A38: PRD00025 | B38: =IFERROR(VLOOKUP(A38,'Tabela de Produtos'!A:B,2,0),"Preencher Cód. Produto") -> BRAZIMIL LÁTEX ECONÔMICO INT/EXT SEMIBRILHO 3L BRANCO GELO | D38: Galao | F38: =IF(A38=0,0,VLOOKUP(A38,'Tabela de Produtos'!A:W,23,0)) -> Cadastrar Ficha de Produção | G38: 0 | H38: 1 | I38: =G38*H38 -> 0 | J38: =VLOOKUP(B38,'Tabela de Produtos'!B:M,12,FALSE()) -> 0 | AY38: =I38-AW38 -> 0 | AZ38: =IFERROR(H38*VLOOKUP(A38,'Tabela de Produtos'!A:Q,17,0),0) -> 0 | BA38: =$I38*BA$12 -> 0 | BB38: =$I38*BB$12 -> 0 | BC38: =$I38*BC$12 -> 0 | BD38: =$I38*BD$12 -> 0 | BE38: =I38*$BE$12 -> 0 | BF38: =SUM(AZ38:BE38) -> 0 | BG38: =I38-BF38 -> 0 | BH38: =IF(F38="Cadastrar Ficha de Produção",0,IFERROR(BG38/I38,0)) -> 0
A39: PRD00026 | B39: =IFERROR(VLOOKUP(A39,'Tabela de Produtos'!A:B,2,0),"Preencher Cód. Produto") -> BRAZIMIL LÁTEX ECONÔMICO INT/EXT SEMIBRILHO 3L AREIA | D39: Galao | F39: =IF(A39=0,0,VLOOKUP(A39,'Tabela de Produtos'!A:W,23,0)) -> Cadastrar Ficha de Produção | G39: 0 | H39: 1 | I39: =G39*H39 -> 0 | J39: =VLOOKUP(B39,'Tabela de Produtos'!B:M,12,FALSE()) -> 0 | AY39: =I39-AW39 -> 0 | AZ39: =IFERROR(H39*VLOOKUP(A39,'Tabela de Produtos'!A:Q,17,0),0) -> 0 | BA39: =$I39*BA$12 -> 0 | BB39: =$I39*BB$12 -> 0 | BC39: =$I39*BC$12 -> 0 | BD39: =$I39*BD$12 -> 0 | BE39: =I39*$BE$12 -> 0 | BF39: =SUM(AZ39:BE39) -> 0 | BG39: =I39-BF39 -> 0 | BH39: =IF(F39="Cadastrar Ficha de Produção",0,IFERROR(BG39/I39,0)) -> 0
A40: PRD00027 | B40: =IFERROR(VLOOKUP(A40,'Tabela de Produtos'!A:B,2,0),"Preencher Cód. Produto") -> BRAZIMIL LÁTEX ECONÔMICO INT/EXT SEMIBRILHO 3L PALHA | D40: Galao | F40: =IF(A40=0,0,VLOOKUP(A40,'Tabela de Produtos'!A:W,23,0)) -> Cadastrar Ficha de Produção | G40: 0 | H40: 1 | I40: =G40*H40 -> 0 | J40: =VLOOKUP(B40,'Tabela de Produtos'!B:M,12,FALSE()) -> 0 | AY40: =I40-AW40 -> 0 | AZ40: =IFERROR(H40*VLOOKUP(A40,'Tabela de Produtos'!A:Q,17,0),0) -> 0 | BA40: =$I40*BA$12 -> 0 | BB40: =$I40*BB$12 -> 0 | BC40: =$I40*BC$12 -> 0 | BD40: =$I40*BD$12 -> 0 | BE40: =I40*$BE$12 -> 0 | BF40: =SUM(AZ40:BE40) -> 0 | BG40: =I40-BF40 -> 0 | BH40: =IF(F40="Cadastrar Ficha de Produção",0,IFERROR(BG40/I40,0)) -> 0
A41: PRD00028 | B41: =IFERROR(VLOOKUP(A41,'Tabela de Produtos'!A:B,2,0),"Preencher Cód. Produto") -> BRAZIMIL LÁTEX ECONÔMICO INT/EXT SEMIBRILHO 3L VERDE PRIMAVERA | D41: Galao | F41: =IF(A41=0,0,VLOOKUP(A41,'Tabela de Produtos'!A:W,23,0)) -> Cadastrar Ficha de Produção | G41: 0 | H41: 1 | I41: =G41*H41 -> 0 | J41: =VLOOKUP(B41,'Tabela de Produtos'!B:M,12,FALSE()) -> 0 | AY41: =I41-AW41 -> 0 | AZ41: =IFERROR(H41*VLOOKUP(A41,'Tabela de Produtos'!A:Q,17,0),0) -> 0 | BA41: =$I41*BA$12 -> 0 | BB41: =$I41*BB$12 -> 0 | BC41: =$I41*BC$12 -> 0 | BD41: =$I41*BD$12 -> 0 | BE41: =I41*$BE$12 -> 0 | BF41: =SUM(AZ41:BE41) -> 0 | BG41: =I41-BF41 -> 0 | BH41: =IF(F41="Cadastrar Ficha de Produção",0,IFERROR(BG41/I41,0)) -> 0
A42: PRD00029 | B42: =IFERROR(VLOOKUP(A42,'Tabela de Produtos'!A:B,2,0),"Preencher Cód. Produto") -> BRAZIMIL LÁTEX ECONÔMICO INT/EXT SEMIBRILHO 3L VERDE FOLHA | D42: Galao | F42: =IF(A42=0,0,VLOOKUP(A42,'Tabela de Produtos'!A:W,23,0)) -> Cadastrar Ficha de Produção | G42: 0 | H42: 1 | I42: =G42*H42 -> 0 | J42: =VLOOKUP(B42,'Tabela de Produtos'!B:M,12,FALSE()) -> 0 | AY42: =I42-AW42 -> 0 | AZ42: =IFERROR(H42*VLOOKUP(A42,'Tabela de Produtos'!A:Q,17,0),0) -> 0 | BA42: =$I42*BA$12 -> 0 | BB42: =$I42*BB$12 -> 0 | BC42: =$I42*BC$12 -> 0 | BD42: =$I42*BD$12 -> 0 | BE42: =I42*$BE$12 -> 0 | BF42: =SUM(AZ42:BE42) -> 0 | BG42: =I42-BF42 -> 0 | BH42: =IF(F42="Cadastrar Ficha de Produção",0,IFERROR(BG42/I42,0)) -> 0
A43: PRD00030 | B43: =IFERROR(VLOOKUP(A43,'Tabela de Produtos'!A:B,2,0),"Preencher Cód. Produto") -> BRAZIMIL LÁTEX ECONÔMICO INT/EXT SEMIBRILHO 3L AZUL CEU | D43: Galao | F43: =IF(A43=0,0,VLOOKUP(A43,'Tabela de Produtos'!A:W,23,0)) -> Cadastrar Ficha de Produção | G43: 0 | H43: 1 | I43: =G43*H43 -> 0 | J43: =VLOOKUP(B43,'Tabela de Produtos'!B:M,12,FALSE()) -> 0 | AY43: =I43-AW43 -> 0 | AZ43: =IFERROR(H43*VLOOKUP(A43,'Tabela de Produtos'!A:Q,17,0),0) -> 0 | BA43: =$I43*BA$12 -> 0 | BB43: =$I43*BB$12 -> 0 | BC43: =$I43*BC$12 -> 0 | BD43: =$I43*BD$12 -> 0 | BE43: =I43*$BE$12 -> 0 | BF43: =SUM(AZ43:BE43) -> 0 | BG43: =I43-BF43 -> 0 | BH43: =IF(F43="Cadastrar Ficha de Produção",0,IFERROR(BG43/I43,0)) -> 0
...

Sheet Grfico
C1: TOTAL
B2: BRAZIMIL LÁTEX ECONÔMICO INT FOSCO 15L BRANCO NEVE | C2: =SUM(C4:C13) -> 56.604379
B3: Tipo | C3: Custo
B4: 1. Materia prima | C4: ='Formação de Preço de Venda'!N52 -> 23.163 | D4: =C4/$C$2 -> 0.40920862
B5: 3.Embalagem | C5: ='Formação de Preço de Venda'!W52 -> 10.832222 | D5: =C5/$C$2 -> 0.19136721
B6: 6.Mark up | C6: ='Formação de Preço de Venda'!AF52 -> 9.7906043 | D6: =C6/$C$2 -> 0.17296549
B7: 7.Outros Despesas (Indireto) - 15% | C7: ='Formação de Preço de Venda'!AL52 -> 0 | D7: =C7/$C$2 -> 0
B8: 9.Impostos(Dentro) | C8: ='Formação de Preço de Venda'!AT52 -> 4.0875773 | D8: =C8/$C$2 -> 0.072213093
B9: 5.Outras custos Industriais | C9: ='Formação de Preço de Venda'!AD52 -> 1.4805357 | D9: =C9/$C$2 -> 0.026155851
B10: 2.Processo | C10: ='Formação de Preço de Venda'!R52 -> 3.3135714 | D10: =C10/$C$2 -> 0.058539136
B11: 10.Comissao | C11: ='Formação de Preço de Venda'!AV52 -> 2.4476511 | D11: =C11/$C$2 -> 0.043241373
B12: 8.Impostos(Fora) | C12: ='Formação de Preço de Venda'!AP52 -> 1.1161289 | D12: =C12/$C$2 -> 0.019718066
B13: 4.Refugo | C13: ='Formação de Preço de Venda'!Y52 -> 0.37308794 | D13: =C13/$C$2 -> 0.0065911497

Sheet Tabela de Produtos
P1: 0.31 | R1: ='Formação de Preço de Venda'!$BE$12 -> 0.05 | S1: =SUM('Formação de Preço de Venda'!$BA$12:$BD$12) -> 0.07 | AB1: ⚠️ CORREÇÃO METODOLÓGICA — Custeio Variável MC Correta = PLV − CV (I+E+F) | PLV = Preço × (1 − Comissão − Imposto) Comissão e Imposto são deduções do preço — NÃO fazem parte do custo variável do produto
AB2: 🟢 MC ≥ 35% = Saudável | 🟡 MC 20–35% = Atenção | 🔴 MC < 20% = Crítico | ⬛ MC < 0% = Prejuízo
A3: CÓDIGO | B3: DESCRIÇÃO | C3: GRUPO | D3: PROD. INTERM. | E3: ACABAMENTO | F3: COR | G3: EM PRODUÇÃO? | H3: EMBALAGEM | I3: MEDIDA | J3: FATOR CONV DENS | K3: Status Insumo | L3: Status Embalagem | M3: CUSTO INSUMOS (I) | N3: CUSTO EMBAL. (E) | O3: CUSTO (I+E) ← | P3: FRETE (F) | Q3: (I+E+F+CP) ← | R3: COMISSÃO FINAL | S3: IMPOSTO FINAL | T3: CUSTO TT FINAL | U3: PREÇO FINAL | V3: MARGEM FINAL | W3: PREÇO MÍNIMO | X3: CUSTO VARIÁVEL (método antigo) [inclui comissão+imposto] | Y3: MC UNITÁRIA (método antigo) [Preço − Custo TT] | Z3: MC % (método antigo) [MC / Preço Bruto] | AA3: CUSTOS FIXOS TOTAIS | AB3: CV UNITÁRIO CORRETO (I+E+F apenas) | AC3: PLV (Preço Líq. de Venda) | AD3: MC UNITÁRIA CORRETA (PLV − CV) | AE3: MC % CORRETA (MC/PLV) | AF3: PREÇO SUSTENTÁVEL (cobre CF também)
A4: PRD00001 | B4: BRAZIMIL MASSA CORRIDA 4,0KG | C4: MASSA CORRIDA | D4: PI00001 | E4: N/A | F4: N/A | G4: SIM | H4: 4 | I4: KG | J4: =IF(I4="KG",1,1.27) -> 1 | K4: =IFERROR(IF(VLOOKUP(D4,'Ficha de Produção'!C:C,1,0)=D4,"OK","Custo Produção Não Cadastrado"),"Custo Produção Não Cadastrado") -> OK | L4: =IFERROR(IF(VLOOKUP(A4,'Ficha de Embalagens'!A:A,1,0)=A4,"OK","Ficha de Embalagens Não Cadastrada"),"Ficha de Embalagens Não Cadastrada") -> OK | M4: =SUMIFS('Ficha de Produção'!N:N,'Ficha de Produção'!C:C,D4)*H4 -> 3 | N4: =SUMIFS('Ficha de Embalagens'!F:F,'Ficha de Embalagens'!A:A,A4) -> 3.06 | O4: =SUM(M4:N4) -> 6.06 | P4: =IF(AND(K4="OK",L4="OK"),H4*$P$1,0) -> 1.24 | Q4: =P4+O4 -> 7.3 | R4: =U4*$R$1 -> 0.7995 | S4: =$S$1*U4 -> 1.1193 | T4: =+Q4+R4+S4 -> 9.2188 | U4: 15.99 | V4: =IF(M4=0,"Cadastrar Ficha de Produção",IF(AND(M4>0,U4=""),"Cadastrar Preço Final",IFERROR((U4-T4)/U4,""))) -> 0.42346467 | W4: =IF(M4=0,"Cadastrar Ficha de Produção",ROUNDUP(Q4/(1-$R$1-$S$1),2)) -> 8.3 | X4: =SUM(Q4,R4,S4) -> 9.2188 | Y4: =U4-X4 -> 6.7712 | Z4: =Y4/U4 -> 0.42346467 | AA4: =SUM('Despesas Fixas'!F4,'Custos de Produção'!K4,Salários!J21) -> 55345.981 | AB4: =IF(Q4=0,"",Q4) -> 7.3 | AC4: =IF(U4="","",U4*(1-$R$1-$S$1)) -> 14.0712 | AD4: =IF(OR(AB4="",AC4=""),"",AC4-AB4) -> 6.7712 | AE4: =IF(OR(AD4="",AC4=0),"",AD4/AC4) -> 0.48120985 | AF4: =IF(Q4=0,"",ROUNDUP((Q4+IF(AA4="",0,AA4/1200))/(1-$R$1-$S$1),2)) -> 60.71
A5: PRD00002 | B5: BRAZIMIL MASSA CORRIDA 20,0 KG | C5: MASSA CORRIDA | D5: PI00001 | E5: N/A | F5: N/A | G5: SIM | H5: 20 | I5: KG | J5: =IF(I5="KG",1,1.27) -> 1 | K5: =IFERROR(IF(VLOOKUP(D5,'Ficha de Produção'!C:C,1,0)=D5,"OK","Custo Produção Não Cadastrado"),"Custo Produção Não Cadastrado") -> OK | L5: =IFERROR(IF(VLOOKUP(A5,'Ficha de Embalagens'!A:A,1,0)=A5,"OK","Ficha de Embalagens Não Cadastrada"),"Ficha de Embalagens Não Cadastrada") -> OK | M5: =SUMIFS('Ficha de Produção'!N:N,'Ficha de Produção'!C:C,D5)*H5 -> 15 | N5: =SUMIFS('Ficha de Embalagens'!F:F,'Ficha de Embalagens'!A:A,A5) -> 8.61 | O5: =SUM(M5:N5) -> 23.61 | P5: =IF(AND(K5="OK",L5="OK"),H5*$P$1,0) -> 6.2 | Q5: =P5+O5 -> 29.81 | R5: =U5*$R$1 -> 1.945 | S5: =$S$1*U5 -> 2.723 | T5: =+Q5+R5+S5 -> 34.478 | U5: 38.9 | V5: =IF(M5=0,"Cadastrar Ficha de Produção",IF(AND(M5>0,U5=""),"Cadastrar Preço Final",IFERROR((U5-T5)/U5,""))) -> 0.11367609 | W5: =IF(M5=0,"Cadastrar Ficha de Produção",ROUNDUP(Q5/(1-$R$1-$S$1),2)) -> 33.88 | AB5: =IF(Q5=0,"",Q5) -> 29.81 | AC5: =IF(U5="","",U5*(1-$R$1-$S$1)) -> 34.232 | AD5: =IF(OR(AB5="",AC5=""),"",AC5-AB5) -> 4.422 | AE5: =IF(OR(AD5="",AC5=0),"",AD5/AC5) -> 0.12917738 | AF5: =IF(Q5=0,"",ROUNDUP((Q5+IF(AA5="",0,AA5/1200))/(1-$R$1-$S$1),2)) -> 33.88
A6: PRD00003 | B6: BRAZIMIL SELADOR ACRILICO 3L | C6: SELADOR | D6: PI00002 | E6: ACRÍLICO | F6: N/A | G6: SIM | H6: 3 | I6: L | J6: =IF(I6="KG",1,1.27) -> 1.27 | K6: =IFERROR(IF(VLOOKUP(D6,'Ficha de Produção'!C:C,1,0)=D6,"OK","Custo Produção Não Cadastrado"),"Custo Produção Não Cadastrado") -> OK | L6: =IFERROR(IF(VLOOKUP(A6,'Ficha de Embalagens'!A:A,1,0)=A6,"OK","Ficha de Embalagens Não Cadastrada"),"Ficha de Embalagens Não Cadastrada") -> OK | M6: =SUMIFS('Ficha de Produção'!N:N,'Ficha de Produção'!C:C,D6)*H6 -> 2.64 | N6: =SUMIFS('Ficha de Embalagens'!F:F,'Ficha de Embalagens'!A:A,A6) -> 3.06 | O6: =SUM(M6:N6) -> 5.7 | P6: =IF(AND(K6="OK",L6="OK"),H6*$P$1,0) -> 0.93 | Q6: =P6+O6 -> 6.63 | R6: =U6*$R$1 -> 0.8495 | S6: =$S$1*U6 -> 1.1893 | T6: =+Q6+R6+S6 -> 8.6688 | U6: 16.99 | V6: =IF(M6=0,"Cadastrar Ficha de Produção",IF(AND(M6>0,U6=""),"Cadastrar Preço Final",IFERROR((U6-T6)/U6,""))) -> 0.48977045 | W6: =IF(M6=0,"Cadastrar Ficha de Produção",ROUNDUP(Q6/(1-$R$1-$S$1),2)) -> 7.54 | AB6: =IF(Q6=0,"",Q6) -> 6.63 | AC6: =IF(U6="","",U6*(1-$R$1-$S$1)) -> 14.9512 | AD6: =IF(OR(AB6="",AC6=""),"",AC6-AB6) -> 8.3212 | AE6: =IF(OR(AD6="",AC6=0),"",AD6/AC6) -> 0.55655733 | AF6: =IF(Q6=0,"",ROUNDUP((Q6+IF(AA6="",0,AA6/1200))/(1-$R$1-$S$1),2)) -> 7.54
A7: PRD00004 | B7: BRAZIMIL SELADOR ACRILICO 15L | C7: SELADOR | D7: PI00002 | E7: ACRÍLICO | F7: N/A | G7: SIM | H7: 15 | I7: L | J7: =IF(I7="KG",1,1.27) -> 1.27 | K7: =IFERROR(IF(VLOOKUP(D7,'Ficha de Produção'!C:C,1,0)=D7,"OK","Custo Produção Não Cadastrado"),"Custo Produção Não Cadastrado") -> OK | L7: =IFERROR(IF(VLOOKUP(A7,'Ficha de Embalagens'!A:A,1,0)=A7,"OK","Ficha de Embalagens Não Cadastrada"),"Ficha de Embalagens Não Cadastrada") -> OK | M7: =SUMIFS('Ficha de Produção'!N:N,'Ficha de Produção'!C:C,D7)*H7 -> 13.2 | N7: =SUMIFS('Ficha de Embalagens'!F:F,'Ficha de Embalagens'!A:A,A7) -> 8.61 | O7: =SUM(M7:N7) -> 21.81 | P7: =IF(AND(K7="OK",L7="OK"),H7*$P$1,0) -> 4.65 | Q7: =P7+O7 -> 26.46 | R7: =U7*$R$1 -> 3.3245 | S7: =$S$1*U7 -> 4.6543 | T7: =+Q7+R7+S7 -> 34.4388 | U7: 66.49 | V7: =IF(M7=0,"Cadastrar Ficha de Produção",IF(AND(M7>0,U7=""),"Cadastrar Preço Final",IFERROR((U7-T7)/U7,""))) -> 0.48204542 | W7: =IF(M7=0,"Cadastrar Ficha de Produção",ROUNDUP(Q7/(1-$R$1-$S$1),2)) -> 30.07 | AB7: =IF(Q7=0,"",Q7) -> 26.46 | AC7: =IF(U7="","",U7*(1-$R$1-$S$1)) -> 58.5112 | AD7: =IF(OR(AB7="",AC7=""),"",AC7-AB7) -> 32.0512 | AE7: =IF(OR(AD7="",AC7=0),"",AD7/AC7) -> 0.54777889 | AF7: =IF(Q7=0,"",ROUNDUP((Q7+IF(AA7="",0,AA7/1200))/(1-$R$1-$S$1),2)) -> 30.07
A8: PRD00005 | B8: BRAZIMIL SELADORA PARA MADEIRA 0,75L INCOLOR | C8: SELADOR | E8: PARA MADEIRA | F8: INCOLOR | G8: NÃO | H8: 0.75 | I8: L | J8: =IF(I8="KG",1,1.27) -> 1.27 | K8: =IFERROR(IF(VLOOKUP(D8,'Ficha de Produção'!C:C,1,0)=D8,"OK","Custo Produção Não Cadastrado"),"Custo Produção Não Cadastrado") -> Custo Produção Não Cadastrado | L8: =IFERROR(IF(VLOOKUP(A8,'Ficha de Embalagens'!A:A,1,0)=A8,"OK","Ficha de Embalagens Não Cadastrada"),"Ficha de Embalagens Não Cadastrada") -> Ficha de Embalagens Não Cadastrada | M8: =SUMIFS('Ficha de Produção'!N:N,'Ficha de Produção'!C:C,D8)*H8 -> 0 | N8: =SUMIFS('Ficha de Embalagens'!F:F,'Ficha de Embalagens'!A:A,A8) -> 0 | O8: =SUM(M8:N8) -> 0 | P8: =IF(AND(K8="OK",L8="OK"),H8*$P$1,0) -> 0 | Q8: =P8+O8 -> 0 | R8: =U8*$R$1 -> 0 | S8: =$S$1*U8 -> 0 | T8: =+Q8+R8+S8 -> 0 | V8: =IF(M8=0,"Cadastrar Ficha de Produção",IF(AND(M8>0,U8=""),"Cadastrar Preço Final",IFERROR((U8-T8)/U8,""))) -> Cadastrar Ficha de Produção | W8: =IF(M8=0,"Cadastrar Ficha de Produção",ROUNDUP(Q8/(1-$R$1-$S$1),2)) -> Cadastrar Ficha de Produção | AB8: =IF(Q8=0,"",Q8) | AC8: =IF(U8="","",U8*(1-$R$1-$S$1)) | AD8: =IF(OR(AB8="",AC8=""),"",AC8-AB8) | AE8: =IF(OR(AD8="",AC8=0),"",AD8/AC8) | AF8: =IF(Q8=0,"",ROUNDUP((Q8+IF(AA8="",0,AA8/1200))/(1-$R$1-$S$1),2))
A9: PRD00006 | B9: BRAZIMIL SELADORA PARA MADEIRA 3L INCOLOR | C9: SELADOR | E9: PARA MADEIRA | F9: INCOLOR | G9: NÃO | H9: 3 | I9: L | J9: =IF(I9="KG",1,1.27) -> 1.27 | K9: =IFERROR(IF(VLOOKUP(D9,'Ficha de Produção'!C:C,1,0)=D9,"OK","Custo Produção Não Cadastrado"),"Custo Produção Não Cadastrado") -> Custo Produção Não Cadastrado | L9: =IFERROR(IF(VLOOKUP(A9,'Ficha de Embalagens'!A:A,1,0)=A9,"OK","Ficha de Embalagens Não Cadastrada"),"Ficha de Embalagens Não Cadastrada") -> Ficha de Embalagens Não Cadastrada | M9: =SUMIFS('Ficha de Produção'!N:N,'Ficha de Produção'!C:C,D9)*H9 -> 0 | N9: =SUMIFS('Ficha de Embalagens'!F:F,'Ficha de Embalagens'!A:A,A9) -> 0 | O9: =SUM(M9:N9) -> 0 | P9: =IF(AND(K9="OK",L9="OK"),H9*$P$1,0) -> 0 | Q9: =P9+O9 -> 0 | R9: =U9*$R$1 -> 0 | S9: =$S$1*U9 -> 0 | T9: =+Q9+R9+S9 -> 0 | V9: =IF(M9=0,"Cadastrar Ficha de Produção",IF(AND(M9>0,U9=""),"Cadastrar Preço Final",IFERROR((U9-T9)/U9,""))) -> Cadastrar Ficha de Produção | W9: =IF(M9=0,"Cadastrar Ficha de Produção",ROUNDUP(Q9/(1-$R$1-$S$1),2)) -> Cadastrar Ficha de Produção | AB9: =IF(Q9=0,"",Q9) | AC9: =IF(U9="","",U9*(1-$R$1-$S$1)) | AD9: =IF(OR(AB9="",AC9=""),"",AC9-AB9) | AE9: =IF(OR(AD9="",AC9=0),"",AD9/AC9) | AF9: =IF(Q9=0,"",ROUNDUP((Q9+IF(AA9="",0,AA9/1200))/(1-$R$1-$S$1),2))
A10: PRD00007 | B10: BRAZIMIL MASSA ACRÍLICA 4KG | C10: MASSA ACRÍLICA | D10: PI00004 | E10: ACRÍLICO | F10: N/A | G10: SIM | H10: 4 | I10: KG | J10: =IF(I10="KG",1,1.27) -> 1 | K10: =IFERROR(IF(VLOOKUP(D10,'Ficha de Produção'!C:C,1,0)=D10,"OK","Custo Produção Não Cadastrado"),"Custo Produção Não Cadastrado") -> OK | L10: =IFERROR(IF(VLOOKUP(A10,'Ficha de Embalagens'!A:A,1,0)=A10,"OK","Ficha de Embalagens Não Cadastrada"),"Ficha de Embalagens Não Cadastrada") -> OK | M10: =SUMIFS('Ficha de Produção'!N:N,'Ficha de Produção'!C:C,D10)*H10 -> 6.44 | N10: =SUMIFS('Ficha de Embalagens'!F:F,'Ficha de Embalagens'!A:A,A10) -> 3.06 | O10: =SUM(M10:N10) -> 9.5 | P10: =IF(AND(K10="OK",L10="OK"),H10*$P$1,0) -> 1.24 | Q10: =P10+O10 -> 10.74 | R10: =U10*$R$1 -> 0.9995 | S10: =$S$1*U10 -> 1.3993 | T10: =+Q10+R10+S10 -> 13.1388 | U10: 19.99 | V10: =IF(M10=0,"Cadastrar Ficha de Produção",IF(AND(M10>0,U10=""),"Cadastrar Preço Final",IFERROR((U10-T10)/U10,""))) -> 0.34273137 | W10: =IF(M10=0,"Cadastrar Ficha de Produção",ROUNDUP(Q10/(1-$R$1-$S$1),2)) -> 12.21 | AB10: =IF(Q10=0,"",Q10) -> 10.74 | AC10: =IF(U10="","",U10*(1-$R$1-$S$1)) -> 17.5912 | AD10: =IF(OR(AB10="",AC10=""),"",AC10-AB10) -> 6.8512 | AE10: =IF(OR(AD10="",AC10=0),"",AD10/AC10) -> 0.38946746 | AF10: =IF(Q10=0,"",ROUNDUP((Q10+IF(AA10="",0,AA10/1200))/(1-$R$1-$S$1),2)) -> 12.21
