Workbook

Sheet Frete_Regiao-Impostos
A1: REPRESENTANTE | B1: FRETE TON | C1: IMPOSTOS | D1: ESTADO | E1: GRUPO ST | G1: TRIBUTAÇÃO P/ LUCRO PRESUMIDO!
H2: C
G3: PARAIBA | H3: =SUM(H4:H6) -> 0.2365
G4: Icms | H4: 0.2
G5: Pis | H5: 0.0065
G6: Cofins | H6: 0.03
H8: I
G9: INTERESTADUAL | H9: =SUM(H10:H12) -> 0.1565
G10: Icms | H10: 0.12
G11: Pis | H11: 0.0065
G12: Cofins | H12: 0.03
G14: MANUAS | H14: I (AM)
G15: INTERESTADUAL | H15: =SUM(H16:H18) -> 0.12
G16: Icms | H16: 0.12 | I16: ATENÇÃO: DESONERAÇÃO
G18: Desconto
G20: Exportação | H20: E
H21: =SUM(H22:H24) -> 0
G22: Icms | H22: 0
G23: Pis | H23: 0
G24: Cofins | H24: 0
A25: Manaus CIF | B25: 100 | C25: 0.07 | D25: AM | E25: GRUPO 4
A27: Manaus - FOB | B27: 0 | C27: 0.07 | D27: AM | E27: GRUPO 4
A28: Manaus - INTERIOR PIS COFINS | B28: 0 | C28: 0.1065 | D28: AM | E28: GRUPO 4 | G28: =2000/14 -> 142.85714
A29: Manaus - INTERIOR S/ PIS COFINS | B29: 0 | C29: 0.07 | D29: AM | E29: GRUPO 4

Sheet Sim_Preço
A2: Juros desconto duplicata | B2: X | C2: 0 | AJ2: % Comissão
A3: Representante | B3: Estado | C3: Grupo | AJ3: Vínculo planilha Frete_Regiao => Base p/ o Filtro "Representante-A4"
A4: Manaus CIF | B4: =VLOOKUP(A4,'Frete_Regiao-Impostos'!A1:D62,4,FALSE) -> AM | C4: =VLOOKUP(A4,'Frete_Regiao-Impostos'!A1:E62,5,FALSE) -> GRUPO 4 | E4: Fórmula | F4: Fórmula | I4: Digitado | N4: RESULTADO EM R$
A5: Impostos | B5: =VLOOKUP(A4,AF10:$AH$187,3,0) -> 0.07 | C5: PESO (Kg) | E5: Se "X" | F5: Se "X" | I5: Se "X" | O5: =N15/E15 -> 0.47981726 | X5: RESUMO DA VENDA
A6: Frete | B6: =VLOOKUP(A4,$AF$10:$AG$187,2,0) -> 100 | C6: =SUMPRODUCT(C12:C125,AP12:AP125) -> 0 | D6: MC Geral | E6: Considera | F6: Considera | I6: Considera
A7: Frete acima não é base p/ cálculo da MC => | B7: VALOR PEDIDO | C7: =SUMPRODUCT(B12:B133,C12:C133) -> 0 | D7: =+AB9 | E7: =IF($B$6<=$B$7,"X","") -> X | F7: =IF($B$6>$B$7,"X","") | I7: X | M7: Despesas | N7: =SUMPRODUCT(C12:C133,N12:N133) -> 0 | O7: Margem | Q7: CALCULO DO PREÇO FINAL PARA O CLIENTE
B8: Preço | D8: 9 | E8: Preço | F8: Preço | G8: Custo | I8: Comissão | J8: Comissão | K8: Desc. duplicata | L8: Desc. duplicata | M8: Custo | N8: Margem | O8: R$/TON | Q8: Alíquota | R8: Valor | S8: =HLOOKUP(B4,'MVA-IPI'!B137:AB142,2,FALSE) -> 0.12 | T8: MVA | U8: Base | V8: =HLOOKUP( B4,'MVA-IPI'!B137:AB142,3,FALSE) -> 0.2 | X8: PRODUTO | Y8: QTDE | Z8: MARGEM | AA8: RLV | AB8: MARGEM | AC8: MC Guia | AD8: Comissão | AE8: Comissão | AF8: REPRESENTANTE | AG8: FRETE TON | AH8: IMPOSTOS | AI8: ESTADO
A9: Produto | B9: Produto | C9: QTDE | D9: % | E9: Líquido | F9: Liq-Frete | G9: MP/ME | H9: Frete | I9: % | J9: R$ | K9: % | L9: R$ | M9: Variável | N9: R$ | O9: R$/HL | P9: Conversão | Q9: IPI | R9: IPI | S9: ICMS Normal | T9: ST | U9: ICMS ST | V9: ICMS ST | X9: TOTAL | Z9: =Z10+Z48+Z76+Z108 -> 0 | AA9: =AA10+AA48+AA76+AA108 -> 0 | AB9: =IF(ISERROR(Z9/AA9),"",Z9/AA9) | AC9: 0.18 | AE9: % | AH9: ICMS+PIS+COFINS
A10: TINTAS BASE ÁGUA | D10: =AB10 | X10: TINTAS BASE ÁGUA | Z10: =Z11+Z16+Z21+Z24+Z27+Z30+Z33+Z36+Z39+Z42+Z44+Z46 -> 0 | AA10: =AA11+AA16+AA21+AA24+AA27+AA30+AA33+AA36+AA39+AA42+AA44+AA46 -> 0 | AB10: =IF(ISERROR(Z10/AA10),"",Z10/AA10) | AC10: 0.25 | AF10: =+'Frete_Regiao-Impostos'!A2 -> 0 | AG10: =+'Frete_Regiao-Impostos'!B2 -> 0 | AH10: =+'Frete_Regiao-Impostos'!C2 -> 0 | AI10: =+'Frete_Regiao-Impostos'!D2 -> 0
A11: BRAZIMIL ECONOMICA 3,0L | D11: =AB11 | X11: =A11 -> BRAZIMIL ECONOMICA 3,0L | Z11: =SUM(Z12:Z15) -> 0 | AA11: =SUM(AA12:AA15) -> 0 | AB11: =IF(ISERROR(Z11/AA11),"",Z11/AA11) | AC11: 0.25 | AF11: =+'Frete_Regiao-Impostos'!A3 -> 0 | AG11: =+'Frete_Regiao-Impostos'!B3 -> 0 | AH11: =+'Frete_Regiao-Impostos'!C3 -> 0 | AI11: =+'Frete_Regiao-Impostos'!D3 -> 0 | AP11: PESO
A12: BRAZIMIL ECONÔMICA 3,0L REFIL BRANCO NEVE | B12: 9.5 | D12: =IF($F$7="x",IF(F12=0,0,N12/F12),IF($E$7="x",IF(F12=0,0,N12/E12),"")) -> 0.39340313 | E12: =+B12*(-B$5+100%) -> 8.835 | F12: =IF(B12=0,0,E12-H12) -> 8.45 | G12: =VLOOKUP(A12,Custo!A:B,2,0) -> 4.4992833 | H12: =(VLOOKUP(A12,Peso!$A$10:$B$148,2,0))*($B$6/1000) -> 0.385 | I12: =IF($I$7="X",AE12,0%) -> 0.05 | J12: =+B12*I12 -> 0.475 | K12: =IF($B$2="X",$C$2,0) -> 0 | L12: =+B12*K12 -> 0 | M12: =+G12+H12+J12+L12 -> 5.3592833 | N12: =+E12-M12 -> 3.4757167 | O12: =IF(ISERROR((N12/P12)*1000),"",(N12/P12)*1000) | Q12: =VLOOKUP(A12,'MVA-IPI'!A:AD,30,FALSE) -> 0 | R12: =IF($B$4="AM",0,IF($B$4="AP",0,IF($B$4="RR",0,(B12*Q12)))) -> 0 | S12: =IF($B$4="AP",(B12/0.88*$S$8),IF(T12=0%,0,IF($B$4="AM",(B12/0.88*$S$8),IF(T12=0%,0,IF($B$4="RR",(B12/0.88*$S$8),IF(T12=0%,0,B12*$S$8)))))) -> 0 | T12: =IF($C$4="GRUPO 1",VLOOKUP(A12,'MVA-grupos'!$A$9:$B$128,2,FALSE),IF($C$4="GRUPO 2",VLOOKUP(A12,'MVA-grupos'!$A$9:$D$128,4,FALSE),IF($C$4="GRUPO 3",VLOOKUP(A12,'MVA-grupos'!$A$10:$F$128,6,FALSE),IF($C$4="Grupo 4",VLOOKUP(A12,'MVA-grupos'!$A$9:$H$128,8,FALSE))))) -> 0 | U12: =IF(T12=0%,0,(B12+R12)*T12+(B12+R12)) -> 0 | V12: =(U12*$V$8)-S12 -> 0 | X12: =A12 -> BRAZIMIL ECONÔMICA 3,0L REFIL BRANCO NEVE | Y12: =+C12 -> 0 | Z12: =IF(ISERROR(Y12*N12),"",Y12*N12) -> 0 | AA12: =IF(ISERROR(IF(E$7="X",Y12*E12,Y12*F12)),"",IF(E$7="X",Y12*E12,Y12*F12)) -> 0 | AB12: =IF(ISERROR(Z12/AA12),"",Z12/AA12) | AE12: 0.05 | AF12: =+'Frete_Regiao-Impostos'!A4 -> 0 | AG12: =+'Frete_Regiao-Impostos'!B4 -> 0 | AH12: =+'Frete_Regiao-Impostos'!C4 -> 0 | AI12: =+'Frete_Regiao-Impostos'!D4 -> 0 | AP12: =Peso!B12 -> 3.85
A13: BRAZIMIL ECONÔMICA 3,0L REFIL COR | B13: 9.5 | D13: =IF($F$7="x",IF(F13=0,0,N13/F13),IF($E$7="x",IF(F13=0,0,N13/E13),"")) -> 0.45755276 | E13: =+B13*(-B$5+100%) -> 8.835 | F13: =IF(B13=0,0,E13-H13) -> 8.5 | G13: =VLOOKUP(A13,Custo!A:B,2,0) -> 3.9825213 | H13: =(VLOOKUP(A13,Peso!$A$10:$B$148,2,0))*($B$6/1000) -> 0.335 | I13: =IF($I$7="X",AE13,0%) -> 0.05 | J13: =+B13*I13 -> 0.475 | K13: =IF($B$2="X",$C$2,0) -> 0 | L13: =+B13*K13 -> 0 | M13: =+G13+H13+J13+L13 -> 4.7925213 | N13: =+E13-M13 -> 4.0424787 | O13: =IF(ISERROR((N13/P13)*1000),"",(N13/P13)*1000) | Q13: =VLOOKUP(A13,'MVA-IPI'!A:AD,30,FALSE) -> 0 | R13: =IF($B$4="AM",0,IF($B$4="AP",0,IF($B$4="RR",0,(B13*Q13)))) -> 0 | S13: =IF($B$4="AP",(B13/0.88*$S$8),IF(T13=0%,0,IF($B$4="AM",(B13/0.88*$S$8),IF(T13=0%,0,IF($B$4="RR",(B13/0.88*$S$8),IF(T13=0%,0,B13*$S$8)))))) -> 0 | T13: =IF($C$4="GRUPO 1",VLOOKUP(A13,'MVA-grupos'!$A$9:$B$128,2,FALSE),IF($C$4="GRUPO 2",VLOOKUP(A13,'MVA-grupos'!$A$9:$D$128,4,FALSE),IF($C$4="GRUPO 3",VLOOKUP(A13,'MVA-grupos'!$A$10:$F$128,6,FALSE),IF($C$4="Grupo 4",VLOOKUP(A13,'MVA-grupos'!$A$9:$H$128,8,FALSE))))) -> 0 | U13: =IF(T13=0%,0,(B13+R13)*T13+(B13+R13)) -> 0 | V13: =(U13*$V$8)-S13 -> 0 | X13: =A13 -> BRAZIMIL ECONÔMICA 3,0L REFIL COR | Y13: =+C13 -> 0 | Z13: =IF(ISERROR(Y13*N13),"",Y13*N13) -> 0 | AA13: =IF(ISERROR(IF(E$7="X",Y13*E13,Y13*F13)),"",IF(E$7="X",Y13*E13,Y13*F13)) -> 0 | AB13: =IF(ISERROR(Z13/AA13),"",Z13/AA13) | AE13: 0.05 | AF13: =+'Frete_Regiao-Impostos'!A5 -> 0 | AG13: =+'Frete_Regiao-Impostos'!B5 -> 0 | AH13: =+'Frete_Regiao-Impostos'!C5 -> 0 | AI13: =+'Frete_Regiao-Impostos'!D5 -> 0 | AP13: =Peso!B13 -> 3.35
A14: BRAZIMIL ECONÔMICA 3,0L GALÃO BRANCO NEVE | B14: 17.99 | D14: =IF($F$7="x",IF(F14=0,0,N14/F14),IF($E$7="x",IF(F14=0,0,N14/E14),"")) -> 0.44594169 | E14: =+B14*(-B$5+100%) -> 16.7307 | F14: =IF(B14=0,0,E14-H14) -> 16.3307 | G14: =VLOOKUP(A14,Custo!A:B,2,0) -> 7.9702833 | H14: =(VLOOKUP(A14,Peso!$A$10:$B$148,2,0))*($B$6/1000) -> 0.4 | I14: =IF($I$7="X",AE14,0%) -> 0.05 | J14: =+B14*I14 -> 0.8995 | K14: =IF($B$2="X",$C$2,0) -> 0 | L14: =+B14*K14 -> 0 | M14: =+G14+H14+J14+L14 -> 9.2697833 | N14: =+E14-M14 -> 7.4609167 | O14: =IF(ISERROR((N14/P14)*1000),"",(N14/P14)*1000) | Q14: =VLOOKUP(A14,'MVA-IPI'!A:AD,30,FALSE) -> 0 | R14: =IF($B$4="AM",0,IF($B$4="AP",0,IF($B$4="RR",0,(B14*Q14)))) -> 0 | S14: =IF($B$4="AP",(B14/0.88*$S$8),IF(T14=0%,0,IF($B$4="AM",(B14/0.88*$S$8),IF(T14=0%,0,IF($B$4="RR",(B14/0.88*$S$8),IF(T14=0%,0,B14*$S$8)))))) -> 0 | T14: =IF($C$4="GRUPO 1",VLOOKUP(A14,'MVA-grupos'!$A$9:$B$128,2,FALSE),IF($C$4="GRUPO 2",VLOOKUP(A14,'MVA-grupos'!$A$9:$D$128,4,FALSE),IF($C$4="GRUPO 3",VLOOKUP(A14,'MVA-grupos'!$A$10:$F$128,6,FALSE),IF($C$4="Grupo 4",VLOOKUP(A14,'MVA-grupos'!$A$9:$H$128,8,FALSE))))) -> 0 | U14: =IF(T14=0%,0,(B14+R14)*T14+(B14+R14)) -> 0 | V14: =(U14*$V$8)-S14 -> 0 | X14: =A14 -> BRAZIMIL ECONÔMICA 3,0L GALÃO BRANCO NEVE | Y14: =+C14 -> 0 | Z14: =IF(ISERROR(Y14*N14),"",Y14*N14) -> 0 | AA14: =IF(ISERROR(IF(E$7="X",Y14*E14,Y14*F14)),"",IF(E$7="X",Y14*E14,Y14*F14)) -> 0 | AB14: =IF(ISERROR(Z14/AA14),"",Z14/AA14) | AE14: 0.05 | AF14: =+'Frete_Regiao-Impostos'!A6 -> 0 | AG14: =+'Frete_Regiao-Impostos'!B6 -> 0 | AH14: =+'Frete_Regiao-Impostos'!C6 -> 0 | AI14: =+'Frete_Regiao-Impostos'!D6 -> 0 | AP14: =Peso!B14 -> 4
A15: BRAZIMIL ECONÔMICA 3,0L GALÃO COR | B15: 17.99 | D15: =IF($F$7="x",IF(F15=0,0,N15/F15),IF($E$7="x",IF(F15=0,0,N15/E15),"")) -> 0.47981726 | E15: =+B15*(-B$5+100%) -> 16.7307 | F15: =IF(B15=0,0,E15-H15) -> 16.3807 | G15: =VLOOKUP(A15,Custo!A:B,2,0) -> 7.4535213 | H15: =(VLOOKUP(A15,Peso!$A$10:$B$148,2,0))*($B$6/1000) -> 0.35 | I15: =IF($I$7="X",AE15,0%) -> 0.05 | J15: =+B15*I15 -> 0.8995 | K15: =IF($B$2="X",$C$2,0) -> 0 | L15: =+B15*K15 -> 0 | M15: =+G15+H15+J15+L15 -> 8.7030213 | N15: =+E15-M15 -> 8.0276787 | O15: =IF(ISERROR((N15/P15)*1000),"",(N15/P15)*1000) | Q15: =VLOOKUP(A15,'MVA-IPI'!A:AD,30,FALSE) -> 0 | R15: =IF($B$4="AM",0,IF($B$4="AP",0,IF($B$4="RR",0,(B15*Q15)))) -> 0 | S15: =IF($B$4="AP",(B15/0.88*$S$8),IF(T15=0%,0,IF($B$4="AM",(B15/0.88*$S$8),IF(T15=0%,0,IF($B$4="RR",(B15/0.88*$S$8),IF(T15=0%,0,B15*$S$8)))))) -> 0 | T15: =IF($C$4="GRUPO 1",VLOOKUP(A15,'MVA-grupos'!$A$9:$B$128,2,FALSE),IF($C$4="GRUPO 2",VLOOKUP(A15,'MVA-grupos'!$A$9:$D$128,4,FALSE),IF($C$4="GRUPO 3",VLOOKUP(A15,'MVA-grupos'!$A$10:$F$128,6,FALSE),IF($C$4="Grupo 4",VLOOKUP(A15,'MVA-grupos'!$A$9:$H$128,8,FALSE))))) -> 0 | U15: =IF(T15=0%,0,(B15+R15)*T15+(B15+R15)) -> 0 | V15: =(U15*$V$8)-S15 -> 0 | X15: =A15 -> BRAZIMIL ECONÔMICA 3,0L GALÃO COR | Y15: =+C15 -> 0 | Z15: =IF(ISERROR(Y15*N15),"",Y15*N15) -> 0 | AA15: =IF(ISERROR(IF(E$7="X",Y15*E15,Y15*F15)),"",IF(E$7="X",Y15*E15,Y15*F15)) -> 0 | AB15: =IF(ISERROR(Z15/AA15),"",Z15/AA15) | AE15: 0.05 | AF15: =+'Frete_Regiao-Impostos'!A7 -> 0 | AG15: =+'Frete_Regiao-Impostos'!B7 -> 0 | AH15: =+'Frete_Regiao-Impostos'!C7 -> 0 | AI15: =+'Frete_Regiao-Impostos'!D7 -> 0 | AP15: =Peso!B15 -> 3.5
A16: BRAZIMIL ECONÔMICA 15L | D16: =AB16 | X16: =A16 -> BRAZIMIL ECONÔMICA 15L | Z16: =SUM(Z17:Z20) -> 0 | AA16: =SUM(AA17:AA20) -> 0 | AB16: =IF(ISERROR(Z16/AA16),"",Z16/AA16) | AC16: 0.25 | AF16: =+'Frete_Regiao-Impostos'!A8 -> 0 | AG16: =+'Frete_Regiao-Impostos'!B8 -> 0 | AH16: =+'Frete_Regiao-Impostos'!C8 -> 0 | AI16: =+'Frete_Regiao-Impostos'!D8 -> 0 | AP16: =Peso!B16 -> 0
A17: BRAZIMIL ECONÔMICA 15L PPQ BRANCO NEVE | D17: =IF($F$7="x",IF(F17=0,0,N17/F17),IF($E$7="x",IF(F17=0,0,N17/E17),"")) -> 0 | E17: =+B17*(-B$5+100%) -> 0 | F17: =IF(B17=0,0,E17-H17) -> 0 | G17: =VLOOKUP(A17,Custo!A:B,2,0) -> 0 | H17: =(VLOOKUP(A17,Peso!$A$10:$B$148,2,0))*($B$6/1000) -> 1.87 | I17: =IF($I$7="X",AE17,0%) -> 0.06 | J17: =+B17*I17 -> 0 | M17: =+G17+H17+J17 -> 1.87 | N17: =+E17-M17 -> -1.87 | O17: =IF(ISERROR((N17/P17)*1000),"",(N17/P17)*1000) | Q17: =VLOOKUP(A17,'MVA-IPI'!A:AD,30,FALSE) -> 0 | R17: =IF($B$4="AM",0,IF($B$4="AP",0,IF($B$4="RR",0,(B17*Q17)))) -> 0 | S17: =IF($B$4="AP",(B17/0.88*$S$8),IF(T17=0%,0,IF($B$4="AM",(B17/0.88*$S$8),IF(T17=0%,0,IF($B$4="RR",(B17/0.88*$S$8),IF(T17=0%,0,B17*$S$8)))))) -> 0 | T17: =IF($C$4="GRUPO 1",VLOOKUP(A17,'MVA-grupos'!$A$9:$B$128,2,FALSE),IF($C$4="GRUPO 2",VLOOKUP(A17,'MVA-grupos'!$A$9:$D$128,4,FALSE),IF($C$4="GRUPO 3",VLOOKUP(A17,'MVA-grupos'!$A$10:$F$128,6,FALSE),IF($C$4="Grupo 4",VLOOKUP(A17,'MVA-grupos'!$A$9:$H$128,8,FALSE))))) -> 0 | U17: =IF(T17=0%,0,(B17+R17)*T17+(B17+R17)) -> 0 | V17: =(U17*$V$8)-S17 -> 0 | X17: =A17 -> BRAZIMIL ECONÔMICA 15L PPQ BRANCO NEVE | Y17: =+C17 -> 0 | Z17: =IF(ISERROR(Y17*N17),"",Y17*N17) -> 0 | AA17: =IF(ISERROR(IF(E$7="X",Y17*E17,Y17*F17)),"",IF(E$7="X",Y17*E17,Y17*F17)) -> 0 | AB17: =IF(ISERROR(Z17/AA17),"",Z17/AA17) | AE17: 0.06 | AF17: =+'Frete_Regiao-Impostos'!A38 -> 0 | AG17: =+'Frete_Regiao-Impostos'!B38 -> 0 | AH17: =+'Frete_Regiao-Impostos'!C38 -> 0 | AI17: =+'Frete_Regiao-Impostos'!D38 -> 0 | AP17: =Peso!B17 -> 18.7
A18: BRAZIMIL ECONÔMICA 12L BALDE BRANCO NEVE | B18: 0 | D18: =IF($F$7="x",IF(F18=0,0,N18/F18),IF($E$7="x",IF(F18=0,0,N18/E18),"")) -> 0 | E18: =+B18*(-B$5+100%) -> 0 | F18: =IF(B18=0,0,E18-H18) -> 0 | G18: =VLOOKUP(A18,Custo!A:B,2,0) -> 25.763717 | H18: =(VLOOKUP(A18,Peso!$A$10:$B$148,2,0))*($B$6/1000) -> 1.44 | I18: =IF($I$7="X",AE18,0%) -> 0.05 | J18: =+B18*I18 -> 0 | L18: =+B18*K18 -> 0 | M18: =+G18+H18+J18+L18 -> 27.203717 | N18: =+E18-M18 -> -27.203717 | O18: =IF(ISERROR((N18/P18)*1000),"",(N18/P18)*1000) | Q18: =VLOOKUP(A18,'MVA-IPI'!A:AD,30,FALSE) -> 0 | R18: =IF($B$4="AM",0,IF($B$4="AP",0,IF($B$4="RR",0,(B18*Q18)))) -> 0 | S18: =IF($B$4="AP",(B18/0.88*$S$8),IF(T18=0%,0,IF($B$4="AM",(B18/0.88*$S$8),IF(T18=0%,0,IF($B$4="RR",(B18/0.88*$S$8),IF(T18=0%,0,B18*$S$8)))))) -> 0 | T18: =IF($C$4="GRUPO 1",VLOOKUP(A18,'MVA-grupos'!$A$9:$B$128,2,FALSE),IF($C$4="GRUPO 2",VLOOKUP(A18,'MVA-grupos'!$A$9:$D$128,4,FALSE),IF($C$4="GRUPO 3",VLOOKUP(A18,'MVA-grupos'!$A$10:$F$128,6,FALSE),IF($C$4="Grupo 4",VLOOKUP(A18,'MVA-grupos'!$A$9:$H$128,8,FALSE))))) -> 0 | U18: =IF(T18=0%,0,(B18+R18)*T18+(B18+R18)) -> 0 | V18: =(U18*$V$8)-S18 -> 0 | X18: =A18 -> BRAZIMIL ECONÔMICA 12L BALDE BRANCO NEVE | Y18: =+C18 -> 0 | Z18: =IF(ISERROR(Y18*N18),"",Y18*N18) -> 0 | AA18: =IF(ISERROR(IF(E$7="X",Y18*E18,Y18*F18)),"",IF(E$7="X",Y18*E18,Y18*F18)) -> 0 | AB18: =IF(ISERROR(Z18/AA18),"",Z18/AA18) | AE18: 0.05 | AF18: =+'Frete_Regiao-Impostos'!A39 -> 0 | AG18: =+'Frete_Regiao-Impostos'!B39 -> 0 | AH18: =+'Frete_Regiao-Impostos'!C39 -> 0 | AI18: =+'Frete_Regiao-Impostos'!D39 -> 0 | AP18: =Peso!B18 -> 14.4
A19: BRAZIMIL ECONÔMICA 15L BALDE BRANCO NEVE | B19: 58 | D19: =IF($F$7="x",IF(F19=0,0,N19/F19),IF($E$7="x",IF(F19=0,0,N19/E19),"")) -> 0.30387761 | E19: =+B19*(-B$5+100%) -> 53.94 | F19: =IF(B19=0,0,E19-H19) -> 52.07 | G19: =VLOOKUP(A19,Custo!A:B,2,0) -> 32.778842 | H19: =(VLOOKUP(A19,Peso!$A$10:$B$148,2,0))*($B$6/1000) -> 1.87 | I19: =IF($I$7="X",AE19,0%) -> 0.05 | J19: =+B19*I19 -> 2.9 | K19: =IF($B$2="X",$C$2,0) -> 0 | L19: =+B19*K19 -> 0 | M19: =+G19+H19+J19+L19 -> 37.548842 | N19: =+E19-M19 -> 16.391158 | O19: =IF(ISERROR((N19/P19)*1000),"",(N19/P19)*1000) | Q19: =VLOOKUP(A19,'MVA-IPI'!A:AD,30,FALSE) -> 0 | R19: =IF($B$4="AM",0,IF($B$4="AP",0,IF($B$4="RR",0,(B19*Q19)))) -> 0 | S19: =IF($B$4="AP",(B19/0.88*$S$8),IF(T19=0%,0,IF($B$4="AM",(B19/0.88*$S$8),IF(T19=0%,0,IF($B$4="RR",(B19/0.88*$S$8),IF(T19=0%,0,B19*$S$8)))))) -> 0 | T19: =IF($C$4="GRUPO 1",VLOOKUP(A19,'MVA-grupos'!$A$9:$B$128,2,FALSE),IF($C$4="GRUPO 2",VLOOKUP(A19,'MVA-grupos'!$A$9:$D$128,4,FALSE),IF($C$4="GRUPO 3",VLOOKUP(A19,'MVA-grupos'!$A$10:$F$128,6,FALSE),IF($C$4="Grupo 4",VLOOKUP(A19,'MVA-grupos'!$A$9:$H$128,8,FALSE))))) -> 0 | U19: =IF(T19=0%,0,(B19+R19)*T19+(B19+R19)) -> 0 | V19: =(U19*$V$8)-S19 -> 0 | X19: =A19 -> BRAZIMIL ECONÔMICA 15L BALDE BRANCO NEVE | Y19: =+C19 -> 0 | Z19: =IF(ISERROR(Y19*N19),"",Y19*N19) -> 0 | AA19: =IF(ISERROR(IF(E$7="X",Y19*E19,Y19*F19)),"",IF(E$7="X",Y19*E19,Y19*F19)) -> 0 | AB19: =IF(ISERROR(Z19/AA19),"",Z19/AA19) | AE19: 0.05 | AF19: =+'Frete_Regiao-Impostos'!A10 -> 0 | AG19: =+'Frete_Regiao-Impostos'!B10 -> 0 | AH19: =+'Frete_Regiao-Impostos'!C10 -> 0 | AI19: =+'Frete_Regiao-Impostos'!D10 -> 0 | AP19: =Peso!B19 -> 18.7
A20: BRAZIMIL ECONÔMICA 15L BALDE COR | B20: 69.9 | D20: =IF($F$7="x",IF(F20=0,0,N20/F20),IF($E$7="x",IF(F20=0,0,N20/E20),"")) -> 0.4675206 | E20: =+B20*(-B$5+100%) -> 65.007 | F20: =IF(B20=0,0,E20-H20) -> 63.307 | G20: =VLOOKUP(A20,Custo!A:B,2,0) -> 29.419889 | H20: =(VLOOKUP(A20,Peso!$A$10:$B$148,2,0))*($B$6/1000) -> 1.7 | I20: =IF($I$7="X",AE20,0%) -> 0.05 | J20: =+B20*I20 -> 3.495 | K20: =IF($B$2="X",$C$2,0) -> 0 | L20: =+B20*K20 -> 0 | M20: =+G20+H20+J20+L20 -> 34.614889 | N20: =+E20-M20 -> 30.392111 | O20: =IF(ISERROR((N20/P20)*1000),"",(N20/P20)*1000) | Q20: =VLOOKUP(A20,'MVA-IPI'!A:AD,30,FALSE) -> 0 | R20: =IF($B$4="AM",0,IF($B$4="AP",0,IF($B$4="RR",0,(B20*Q20)))) -> 0 | S20: =IF($B$4="AP",(B20/0.88*$S$8),IF(T20=0%,0,IF($B$4="AM",(B20/0.88*$S$8),IF(T20=0%,0,IF($B$4="RR",(B20/0.88*$S$8),IF(T20=0%,0,B20*$S$8)))))) -> 0 | T20: =IF($C$4="GRUPO 1",VLOOKUP(A20,'MVA-grupos'!$A$9:$B$128,2,FALSE),IF($C$4="GRUPO 2",VLOOKUP(A20,'MVA-grupos'!$A$9:$D$128,4,FALSE),IF($C$4="GRUPO 3",VLOOKUP(A20,'MVA-grupos'!$A$10:$F$128,6,FALSE),IF($C$4="Grupo 4",VLOOKUP(A20,'MVA-grupos'!$A$9:$H$128,8,FALSE))))) -> 0 | U20: =IF(T20=0%,0,(B20+R20)*T20+(B20+R20)) -> 0 | V20: =(U20*$V$8)-S20 -> 0 | X20: =A20 -> BRAZIMIL ECONÔMICA 15L BALDE COR | Y20: =+C20 -> 0 | Z20: =IF(ISERROR(Y20*N20),"",Y20*N20) -> 0 | AA20: =IF(ISERROR(IF(E$7="X",Y20*E20,Y20*F20)),"",IF(E$7="X",Y20*E20,Y20*F20)) -> 0 | AB20: =IF(ISERROR(Z20/AA20),"",Z20/AA20) | AE20: 0.05 | AF20: =+'Frete_Regiao-Impostos'!A11 -> 0 | AG20: =+'Frete_Regiao-Impostos'!B11 -> 0 | AH20: =+'Frete_Regiao-Impostos'!C11 -> 0 | AI20: =+'Frete_Regiao-Impostos'!D11 -> 0 | AP20: =Peso!B20 -> 17
A21: BRAZIMIL EXTERNA 3,0L | D21: =AB21 | X21: =A21 -> BRAZIMIL EXTERNA 3,0L | Z21: =SUM(Z22:Z23) -> 0 | AA21: =SUM(AA22:AA23) -> 0 | AB21: =IF(ISERROR(Z21/AA21),"",Z21/AA21) | AC21: 0.25 | AF21: =+'Frete_Regiao-Impostos'!A12 -> 0 | AG21: =+'Frete_Regiao-Impostos'!B12 -> 0 | AH21: =+'Frete_Regiao-Impostos'!C12 -> 0 | AI21: =+'Frete_Regiao-Impostos'!D12 -> 0 | AP21: =Peso!B21 -> 0
A22: BRAZIMIL EXTERNA 3,0L BALDE BRANCO NEVE | B22: 26 | D22: =IF($F$7="x",IF(F22=0,0,N22/F22),IF($E$7="x",IF(F22=0,0,N22/E22),"")) -> 0.46348735 | E22: =+B22*(-B$5+100%) -> 24.18 | F22: =IF(B22=0,0,E22-H22) -> 23.76 | G22: =VLOOKUP(A22,Custo!A:B,2,0) -> 11.252876 | H22: =(VLOOKUP(A22,Peso!$A$10:$B$148,2,0))*($B$6/1000) -> 0.42 | I22: =IF($I$7="X",AE22,0%) -> 0.05 | J22: =+B22*I22 -> 1.3 | K22: =IF($B$2="X",$C$2,0) -> 0 | L22: =+B22*K22 -> 0 | M22: =+G22+H22+J22+L22 -> 12.972876 | N22: =+E22-M22 -> 11.207124 | O22: =IF(ISERROR((N22/P22)*1000),"",(N22/P22)*1000) | Q22: =VLOOKUP(A22,'MVA-IPI'!A:AD,30,FALSE) -> 0 | R22: =IF($B$4="AM",0,IF($B$4="AP",0,IF($B$4="RR",0,(B22*Q22)))) -> 0 | S22: =IF($B$4="AP",(B22/0.88*$S$8),IF(T22=0%,0,IF($B$4="AM",(B22/0.88*$S$8),IF(T22=0%,0,IF($B$4="RR",(B22/0.88*$S$8),IF(T22=0%,0,B22*$S$8)))))) -> 0 | T22: =IF($C$4="GRUPO 1",VLOOKUP(A22,'MVA-grupos'!$A$9:$B$128,2,FALSE),IF($C$4="GRUPO 2",VLOOKUP(A22,'MVA-grupos'!$A$9:$D$128,4,FALSE),IF($C$4="GRUPO 3",VLOOKUP(A22,'MVA-grupos'!$A$10:$F$128,6,FALSE),IF($C$4="Grupo 4",VLOOKUP(A22,'MVA-grupos'!$A$9:$H$128,8,FALSE))))) -> 0 | U22: =IF(T22=0%,0,(B22+R22)*T22+(B22+R22)) -> 0 | V22: =(U22*$V$8)-S22 -> 0 | X22: =A22 -> BRAZIMIL EXTERNA 3,0L BALDE BRANCO NEVE | Y22: =+C22 -> 0 | Z22: =IF(ISERROR(Y22*N22),"",Y22*N22) -> 0 | AA22: =IF(ISERROR(IF(E$7="X",Y22*E22,Y22*F22)),"",IF(E$7="X",Y22*E22,Y22*F22)) -> 0 | AB22: =IF(ISERROR(Z22/AA22),"",Z22/AA22) | AE22: 0.05 | AF22: =+'Frete_Regiao-Impostos'!A13 -> 0 | AG22: =+'Frete_Regiao-Impostos'!B13 -> 0 | AH22: =+'Frete_Regiao-Impostos'!C13 -> 0 | AI22: =+'Frete_Regiao-Impostos'!D13 -> 0 | AP22: =Peso!B22 -> 4.2
A23: BRAZIMIL EXTERNA 3,0L BALDE COR | B23: 24.2 | D23: =IF($F$7="x",IF(F23=0,0,N23/F23),IF($E$7="x",IF(F23=0,0,N23/E23),"")) -> 0.51154588 | E23: =+B23*(-B$5+100%) -> 22.506 | F23: =IF(B23=0,0,E23-H23) -> 22.116 | G23: =VLOOKUP(A23,Custo!A:B,2,0) -> 9.3931485 | H23: =(VLOOKUP(A23,Peso!$A$10:$B$148,2,0))*($B$6/1000) -> 0.39 | I23: =IF($I$7="X",AE23,0%) -> 0.05 | J23: =+B23*I23 -> 1.21 | K23: =IF($B$2="X",$C$2,0) -> 0 | L23: =+B23*K23 -> 0 | M23: =+G23+H23+J23+L23 -> 10.993148 | N23: =+E23-M23 -> 11.512852 | O23: =IF(ISERROR((N23/P23)*1000),"",(N23/P23)*1000) | Q23: =VLOOKUP(A23,'MVA-IPI'!A:AD,30,FALSE) -> 0 | R23: =IF($B$4="AM",0,IF($B$4="AP",0,IF($B$4="RR",0,(B23*Q23)))) -> 0 | S23: =IF($B$4="AP",(B23/0.88*$S$8),IF(T23=0%,0,IF($B$4="AM",(B23/0.88*$S$8),IF(T23=0%,0,IF($B$4="RR",(B23/0.88*$S$8),IF(T23=0%,0,B23*$S$8)))))) -> 0 | T23: =IF($C$4="GRUPO 1",VLOOKUP(A23,'MVA-grupos'!$A$9:$B$128,2,FALSE),IF($C$4="GRUPO 2",VLOOKUP(A23,'MVA-grupos'!$A$9:$D$128,4,FALSE),IF($C$4="GRUPO 3",VLOOKUP(A23,'MVA-grupos'!$A$10:$F$128,6,FALSE),IF($C$4="Grupo 4",VLOOKUP(A23,'MVA-grupos'!$A$9:$H$128,8,FALSE))))) -> 0 | U23: =IF(T23=0%,0,(B23+R23)*T23+(B23+R23)) -> 0 | V23: =(U23*$V$8)-S23 -> 0 | X23: =A23 -> BRAZIMIL EXTERNA 3,0L BALDE COR | Y23: =+C23 -> 0 | Z23: =IF(ISERROR(Y23*N23),"",Y23*N23) -> 0 | AA23: =IF(ISERROR(IF(E$7="X",Y23*E23,Y23*F23)),"",IF(E$7="X",Y23*E23,Y23*F23)) -> 0 | AB23: =IF(ISERROR(Z23/AA23),"",Z23/AA23) | AE23: 0.05 | AF23: =+'Frete_Regiao-Impostos'!A14 -> 0 | AG23: =+'Frete_Regiao-Impostos'!B14 -> 0 | AH23: =+'Frete_Regiao-Impostos'!C14 -> 0 | AI23: =+'Frete_Regiao-Impostos'!D14 -> 0 | AP23: =Peso!B23 -> 3.9
A24: BRAZIMIL EXTERNA 15L | D24: =AB24 | X24: =A24 -> BRAZIMIL EXTERNA 15L | Z24: =SUM(Z25:Z26) -> 0 | AA24: =SUM(AA25:AA26) -> 0 | AB24: =IF(ISERROR(Z24/AA24),"",Z24/AA24) | AC24: 0.25 | AF24: =+'Frete_Regiao-Impostos'!A15 -> 0 | AG24: =+'Frete_Regiao-Impostos'!B15 -> 0 | AH24: =+'Frete_Regiao-Impostos'!C15 -> 0 | AI24: =+'Frete_Regiao-Impostos'!D15 -> 0 | AP24: =Peso!B24 -> 0
A25: BRAZIMIL EXTERNA 15L BALDE BRANCO NEVE | B25: 94 | D25: =IF($F$7="x",IF(F25=0,0,N25/F25),IF($E$7="x",IF(F25=0,0,N25/E25),"")) -> 0.30961014 | E25: =+B25*(-B$5+100%) -> 87.42 | F25: =IF(B25=0,0,E25-H25) -> 85.52 | G25: =VLOOKUP(A25,Custo!A:B,2,0) -> 53.753882 | H25: =(VLOOKUP(A25,Peso!$A$10:$B$148,2,0))*($B$6/1000) -> 1.9 | I25: =IF($I$7="X",AE25,0%) -> 0.05 | J25: =+B25*I25 -> 4.7 | K25: =IF($B$2="X",$C$2,0) -> 0 | L25: =+B25*K25 -> 0 | M25: =+G25+H25+J25+L25 -> 60.353882 | N25: =+E25-M25 -> 27.066118 | O25: =IF(ISERROR((N25/P25)*1000),"",(N25/P25)*1000) | Q25: =VLOOKUP(A25,'MVA-IPI'!A:AD,30,FALSE) -> 0 | R25: =IF($B$4="AM",0,IF($B$4="AP",0,IF($B$4="RR",0,(B25*Q25)))) -> 0 | S25: =IF($B$4="AP",(B25/0.88*$S$8),IF(T25=0%,0,IF($B$4="AM",(B25/0.88*$S$8),IF(T25=0%,0,IF($B$4="RR",(B25/0.88*$S$8),IF(T25=0%,0,B25*$S$8)))))) -> 0 | T25: =IF($C$4="GRUPO 1",VLOOKUP(A25,'MVA-grupos'!$A$9:$B$128,2,FALSE),IF($C$4="GRUPO 2",VLOOKUP(A25,'MVA-grupos'!$A$9:$D$128,4,FALSE),IF($C$4="GRUPO 3",VLOOKUP(A25,'MVA-grupos'!$A$10:$F$128,6,FALSE),IF($C$4="Grupo 4",VLOOKUP(A25,'MVA-grupos'!$A$9:$H$128,8,FALSE))))) -> 0 | U25: =IF(T25=0%,0,(B25+R25)*T25+(B25+R25)) -> 0 | V25: =(U25*$V$8)-S25 -> 0 | X25: =A25 -> BRAZIMIL EXTERNA 15L BALDE BRANCO NEVE | Y25: =+C25 -> 0 | Z25: =IF(ISERROR(Y25*N25),"",Y25*N25) -> 0 | AA25: =IF(ISERROR(IF(E$7="X",Y25*E25,Y25*F25)),"",IF(E$7="X",Y25*E25,Y25*F25)) -> 0 | AB25: =IF(ISERROR(Z25/AA25),"",Z25/AA25) | AE25: 0.05 | AF25: =+'Frete_Regiao-Impostos'!A16 -> 0 | AG25: =+'Frete_Regiao-Impostos'!B16 -> 0 | AH25: =+'Frete_Regiao-Impostos'!C16 -> 0 | AI25: =+'Frete_Regiao-Impostos'!D16 -> 0 | AP25: =Peso!B25 -> 19
A26: BRAZIMIL EXTERNA 15L BALDE COR | B26: 90.11 | D26: =IF($F$7="x",IF(F26=0,0,N26/F26),IF($E$7="x",IF(F26=0,0,N26/E26),"")) -> 0.42543208 | E26: =+B26*(-B$5+100%) -> 83.8023 | F26: =IF(B26=0,0,E26-H26) -> 82.1023 | G26: =VLOOKUP(A26,Custo!A:B,2,0) -> 41.944613 | H26: =(VLOOKUP(A26,Peso!$A$10:$B$148,2,0))*($B$6/1000) -> 1.7 | I26: =IF($I$7="X",AE26,0%) -> 0.05 | J26: =+B26*I26 -> 4.5055 | K26: =IF($B$2="X",$C$2,0) -> 0 | L26: =+B26*K26 -> 0 | M26: =+G26+H26+J26+L26 -> 48.150113 | N26: =+E26-M26 -> 35.652187 | O26: =IF(ISERROR((N26/P26)*1000),"",(N26/P26)*1000) | Q26: =VLOOKUP(A26,'MVA-IPI'!A:AD,30,FALSE) -> 0 | R26: =IF($B$4="AM",0,IF($B$4="AP",0,IF($B$4="RR",0,(B26*Q26)))) -> 0 | S26: =IF($B$4="AP",(B26/0.88*$S$8),IF(T26=0%,0,IF($B$4="AM",(B26/0.88*$S$8),IF(T26=0%,0,IF($B$4="RR",(B26/0.88*$S$8),IF(T26=0%,0,B26*$S$8)))))) -> 0 | T26: =IF($C$4="GRUPO 1",VLOOKUP(A26,'MVA-grupos'!$A$9:$B$128,2,FALSE),IF($C$4="GRUPO 2",VLOOKUP(A26,'MVA-grupos'!$A$9:$D$128,4,FALSE),IF($C$4="GRUPO 3",VLOOKUP(A26,'MVA-grupos'!$A$10:$F$128,6,FALSE),IF($C$4="Grupo 4",VLOOKUP(A26,'MVA-grupos'!$A$9:$H$128,8,FALSE))))) -> 0 | U26: =IF(T26=0%,0,(B26+R26)*T26+(B26+R26)) -> 0 | V26: =(U26*$V$8)-S26 -> 0 | X26: =A26 -> BRAZIMIL EXTERNA 15L BALDE COR | Y26: =+C26 -> 0 | Z26: =IF(ISERROR(Y26*N26),"",Y26*N26) -> 0 | AA26: =IF(ISERROR(IF(E$7="X",Y26*E26,Y26*F26)),"",IF(E$7="X",Y26*E26,Y26*F26)) -> 0 | AB26: =IF(ISERROR(Z26/AA26),"",Z26/AA26) | AE26: 0.05 | AF26: =+'Frete_Regiao-Impostos'!A17 -> 0 | AG26: =+'Frete_Regiao-Impostos'!B17 -> 0 | AH26: =+'Frete_Regiao-Impostos'!C17 -> 0 | AI26: =+'Frete_Regiao-Impostos'!D17 -> 0 | AP26: =Peso!B26 -> 17
A27: BRAZIMIL SEMI BRILHO 3,0L | D27: =AB27 | X27: =A27 -> BRAZIMIL SEMI BRILHO 3,0L | Z27: =SUM(Z28:Z29) -> 0 | AA27: =SUM(AA28:AA29) -> 0 | AB27: =IF(ISERROR(Z27/AA27),"",Z27/AA27) | AC27: 0.25 | AF27: =+'Frete_Regiao-Impostos'!A18 -> 0 | AG27: =+'Frete_Regiao-Impostos'!B18 -> 0 | AH27: =+'Frete_Regiao-Impostos'!C18 -> 0 | AI27: =+'Frete_Regiao-Impostos'!D18 -> 0 | AP27: =Peso!B27 -> 0
A28: BRAZIMIL SEMI BRILHO 3,0L BALDE BRANCO NEVE | B28: 43 | D28: =IF($F$7="x",IF(F28=0,0,N28/F28),IF($E$7="x",IF(F28=0,0,N28/E28),"")) -> 0.64685165 | E28: =+B28*(-B$5+100%) -> 39.99 | F28: =IF(B28=0,0,E28-H28) -> 39.63 | G28: =VLOOKUP(A28,Custo!A:B,2,0) -> 11.612403 | H28: =(VLOOKUP(A28,Peso!$A$10:$B$148,2,0))*($B$6/1000) -> 0.36 | I28: =IF($I$7="X",AE28,0%) -> 0.05 | J28: =+B28*I28 -> 2.15 | K28: =IF($B$2="X",$C$2,0) -> 0 | L28: =+B28*K28 -> 0 | M28: =+G28+H28+J28+L28 -> 14.122403 | N28: =+E28-M28 -> 25.867597 | O28: =IF(ISERROR((N28/P28)*1000),"",(N28/P28)*1000) | Q28: =VLOOKUP(A28,'MVA-IPI'!A:AD,30,FALSE) -> 0 | R28: =IF($B$4="AM",0,IF($B$4="AP",0,IF($B$4="RR",0,(B28*Q28)))) -> 0 | S28: =IF($B$4="AP",(B28/0.88*$S$8),IF(T28=0%,0,IF($B$4="AM",(B28/0.88*$S$8),IF(T28=0%,0,IF($B$4="RR",(B28/0.88*$S$8),IF(T28=0%,0,B28*$S$8)))))) -> 0 | T28: =IF($C$4="GRUPO 1",VLOOKUP(A28,'MVA-grupos'!$A$9:$B$128,2,FALSE),IF($C$4="GRUPO 2",VLOOKUP(A28,'MVA-grupos'!$A$9:$D$128,4,FALSE),IF($C$4="GRUPO 3",VLOOKUP(A28,'MVA-grupos'!$A$10:$F$128,6,FALSE),IF($C$4="Grupo 4",VLOOKUP(A28,'MVA-grupos'!$A$9:$H$128,8,FALSE))))) -> 0 | U28: =IF(T28=0%,0,(B28+R28)*T28+(B28+R28)) -> 0 | V28: =(U28*$V$8)-S28 -> 0 | X28: =A28 -> BRAZIMIL SEMI BRILHO 3,0L BALDE BRANCO NEVE | Y28: =+C28 -> 0 | Z28: =IF(ISERROR(Y28*N28),"",Y28*N28) -> 0 | AA28: =IF(ISERROR(IF(E$7="X",Y28*E28,Y28*F28)),"",IF(E$7="X",Y28*E28,Y28*F28)) -> 0 | AB28: =IF(ISERROR(Z28/AA28),"",Z28/AA28) | AE28: 0.05 | AF28: =+'Frete_Regiao-Impostos'!A19 -> 0 | AG28: =+'Frete_Regiao-Impostos'!B19 -> 0 | AH28: =+'Frete_Regiao-Impostos'!C19 -> 0 | AI28: =+'Frete_Regiao-Impostos'!D19 -> 0 | AP28: =Peso!B28 -> 3.6
A29: BRAZIMIL SEMI BRILHO 3,0L BALDE COR | B29: 35 | D29: =IF($F$7="x",IF(F29=0,0,N29/F29),IF($E$7="x",IF(F29=0,0,N29/E29),"")) -> 0.47050906 | E29: =+B29*(-B$5+100%) -> 32.55 | F29: =IF(B29=0,0,E29-H29) -> 32.2 | G29: =VLOOKUP(A29,Custo!A:B,2,0) -> 15.13493 | H29: =(VLOOKUP(A29,Peso!$A$10:$B$148,2,0))*($B$6/1000) -> 0.35 | I29: =IF($I$7="X",AE29,0%) -> 0.05 | J29: =+B29*I29 -> 1.75 | K29: =IF($B$2="X",$C$2,0) -> 0 | L29: =+B29*K29 -> 0 | M29: =+G29+H29+J29+L29 -> 17.23493 | N29: =+E29-M29 -> 15.31507 | O29: =IF(ISERROR((N29/P29)*1000),"",(N29/P29)*1000) | Q29: =VLOOKUP(A29,'MVA-IPI'!A:AD,30,FALSE) -> 0 | R29: =IF($B$4="AM",0,IF($B$4="AP",0,IF($B$4="RR",0,(B29*Q29)))) -> 0 | S29: =IF($B$4="AP",(B29/0.88*$S$8),IF(T29=0%,0,IF($B$4="AM",(B29/0.88*$S$8),IF(T29=0%,0,IF($B$4="RR",(B29/0.88*$S$8),IF(T29=0%,0,B29*$S$8)))))) -> 0 | T29: =IF($C$4="GRUPO 1",VLOOKUP(A29,'MVA-grupos'!$A$9:$B$128,2,FALSE),IF($C$4="GRUPO 2",VLOOKUP(A29,'MVA-grupos'!$A$9:$D$128,4,FALSE),IF($C$4="GRUPO 3",VLOOKUP(A29,'MVA-grupos'!$A$10:$F$128,6,FALSE),IF($C$4="Grupo 4",VLOOKUP(A29,'MVA-grupos'!$A$9:$H$128,8,FALSE))))) -> 0 | U29: =IF(T29=0%,0,(B29+R29)*T29+(B29+R29)) -> 0 | V29: =(U29*$V$8)-S29 -> 0 | X29: =A29 -> BRAZIMIL SEMI BRILHO 3,0L BALDE COR | Y29: =+C29 -> 0 | Z29: =IF(ISERROR(Y29*N29),"",Y29*N29) -> 0 | AA29: =IF(ISERROR(IF(E$7="X",Y29*E29,Y29*F29)),"",IF(E$7="X",Y29*E29,Y29*F29)) -> 0 | AB29: =IF(ISERROR(Z29/AA29),"",Z29/AA29) | AE29: 0.05 | AF29: =+'Frete_Regiao-Impostos'!A20 -> 0 | AG29: =+'Frete_Regiao-Impostos'!B20 -> 0 | AH29: =+'Frete_Regiao-Impostos'!C20 -> 0 | AI29: =+'Frete_Regiao-Impostos'!D20 -> 0 | AP29: =Peso!B29 -> 3.5
A30: BRAZIMIL SEMI BRILHO 15L | D30: =AB30 | X30: =A30 -> BRAZIMIL SEMI BRILHO 15L | Z30: =SUM(Z31:Z32) -> 0 | AA30: =SUM(AA31:AA32) -> 0 | AB30: =IF(ISERROR(Z30/AA30),"",Z30/AA30) | AC30: 0.25 | AF30: =+'Frete_Regiao-Impostos'!A21 -> 0 | AG30: =+'Frete_Regiao-Impostos'!B21 -> 0 | AH30: =+'Frete_Regiao-Impostos'!C21 -> 0 | AI30: =+'Frete_Regiao-Impostos'!D21 -> 0 | AP30: =Peso!B30 -> 0
A31: BRAZIMIL SEMI BRILHO 15L BALDE BRANCO NEVE | B31: 170 | D31: =IF($F$7="x",IF(F31=0,0,N31/F31),IF($E$7="x",IF(F31=0,0,N31/E31),"")) -> 0.54095942 | E31: =+B31*(-B$5+100%) -> 158.1 | F31: =IF(B31=0,0,E31-H31) -> 156.59 | G31: =VLOOKUP(A31,Custo!A:B,2,0) -> 54.064315 | H31: =(VLOOKUP(A31,Peso!$A$10:$B$148,2,0))*($B$6/1000) -> 1.51 | I31: =IF($I$7="X",AE31,0%) -> 0.05 | J31: =+B31*I31 -> 8.5 | K31: 0.05 | L31: =+B31*K31 -> 8.5 | M31: =+G31+H31+J31+L31 -> 72.574315 | N31: =+E31-M31 -> 85.525685 | O31: =IF(ISERROR((N31/P31)*1000),"",(N31/P31)*1000) | Q31: =VLOOKUP(A31,'MVA-IPI'!A:AD,30,FALSE) -> 0 | R31: =IF($B$4="AM",0,IF($B$4="AP",0,IF($B$4="RR",0,(B31*Q31)))) -> 0 | S31: =IF($B$4="AP",(B31/0.88*$S$8),IF(T31=0%,0,IF($B$4="AM",(B31/0.88*$S$8),IF(T31=0%,0,IF($B$4="RR",(B31/0.88*$S$8),IF(T31=0%,0,B31*$S$8)))))) -> 0 | T31: =IF($C$4="GRUPO 1",VLOOKUP(A31,'MVA-grupos'!$A$9:$B$128,2,FALSE),IF($C$4="GRUPO 2",VLOOKUP(A31,'MVA-grupos'!$A$9:$D$128,4,FALSE),IF($C$4="GRUPO 3",VLOOKUP(A31,'MVA-grupos'!$A$10:$F$128,6,FALSE),IF($C$4="Grupo 4",VLOOKUP(A31,'MVA-grupos'!$A$9:$H$128,8,FALSE))))) -> 0 | U31: =IF(T31=0%,0,(B31+R31)*T31+(B31+R31)) -> 0 | V31: =(U31*$V$8)-S31 -> 0 | X31: =A31 -> BRAZIMIL SEMI BRILHO 15L BALDE BRANCO NEVE | Y31: =+C31 -> 0 | Z31: =IF(ISERROR(Y31*N31),"",Y31*N31) -> 0 | AA31: =IF(ISERROR(IF(E$7="X",Y31*E31,Y31*F31)),"",IF(E$7="X",Y31*E31,Y31*F31)) -> 0 | AB31: =IF(ISERROR(Z31/AA31),"",Z31/AA31) | AE31: 0.05 | AF31: =+'Frete_Regiao-Impostos'!A22 -> 0 | AG31: =+'Frete_Regiao-Impostos'!B22 -> 0 | AH31: =+'Frete_Regiao-Impostos'!C22 -> 0 | AI31: =+'Frete_Regiao-Impostos'!D22 -> 0 | AP31: =Peso!B32 -> 15.1
A32: BRAZIMIL SEMI BRILHO 15L BALDE COR | B32: 170 | D32: =IF($F$7="x",IF(F32=0,0,N32/F32),IF($E$7="x",IF(F32=0,0,N32/E32),"")) -> 0.4666107 | E32: =+B32*(-B$5+100%) -> 158.1 | F32: =IF(B32=0,0,E32-H32) -> 156.59 | G32: =VLOOKUP(A32,Custo!A:B,2,0) -> 74.318848 | H32: =(VLOOKUP(A32,Peso!$A$10:$B$148,2,0))*($B$6/1000) -> 1.51 | I32: =IF($I$7="X",AE32,0%) -> 0.05 | J32: =+B32*I32 -> 8.5 | K32: =IF($B$2="X",$C$2,0) -> 0 | L32: =+B32*K32 -> 0 | M32: =+G32+H32+J32+L32 -> 84.328848 | N32: =+E32-M32 -> 73.771152 | O32: =IF(ISERROR((N32/P32)*1000),"",(N32/P32)*1000) | Q32: =VLOOKUP(A32,'MVA-IPI'!A:AD,30,FALSE) -> 0 | R32: =IF($B$4="AM",0,IF($B$4="AP",0,IF($B$4="RR",0,(B32*Q32)))) -> 0 | S32: =IF($B$4="AP",(B32/0.88*$S$8),IF(T32=0%,0,IF($B$4="AM",(B32/0.88*$S$8),IF(T32=0%,0,IF($B$4="RR",(B32/0.88*$S$8),IF(T32=0%,0,B32*$S$8)))))) -> 0 | T32: =IF($C$4="GRUPO 1",VLOOKUP(A32,'MVA-grupos'!$A$9:$B$128,2,FALSE),IF($C$4="GRUPO 2",VLOOKUP(A32,'MVA-grupos'!$A$9:$D$128,4,FALSE),IF($C$4="GRUPO 3",VLOOKUP(A32,'MVA-grupos'!$A$10:$F$128,6,FALSE),IF($C$4="Grupo 4",VLOOKUP(A32,'MVA-grupos'!$A$9:$H$128,8,FALSE))))) -> 0 | U32: =IF(T32=0%,0,(B32+R32)*T32+(B32+R32)) -> 0 | V32: =(U32*$V$8)-S32 -> 0 | X32: =A32 -> BRAZIMIL SEMI BRILHO 15L BALDE COR | Y32: =+C32 -> 0 | Z32: =IF(ISERROR(Y32*N32),"",Y32*N32) -> 0 | AA32: =IF(ISERROR(IF(E$7="X",Y32*E32,Y32*F32)),"",IF(E$7="X",Y32*E32,Y32*F32)) -> 0 | AB32: =IF(ISERROR(Z32/AA32),"",Z32/AA32) | AE32: 0.05 | AF32: =+'Frete_Regiao-Impostos'!A23 -> 0 | AG32: =+'Frete_Regiao-Impostos'!B23 -> 0 | AH32: =+'Frete_Regiao-Impostos'!C23 -> 0 | AI32: =+'Frete_Regiao-Impostos'!D23 -> 0 | AP32: =Peso!B33 -> 15.1
A33: BRAZIMIL TINTA PISO 3,0L | D33: =AB33 | X33: =A33 -> BRAZIMIL TINTA PISO 3,0L | Z33: =SUM(Z34:Z35) -> 0 | AA33: =SUM(AA34:AA35) -> 0 | AB33: =IF(ISERROR(Z33/AA33),"",Z33/AA33) | AC33: 0.25 | AF33: =+'Frete_Regiao-Impostos'!A24 -> 0 | AG33: =+'Frete_Regiao-Impostos'!B24 -> 0 | AH33: =+'Frete_Regiao-Impostos'!C24 -> 0 | AI33: =+'Frete_Regiao-Impostos'!D24 -> 0 | AP33: =Peso!B34 -> 0
A34: BRAZIMIL TINTA PISO 3,0L BALDE BRANCO NEVE | B34: 30 | D34: =IF($F$7="x",IF(F34=0,0,N34/F34),IF($E$7="x",IF(F34=0,0,N34/E34),"")) -> 0.26174171 | E34: =+B34*(-B$5+100%) -> 27.9 | F34: =IF(B34=0,0,E34-H34) -> 27.53 | G34: =VLOOKUP(A34,Custo!A:B,2,0) -> 18.727406 | H34: =(VLOOKUP(A34,Peso!$A$10:$B$148,2,0))*($B$6/1000) -> 0.37 | I34: =IF($I$7="X",AE34,0%) -> 0.05 | J34: =+B34*I34 -> 1.5 | K34: =IF($B$2="X",$C$2,0) -> 0 | L34: =+B34*K34 -> 0 | M34: =+G34+H34+J34+L34 -> 20.597406 | N34: =+E34-M34 -> 7.3025937 | O34: =IF(ISERROR((N34/P34)*1000),"",(N34/P34)*1000) | Q34: =VLOOKUP(A34,'MVA-IPI'!A:AD,30,FALSE) -> 0 | R34: =IF($B$4="AM",0,IF($B$4="AP",0,IF($B$4="RR",0,(B34*Q34)))) -> 0 | S34: =IF($B$4="AP",(B34/0.88*$S$8),IF(T34=0%,0,IF($B$4="AM",(B34/0.88*$S$8),IF(T34=0%,0,IF($B$4="RR",(B34/0.88*$S$8),IF(T34=0%,0,B34*$S$8)))))) -> 0 | T34: =IF($C$4="GRUPO 1",VLOOKUP(A34,'MVA-grupos'!$A$9:$B$128,2,FALSE),IF($C$4="GRUPO 2",VLOOKUP(A34,'MVA-grupos'!$A$9:$D$128,4,FALSE),IF($C$4="GRUPO 3",VLOOKUP(A34,'MVA-grupos'!$A$10:$F$128,6,FALSE),IF($C$4="Grupo 4",VLOOKUP(A34,'MVA-grupos'!$A$9:$H$128,8,FALSE))))) -> 0 | U34: =IF(T34=0%,0,(B34+R34)*T34+(B34+R34)) -> 0 | V34: =(U34*$V$8)-S34 -> 0 | X34: =A34 -> BRAZIMIL TINTA PISO 3,0L BALDE BRANCO NEVE | Y34: =+C34 -> 0 | Z34: =IF(ISERROR(Y34*N34),"",Y34*N34) -> 0 | AA34: =IF(ISERROR(IF(E$7="X",Y34*E34,Y34*F34)),"",IF(E$7="X",Y34*E34,Y34*F34)) -> 0 | AB34: =IF(ISERROR(Z34/AA34),"",Z34/AA34) | AE34: 0.05 | AF34: =+'Frete_Regiao-Impostos'!A25 -> Manaus CIF | AG34: =+'Frete_Regiao-Impostos'!B25 -> 100 | AH34: =+'Frete_Regiao-Impostos'!C25 -> 0.07 | AI34: =+'Frete_Regiao-Impostos'!D25 -> AM | AP34: =Peso!B35 -> 3.7
A35: BRAZIMIL TINTA PISO 3,0L BALDE COR | B35: 28.5 | D35: =IF($F$7="x",IF(F35=0,0,N35/F35),IF($E$7="x",IF(F35=0,0,N35/E35),"")) -> 0.27313443 | E35: =+B35*(-B$5+100%) -> 26.505 | F35: =IF(B35=0,0,E35-H35) -> 26.145 | G35: =VLOOKUP(A35,Custo!A:B,2,0) -> 17.480572 | H35: =(VLOOKUP(A35,Peso!$A$10:$B$148,2,0))*($B$6/1000) -> 0.36 | I35: =IF($I$7="X",AE35,0%) -> 0.05 | J35: =+B35*I35 -> 1.425 | K35: =IF($B$2="X",$C$2,0) -> 0 | L35: =+B35*K35 -> 0 | M35: =+G35+H35+J35+L35 -> 19.265572 | N35: =+E35-M35 -> 7.239428 | O35: =IF(ISERROR((N35/P35)*1000),"",(N35/P35)*1000) | Q35: =VLOOKUP(A35,'MVA-IPI'!A:AD,30,FALSE) -> 0 | R35: =IF($B$4="AM",0,IF($B$4="AP",0,IF($B$4="RR",0,(B35*Q35)))) -> 0 | S35: =IF($B$4="AP",(B35/0.88*$S$8),IF(T35=0%,0,IF($B$4="AM",(B35/0.88*$S$8),IF(T35=0%,0,IF($B$4="RR",(B35/0.88*$S$8),IF(T35=0%,0,B35*$S$8)))))) -> 0 | T35: =IF($C$4="GRUPO 1",VLOOKUP(A35,'MVA-grupos'!$A$9:$B$128,2,FALSE),IF($C$4="GRUPO 2",VLOOKUP(A35,'MVA-grupos'!$A$9:$D$128,4,FALSE),IF($C$4="GRUPO 3",VLOOKUP(A35,'MVA-grupos'!$A$10:$F$128,6,FALSE),IF($C$4="Grupo 4",VLOOKUP(A35,'MVA-grupos'!$A$9:$H$128,8,FALSE))))) -> 0 | U35: =IF(T35=0%,0,(B35+R35)*T35+(B35+R35)) -> 0 | V35: =(U35*$V$8)-S35 -> 0 | X35: =A35 -> BRAZIMIL TINTA PISO 3,0L BALDE COR | Y35: =+C35 -> 0 | Z35: =IF(ISERROR(Y35*N35),"",Y35*N35) -> 0 | AA35: =IF(ISERROR(IF(E$7="X",Y35*E35,Y35*F35)),"",IF(E$7="X",Y35*E35,Y35*F35)) -> 0 | AB35: =IF(ISERROR(Z35/AA35),"",Z35/AA35) | AE35: 0.05 | AF35: =+'Frete_Regiao-Impostos'!A26 -> 0 | AG35: =+'Frete_Regiao-Impostos'!B26 -> 0 | AH35: =+'Frete_Regiao-Impostos'!C26 -> 0 | AI35: =+'Frete_Regiao-Impostos'!D26 -> 0 | AP35: =Peso!B36 -> 3.6
A36: BRAZIMIL TINTA PISO 15L | D36: =AB36 | X36: =A36 -> BRAZIMIL TINTA PISO 15L | Z36: =SUM(Z37:Z38) -> 0 | AA36: =SUM(AA37:AA38) -> 0 | AB36: =IF(ISERROR(Z36/AA36),"",Z36/AA36) | AC36: 0.25 | AF36: =+'Frete_Regiao-Impostos'!A27 -> Manaus - FOB | AG36: =+'Frete_Regiao-Impostos'!B27 -> 0 | AH36: =+'Frete_Regiao-Impostos'!C27 -> 0.07 | AI36: =+'Frete_Regiao-Impostos'!D27 -> AM | AP36: =Peso!B37 -> 0
A37: BRAZIMIL TINTA PISO 15L BALDE BRANCO NEVE | B37: 130 | D37: =IF($F$7="x",IF(F37=0,0,N37/F37),IF($E$7="x",IF(F37=0,0,N37/E37),"")) -> 0.083538953 | E37: =+B37*(-B$5+100%) -> 120.9 | F37: =IF(B37=0,0,E37-H37) -> 119.3 | G37: =VLOOKUP(A37,Custo!A:B,2,0) -> 102.70014 | H37: =(VLOOKUP(A37,Peso!$A$10:$B$148,2,0))*($B$6/1000) -> 1.6 | I37: =IF($I$7="X",AE37,0%) -> 0.05 | J37: =+B37*I37 -> 6.5 | K37: =IF($B$2="X",$C$2,0) -> 0 | L37: =+B37*K37 -> 0 | M37: =+G37+H37+J37+L37 -> 110.80014 | N37: =+E37-M37 -> 10.099859 | O37: =IF(ISERROR((N37/P37)*1000),"",(N37/P37)*1000) | Q37: =VLOOKUP(A37,'MVA-IPI'!A:AD,30,FALSE) -> 0 | R37: =IF($B$4="AM",0,IF($B$4="AP",0,IF($B$4="RR",0,(B37*Q37)))) -> 0 | S37: =IF($B$4="AP",(B37/0.88*$S$8),IF(T37=0%,0,IF($B$4="AM",(B37/0.88*$S$8),IF(T37=0%,0,IF($B$4="RR",(B37/0.88*$S$8),IF(T37=0%,0,B37*$S$8)))))) -> 0 | T37: =IF($C$4="GRUPO 1",VLOOKUP(A37,'MVA-grupos'!$A$9:$B$128,2,FALSE),IF($C$4="GRUPO 2",VLOOKUP(A37,'MVA-grupos'!$A$9:$D$128,4,FALSE),IF($C$4="GRUPO 3",VLOOKUP(A37,'MVA-grupos'!$A$10:$F$128,6,FALSE),IF($C$4="Grupo 4",VLOOKUP(A37,'MVA-grupos'!$A$9:$H$128,8,FALSE))))) -> 0 | U37: =IF(T37=0%,0,(B37+R37)*T37+(B37+R37)) -> 0 | V37: =(U37*$V$8)-S37 -> 0 | X37: =A37 -> BRAZIMIL TINTA PISO 15L BALDE BRANCO NEVE | Y37: =+C37 -> 0 | Z37: =IF(ISERROR(Y37*N37),"",Y37*N37) -> 0 | AA37: =IF(ISERROR(IF(E$7="X",Y37*E37,Y37*F37)),"",IF(E$7="X",Y37*E37,Y37*F37)) -> 0 | AB37: =IF(ISERROR(Z37/AA37),"",Z37/AA37) | AE37: 0.05 | AF37: =+'Frete_Regiao-Impostos'!A28 -> Manaus - INTERIOR PIS COFINS | AG37: =+'Frete_Regiao-Impostos'!B28 -> 0 | AH37: =+'Frete_Regiao-Impostos'!C28 -> 0.1065 | AI37: =+'Frete_Regiao-Impostos'!D28 -> AM | AP37: =Peso!B38 -> 16
A38: BRAZIMIL TINTA PISO 15L BALDE COR | B38: 108 | D38: =IF($F$7="x",IF(F38=0,0,N38/F38),IF($E$7="x",IF(F38=0,0,N38/E38),"")) -> -0.032127247 | E38: =+B38*(-B$5+100%) -> 100.44 | F38: =IF(B38=0,0,E38-H38) -> 98.86 | G38: =VLOOKUP(A38,Custo!A:B,2,0) -> 96.686861 | H38: =(VLOOKUP(A38,Peso!$A$10:$B$148,2,0))*($B$6/1000) -> 1.58 | I38: =IF($I$7="X",AE38,0%) -> 0.05 | J38: =+B38*I38 -> 5.4 | K38: =IF($B$2="X",$C$2,0) -> 0 | L38: =+B38*K38 -> 0 | M38: =+G38+H38+J38+L38 -> 103.66686 | N38: =+E38-M38 -> -3.2268607 | O38: =IF(ISERROR((N38/P38)*1000),"",(N38/P38)*1000) | Q38: =VLOOKUP(A38,'MVA-IPI'!A:AD,30,FALSE) -> 0 | R38: =IF($B$4="AM",0,IF($B$4="AP",0,IF($B$4="RR",0,(B38*Q38)))) -> 0 | S38: =IF($B$4="AP",(B38/0.88*$S$8),IF(T38=0%,0,IF($B$4="AM",(B38/0.88*$S$8),IF(T38=0%,0,IF($B$4="RR",(B38/0.88*$S$8),IF(T38=0%,0,B38*$S$8)))))) -> 0 | T38: =IF($C$4="GRUPO 1",VLOOKUP(A38,'MVA-grupos'!$A$9:$B$128,2,FALSE),IF($C$4="GRUPO 2",VLOOKUP(A38,'MVA-grupos'!$A$9:$D$128,4,FALSE),IF($C$4="GRUPO 3",VLOOKUP(A38,'MVA-grupos'!$A$10:$F$128,6,FALSE),IF($C$4="Grupo 4",VLOOKUP(A38,'MVA-grupos'!$A$9:$H$128,8,FALSE))))) -> 0 | U38: =IF(T38=0%,0,(B38+R38)*T38+(B38+R38)) -> 0 | V38: =(U38*$V$8)-S38 -> 0 | X38: =A38 -> BRAZIMIL TINTA PISO 15L BALDE COR | Y38: =+C38 -> 0 | Z38: =IF(ISERROR(Y38*N38),"",Y38*N38) -> 0 | AA38: =IF(ISERROR(IF(E$7="X",Y38*E38,Y38*F38)),"",IF(E$7="X",Y38*E38,Y38*F38)) -> 0 | AB38: =IF(ISERROR(Z38/AA38),"",Z38/AA38) | AE38: 0.05 | AF38: =+'Frete_Regiao-Impostos'!A29 -> Manaus - INTERIOR S/ PIS COFINS | AG38: =+'Frete_Regiao-Impostos'!B29 -> 0 | AH38: =+'Frete_Regiao-Impostos'!C29 -> 0.07 | AI38: =+'Frete_Regiao-Impostos'!D29 -> AM | AP38: =Peso!B39 -> 15.8
A39: BRAZIMIL SELADOR ACRIL 3,0L | D39: =AB39 | X39: =A39 -> BRAZIMIL SELADOR ACRIL 3,0L | Z39: =SUM(Z40:Z41) -> 0 | AA39: =SUM(AA40:AA41) -> 0 | AB39: =IF(ISERROR(Z39/AA39),"",Z39/AA39) | AC39: 0.25 | AF39: =+'Frete_Regiao-Impostos'!A30 -> 0 | AG39: =+'Frete_Regiao-Impostos'!B30 -> 0 | AH39: =+'Frete_Regiao-Impostos'!C30 -> 0 | AI39: =+'Frete_Regiao-Impostos'!D30 -> 0 | AP39: =Peso!B40 -> 0
A40: BRAZIMIL SELADOR ACRIL 3,0L REFIL PIGMENTADO | B40: 0 | D40: =IF($F$7="x",IF(F40=0,0,N40/F40),IF($E$7="x",IF(F40=0,0,N40/E40),"")) -> 0 | E40: =+B40*(-B$5+100%) -> 0 | F40: =IF(B40=0,0,E40-H40) -> 0 | G40: =VLOOKUP(A40,Custo!A:B,2,0) -> 3.2667289 | H40: =(VLOOKUP(A40,Peso!$A$10:$B$148,2,0))*($B$6/1000) -> 0.385 | I40: =IF($I$7="X",AE40,0%) -> 0.05 | J40: =+B40*I40 -> 0 | K40: =IF($B$2="X",$C$2,0) -> 0 | L40: =+B40*K40 -> 0 | M40: =+G40+H40+J40+L40 -> 3.6517289 | N40: =+E40-M40 -> -3.6517289 | O40: =IF(ISERROR((N40/P40)*1000),"",(N40/P40)*1000) | Q40: =VLOOKUP(A40,'MVA-IPI'!A:AD,30,FALSE) -> 0 | R40: =IF($B$4="AM",0,IF($B$4="AP",0,IF($B$4="RR",0,(B40*Q40)))) -> 0 | S40: =IF($B$4="AP",(B40/0.88*$S$8),IF(T40=0%,0,IF($B$4="AM",(B40/0.88*$S$8),IF(T40=0%,0,IF($B$4="RR",(B40/0.88*$S$8),IF(T40=0%,0,B40*$S$8)))))) -> 0 | T40: =IF($C$4="GRUPO 1",VLOOKUP(A40,'MVA-grupos'!$A$9:$B$128,2,FALSE),IF($C$4="GRUPO 2",VLOOKUP(A40,'MVA-grupos'!$A$9:$D$128,4,FALSE),IF($C$4="GRUPO 3",VLOOKUP(A40,'MVA-grupos'!$A$10:$F$128,6,FALSE),IF($C$4="Grupo 4",VLOOKUP(A40,'MVA-grupos'!$A$9:$H$128,8,FALSE))))) -> 0 | U40: =IF(T40=0%,0,(B40+R40)*T40+(B40+R40)) -> 0 | V40: =(U40*$V$8)-S40 -> 0 | X40: =A40 -> BRAZIMIL SELADOR ACRIL 3,0L REFIL PIGMENTADO | Y40: =+C40 -> 0 | Z40: =IF(ISERROR(Y40*N40),"",Y40*N40) -> 0 | AA40: =IF(ISERROR(IF(E$7="X",Y40*E40,Y40*F40)),"",IF(E$7="X",Y40*E40,Y40*F40)) -> 0 | AB40: =IF(ISERROR(Z40/AA40),"",Z40/AA40) | AE40: 0.05 | AF40: =+'Frete_Regiao-Impostos'!A31 -> 0 | AG40: =+'Frete_Regiao-Impostos'!B31 -> 0 | AH40: =+'Frete_Regiao-Impostos'!C31 -> 0 | AI40: =+'Frete_Regiao-Impostos'!D31 -> 0 | AP40: =Peso!B41 -> 3.85
A41: BRAZIMIL SELADOR ACRIL 3,0L BALDE PIGMENTADO | B41: 17.99 | D41: =IF($F$7="x",IF(F41=0,0,N41/F41),IF($E$7="x",IF(F41=0,0,N41/E41),"")) -> 0.51931306 | E41: =+B41*(-B$5+100%) -> 16.7307 | F41: =IF(B41=0,0,E41-H41) -> 16.3257 | G41: =VLOOKUP(A41,Custo!A:B,2,0) -> 6.7377289 | H41: =(VLOOKUP(A41,Peso!$A$10:$B$148,2,0))*($B$6/1000) -> 0.405 | I41: =IF($I$7="X",AE41,0%) -> 0.05 | J41: =+B41*I41 -> 0.8995 | K41: =IF($B$2="X",$C$2,0) -> 0 | L41: =+B41*K41 -> 0 | M41: =+G41+H41+J41+L41 -> 8.0422289 | N41: =+E41-M41 -> 8.6884711 | O41: =IF(ISERROR((N41/P41)*1000),"",(N41/P41)*1000) | Q41: =VLOOKUP(A41,'MVA-IPI'!A:AD,30,FALSE) -> 0 | R41: =IF($B$4="AM",0,IF($B$4="AP",0,IF($B$4="RR",0,(B41*Q41)))) -> 0 | S41: =IF($B$4="AP",(B41/0.88*$S$8),IF(T41=0%,0,IF($B$4="AM",(B41/0.88*$S$8),IF(T41=0%,0,IF($B$4="RR",(B41/0.88*$S$8),IF(T41=0%,0,B41*$S$8)))))) -> 0 | T41: =IF($C$4="GRUPO 1",VLOOKUP(A41,'MVA-grupos'!$A$9:$B$128,2,FALSE),IF($C$4="GRUPO 2",VLOOKUP(A41,'MVA-grupos'!$A$9:$D$128,4,FALSE),IF($C$4="GRUPO 3",VLOOKUP(A41,'MVA-grupos'!$A$10:$F$128,6,FALSE),IF($C$4="Grupo 4",VLOOKUP(A41,'MVA-grupos'!$A$9:$H$128,8,FALSE))))) -> 0 | U41: =IF(T41=0%,0,(B41+R41)*T41+(B41+R41)) -> 0 | V41: =(U41*$V$8)-S41 -> 0 | X41: =A41 -> BRAZIMIL SELADOR ACRIL 3,0L BALDE PIGMENTADO | Y41: =+C41 -> 0 | Z41: =IF(ISERROR(Y41*N41),"",Y41*N41) -> 0 | AA41: =IF(ISERROR(IF(E$7="X",Y41*E41,Y41*F41)),"",IF(E$7="X",Y41*E41,Y41*F41)) -> 0 | AB41: =IF(ISERROR(Z41/AA41),"",Z41/AA41) | AE41: 0.05 | AF41: =+'Frete_Regiao-Impostos'!A32 -> 0 | AG41: =+'Frete_Regiao-Impostos'!B32 -> 0 | AH41: =+'Frete_Regiao-Impostos'!C32 -> 0 | AI41: =+'Frete_Regiao-Impostos'!D32 -> 0 | AP41: =Peso!B42 -> 4.05
...

Sheet Custo
A9: Produto | B9: CUSTO
A10: TINTAS BASE ÁGUA
A11: BRAZIMIL ECONOMICA 3,0L
A12: BRAZIMIL ECONÔMICA 3,0L REFIL BRANCO NEVE | B12: ='[5]CUSTO ESPELHO'!$B4 -> 4.4992833
A13: BRAZIMIL ECONÔMICA 3,0L REFIL COR | B13: ='[5]CUSTO ESPELHO'!$B5 -> 3.9825213
A14: BRAZIMIL ECONÔMICA 3,0L GALÃO BRANCO NEVE | B14: ='[5]CUSTO ESPELHO'!$B6 -> 7.9702833
A15: BRAZIMIL ECONÔMICA 3,0L GALÃO COR | B15: ='[5]CUSTO ESPELHO'!$B7 -> 7.4535213
A16: BRAZIMIL ECONÔMICA 15L
A17: BRAZIMIL ECONÔMICA 15L PPQ BRANCO NEVE | B17: ='[2]CUSTO ESPELHO'!B17 -> 0
A18: BRAZIMIL ECONÔMICA 12L BALDE BRANCO NEVE | B18: ='[1]CUSTO ESPELHO'!$B18 -> 25.763717
A19: BRAZIMIL ECONÔMICA 15L BALDE BRANCO NEVE | B19: ='[5]CUSTO ESPELHO'!$B11 -> 32.778842
A20: BRAZIMIL ECONÔMICA 15L BALDE COR | B20: ='[5]CUSTO ESPELHO'!$B12 -> 29.419889
A21: BRAZIMIL EXTERNA 3,0L
A22: BRAZIMIL EXTERNA 3,0L BALDE BRANCO NEVE | B22: ='[5]CUSTO ESPELHO'!$B14 -> 11.252876
A23: BRAZIMIL EXTERNA 3,0L BALDE COR | B23: ='[5]CUSTO ESPELHO'!$B15 -> 9.3931485
A24: BRAZIMIL EXTERNA 15L
A25: BRAZIMIL EXTERNA 15L BALDE BRANCO NEVE | B25: ='[5]CUSTO ESPELHO'!$B17 -> 53.753882
A26: BRAZIMIL EXTERNA 15L BALDE COR | B26: ='[5]CUSTO ESPELHO'!$B18 -> 41.944613
A27: BRAZIMIL SEMI BRILHO 3,0L
A28: BRAZIMIL SEMI BRILHO 3,0L BALDE BRANCO NEVE | B28: ='[5]CUSTO ESPELHO'!$B20 -> 11.612403
A29: BRAZIMIL SEMI BRILHO 3,0L BALDE COR | B29: ='[5]CUSTO ESPELHO'!$B21 -> 15.13493
A30: BRAZIMIL SEMI BRILHO 15L
A31: BRAZIMIL SEMI BRILHO 12L BALDE BRANCO NEVE | B31: ='[5]CUSTO ESPELHO'!$B23 -> 35.219452
A32: BRAZIMIL SEMI BRILHO 15L BALDE BRANCO NEVE | B32: ='[5]CUSTO ESPELHO'!$B24 -> 54.064315
A33: BRAZIMIL SEMI BRILHO 15L BALDE COR | B33: ='[5]CUSTO ESPELHO'!$B25 -> 74.318848
A34: BRAZIMIL TINTA PISO 3,0L
A35: BRAZIMIL TINTA PISO 3,0L BALDE BRANCO NEVE | B35: ='[5]CUSTO ESPELHO'!$B27 -> 18.727406
A36: BRAZIMIL TINTA PISO 3,0L BALDE COR | B36: ='[5]CUSTO ESPELHO'!$B28 -> 17.480572
A37: BRAZIMIL TINTA PISO 15L
A38: BRAZIMIL TINTA PISO 15L BALDE BRANCO NEVE | B38: ='[5]CUSTO ESPELHO'!$B30 -> 102.70014
A39: BRAZIMIL TINTA PISO 15L BALDE COR | B39: ='[5]CUSTO ESPELHO'!$B31 -> 96.686861
A40: BRAZIMIL SELADOR ACRIL 3,0L
A41: BRAZIMIL SELADOR ACRIL 3,0L REFIL PIGMENTADO | B41: ='[5]CUSTO ESPELHO'!$B33 -> 3.2667289
A42: BRAZIMIL SELADOR ACRIL 3,0L BALDE PIGMENTADO | B42: ='[5]CUSTO ESPELHO'!$B34 -> 6.7377289
A43: BRAZIMIL SELADOR ACRIL 15L
A44: BRAZIMIL SELADOR ACRIL 12L PIGMENTADO | B44: ='[5]CUSTO ESPELHO'!$B36 -> 11.78179
A45: BRAZIMIL SELADOR ACRIL 15L BALDE PIGMENTADO | B45: ='[5]CUSTO ESPELHO'!$B37 -> 24.767238
A46: LIQUIBRILHO 3,0L
A47: LIQUIBRILHO 3,0L BALDE INCOLOR | B47: ='[1]CUSTO ESPELHO'!$B47 -> 14.149586
A48: LIQUIBRILHO 15L
...

Sheet Peso
A9: Produto | B9: PESO BRUTO
A10: TINTAS BASE ÁGUA
A11: BRAZIMIL ECONOMICA 3,0L
A12: BRAZIMIL ECONÔMICA 3,0L REFIL BRANCO NEVE | B12: 3.85
A13: BRAZIMIL ECONÔMICA 3,0L REFIL COR | B13: 3.35
A14: BRAZIMIL ECONÔMICA 3,0L GALÃO BRANCO NEVE | B14: 4
A15: BRAZIMIL ECONÔMICA 3,0L GALÃO COR | B15: 3.5
A16: BRAZIMIL ECONÔMICA 15L
A17: BRAZIMIL ECONÔMICA 15L PPQ BRANCO NEVE | B17: 18.7
A18: BRAZIMIL ECONÔMICA 12L BALDE BRANCO NEVE | B18: =12*1.2 -> 14.4
A19: BRAZIMIL ECONÔMICA 15L BALDE BRANCO NEVE | B19: 18.7
A20: BRAZIMIL ECONÔMICA 15L BALDE COR | B20: 17
A21: BRAZIMIL EXTERNA 3,0L
A22: BRAZIMIL EXTERNA 3,0L BALDE BRANCO NEVE | B22: 4.2
A23: BRAZIMIL EXTERNA 3,0L BALDE COR | B23: 3.9
A24: BRAZIMIL EXTERNA 15L
A25: BRAZIMIL EXTERNA 15L BALDE BRANCO NEVE | B25: 19
A26: BRAZIMIL EXTERNA 15L BALDE COR | B26: 17
A27: BRAZIMIL SEMI BRILHO 3,0L
A28: BRAZIMIL SEMI BRILHO 3,0L BALDE BRANCO NEVE | B28: 3.6
A29: BRAZIMIL SEMI BRILHO 3,0L BALDE COR | B29: 3.5
A30: BRAZIMIL SEMI BRILHO 15L
A31: BRAZIMIL SEMI BRILHO 12L BALDE BRANCO NEVE | B31: 12.5
A32: BRAZIMIL SEMI BRILHO 15L BALDE BRANCO NEVE | B32: 15.1
A33: BRAZIMIL SEMI BRILHO 15L BALDE COR | B33: 15.1
A34: BRAZIMIL TINTA PISO 3,0L
A35: BRAZIMIL TINTA PISO 3,0L BALDE BRANCO NEVE | B35: 3.7
A36: BRAZIMIL TINTA PISO 3,0L BALDE COR | B36: 3.6
A37: BRAZIMIL TINTA PISO 15L
A38: BRAZIMIL TINTA PISO 15L BALDE BRANCO NEVE | B38: 16
A39: BRAZIMIL TINTA PISO 15L BALDE COR | B39: 15.8
A40: BRAZIMIL SELADOR ACRIL 3,0L
A41: BRAZIMIL SELADOR ACRIL 3,0L REFIL PIGMENTADO | B41: 3.85
A42: BRAZIMIL SELADOR ACRIL 3,0L BALDE PIGMENTADO | B42: 4.05
A43: BRAZIMIL SELADOR ACRIL 15L
A44: BRAZIMIL SELADOR ACRIL 12L PIGMENTADO | B44: 13
A45: BRAZIMIL SELADOR ACRIL 15L BALDE PIGMENTADO | B45: 18
A46: LIQUIBRILHO 3,0L
A47: LIQUIBRILHO 3,0L BALDE INCOLOR | B47: 3.185
A48: LIQUIBRILHO 15L
...

Sheet MVA-grupos
A9: Produto / Grupo ST | B9: GRUPO 1 | D9: GRUPO 2 | F9: GRUPO 3 | H9: GRUPO 4
A10: TINTAS BASE ÁGUA
A11: BRAZIMIL ECONOMICA 3,0L
A12: BRAZIMIL ECONÔMICA 3,0L REFIL BRANCO NEVE | B12: ='MVA-IPI'!O12 -> 0.485 | D12: ='MVA-IPI'!B12 -> 0.485 | F12: ='MVA-IPI'!N12 -> 0.4667 | H12: ='MVA-IPI'!AB12 -> 0
A13: BRAZIMIL ECONÔMICA 3,0L REFIL COR | B13: ='MVA-IPI'!O13 -> 0.485 | D13: ='MVA-IPI'!B13 -> 0.485 | F13: ='MVA-IPI'!N13 -> 0.4667 | H13: ='MVA-IPI'!AB13 -> 0
A14: BRAZIMIL ECONÔMICA 3,0L GALÃO BRANCO NEVE | B14: ='MVA-IPI'!O14 -> 0.485 | D14: ='MVA-IPI'!B14 -> 0.485 | F14: ='MVA-IPI'!N14 -> 0.4667 | H14: ='MVA-IPI'!AB14 -> 0
A15: BRAZIMIL ECONÔMICA 3,0L GALÃO COR | B15: ='MVA-IPI'!O15 -> 0.485 | D15: ='MVA-IPI'!B15 -> 0.485 | F15: ='MVA-IPI'!N15 -> 0.4667 | H15: ='MVA-IPI'!AB15 -> 0
A16: BRAZIMIL ECONÔMICA 15L
A17: BRAZIMIL ECONÔMICA 15L PPQ BRANCO NEVE | B17: ='MVA-IPI'!O17 -> 0.485 | D17: ='MVA-IPI'!B17 -> 0.485 | F17: ='MVA-IPI'!N17 -> 0.4667 | H17: ='MVA-IPI'!AB17 -> 0
A18: BRAZIMIL ECONÔMICA 12L BALDE BRANCO NEVE | B18: ='MVA-IPI'!O18 -> 0.485 | D18: ='MVA-IPI'!B18 -> 0.485 | F18: ='MVA-IPI'!N18 -> 0.4667 | H18: ='MVA-IPI'!AB18 -> 0
A19: BRAZIMIL ECONÔMICA 15L BALDE BRANCO NEVE | B19: ='MVA-IPI'!O19 -> 0.485 | D19: ='MVA-IPI'!B19 -> 0.485 | F19: ='MVA-IPI'!N19 -> 0.4667 | H19: ='MVA-IPI'!AB19 -> 0
A20: BRAZIMIL ECONÔMICA 15L BALDE COR | B20: ='MVA-IPI'!O20 -> 0.485 | D20: ='MVA-IPI'!B20 -> 0.485 | F20: ='MVA-IPI'!N20 -> 0.4667 | H20: ='MVA-IPI'!AB20 -> 0
A21: BRAZIMIL EXTERNA 3,0L
A22: BRAZIMIL EXTERNA 3,0L BALDE BRANCO NEVE | B22: ='MVA-IPI'!O22 -> 0.485 | D22: ='MVA-IPI'!B22 -> 0.485 | F22: ='MVA-IPI'!N22 -> 0.4667 | H22: ='MVA-IPI'!AB22 -> 0
A23: BRAZIMIL EXTERNA 3,0L BALDE COR | B23: ='MVA-IPI'!O23 -> 0.485 | D23: ='MVA-IPI'!B23 -> 0.485 | F23: ='MVA-IPI'!N23 -> 0.4667 | H23: ='MVA-IPI'!AB23 -> 0
A24: BRAZIMIL EXTERNA 15L
A25: BRAZIMIL EXTERNA 15L BALDE BRANCO NEVE | B25: ='MVA-IPI'!O25 -> 0.485 | D25: ='MVA-IPI'!B25 -> 0.485 | F25: ='MVA-IPI'!N25 -> 0.4667 | H25: ='MVA-IPI'!AB25 -> 0
A26: BRAZIMIL EXTERNA 15L BALDE COR | B26: ='MVA-IPI'!O26 -> 0.485 | D26: ='MVA-IPI'!B26 -> 0.485 | F26: ='MVA-IPI'!N26 -> 0.4667 | H26: ='MVA-IPI'!AB26 -> 0
A27: BRAZIMIL SEMI BRILHO 3,0L
A28: BRAZIMIL SEMI BRILHO 3,0L BALDE BRANCO NEVE | B28: ='MVA-IPI'!O28 -> 0.485 | D28: ='MVA-IPI'!B28 -> 0.485 | F28: ='MVA-IPI'!N28 -> 0.4667 | H28: ='MVA-IPI'!AB28 -> 0
A29: BRAZIMIL SEMI BRILHO 3,0L BALDE COR | B29: ='MVA-IPI'!O29 -> 0.485 | D29: ='MVA-IPI'!B29 -> 0.485 | F29: ='MVA-IPI'!N29 -> 0.4667 | H29: ='MVA-IPI'!AB29 -> 0
A30: BRAZIMIL SEMI BRILHO 15L
A31: BRAZIMIL SEMI BRILHO 12L BALDE BRANCO NEVE | B31: ='MVA-IPI'!O31 -> 0.485 | D31: ='MVA-IPI'!B31 -> 0.485 | F31: ='MVA-IPI'!N31 -> 0.4667 | H31: ='MVA-IPI'!AB31 -> 0
A32: BRAZIMIL SEMI BRILHO 15L BALDE BRANCO NEVE | B32: ='MVA-IPI'!O32 -> 0.485 | D32: ='MVA-IPI'!B32 -> 0.485 | F32: ='MVA-IPI'!N32 -> 0.4667 | H32: ='MVA-IPI'!AB32 -> 0
A33: BRAZIMIL SEMI BRILHO 15L BALDE COR | B33: ='MVA-IPI'!O33 -> 0.485 | D33: ='MVA-IPI'!B33 -> 0.485 | F33: ='MVA-IPI'!N33 -> 0.4667 | H33: ='MVA-IPI'!AB33 -> 0
A34: BRAZIMIL TINTA PISO 3,0L
A35: BRAZIMIL TINTA PISO 3,0L BALDE BRANCO NEVE | B35: ='MVA-IPI'!O35 -> 0.485 | D35: ='MVA-IPI'!B35 -> 0.485 | F35: ='MVA-IPI'!N35 -> 0.4667 | H35: ='MVA-IPI'!AB35 -> 0
A36: BRAZIMIL TINTA PISO 3,0L BALDE COR | B36: ='MVA-IPI'!O36 -> 0.485 | D36: ='MVA-IPI'!B36 -> 0.485 | F36: ='MVA-IPI'!N36 -> 0.4667 | H36: ='MVA-IPI'!AB36 -> 0
A37: BRAZIMIL TINTA PISO 15L
A38: BRAZIMIL TINTA PISO 15L BALDE BRANCO NEVE | B38: ='MVA-IPI'!O38 -> 0.485 | D38: ='MVA-IPI'!B38 -> 0.485 | F38: ='MVA-IPI'!N38 -> 0.4667 | H38: ='MVA-IPI'!AB38 -> 0
A39: BRAZIMIL TINTA PISO 15L BALDE COR | B39: ='MVA-IPI'!O39 -> 0.485 | D39: ='MVA-IPI'!B39 -> 0.485 | F39: ='MVA-IPI'!N39 -> 0.4667 | H39: ='MVA-IPI'!AB39 -> 0
A40: BRAZIMIL SELADOR ACRIL 3,0L
A41: BRAZIMIL SELADOR ACRIL 3,0L REFIL PIGMENTADO | B41: ='MVA-IPI'!O41 -> 0.485 | D41: ='MVA-IPI'!B41 -> 0.485 | F41: ='MVA-IPI'!N41 -> 0.4667 | H41: ='MVA-IPI'!AB41 -> 0
A42: BRAZIMIL SELADOR ACRIL 3,0L BALDE PIGMENTADO | B42: ='MVA-IPI'!O42 -> 0.485 | D42: ='MVA-IPI'!B42 -> 0.485 | F42: ='MVA-IPI'!N42 -> 0.4667 | H42: ='MVA-IPI'!AB42 -> 0
A43: BRAZIMIL SELADOR ACRIL 15L
A44: BRAZIMIL SELADOR ACRIL 12L PIGMENTADO | B44: ='MVA-IPI'!O44 -> 0.485 | D44: ='MVA-IPI'!B44 -> 0.485 | F44: ='MVA-IPI'!N44 -> 0.4667 | H44: ='MVA-IPI'!AB44 -> 0
A45: BRAZIMIL SELADOR ACRIL 15L BALDE PIGMENTADO | B45: ='MVA-IPI'!O45 -> 0.485 | D45: ='MVA-IPI'!B45 -> 0.485 | F45: ='MVA-IPI'!N45 -> 0.4667 | H45: ='MVA-IPI'!AB45 -> 0
A46: LIQUIBRILHO 3,0L
A47: LIQUIBRILHO 3,0L BALDE INCOLOR | B47: ='MVA-IPI'!O47 -> 0.485 | D47: ='MVA-IPI'!B47 -> 0.485 | F47: ='MVA-IPI'!N47 -> 0.4667 | H47: ='MVA-IPI'!AB47 -> 0
A48: LIQUIBRILHO 15L
...

Sheet MVA-IPI
A2: ICMS - ALIQUOTA PB | B2: =B138 -> 0.12 | C2: =C138 -> 0.12 | D2: =D138 -> 0.12 | E2: =E138 -> 0.12 | F2: =F138 -> 0.12 | G2: =G138 -> 0.12 | H2: =H138 -> 0.12 | I2: =I138 -> 0.12 | ... AB2: =AB138 -> 0.12
A3: ICMS ST - ALIQ. INTERNA DE CADA ESTADO | B3: =B139 -> 0.2 | C3: =C139 -> 0.19 | D3: =D139 -> 0.19 | E3: =E139 -> 0.2 | F3: =F139 -> 0.205 | G3: =G139 -> 0.205 | H3: =H139 -> 0.18 | I3: =I139 -> 0.17 | ... AB3: =AB139 -> 0.2
B7: MVA - MARGEM DE VALOR AGREGADO - %
A9: Produto / Estados Destino | B9: CE | C9: AC | D9: AL | E9: AM | F9: AP | G9: BA | H9: DF | I9: ES | J9: GO | K9: MA | L9: MT | M9: MS | N9: PA | O9: PB | P9: PE | Q9: PI | R9: RN | S9: RS | T9: RR | U9: RO | V9: SC | W9: SE | X9: TO | Y9: MG | Z9: PR | AA9: SP | AB9: RJ
A10: TINTAS BASE ÁGUA | B10: G1 | D10: G2 | E10: G2 | F10: G2 | G10: G2 | K10: G2 | N10: G3 | O10: G2 | P10: G2 | Q10: G2 | R10: G2 | T10: G3 | X10: G2 | AD10: Alíquota IPI
A11: BRAZIMIL ECONOMICA 3,0L
A12: BRAZIMIL ECONÔMICA 3,0L REFIL BRANCO NEVE | B12: 0.485 | D12: 0.4667 | E12: 0.485 | F12: 0.4943 | G12: 0.4943 | K12: 0.5231 | N12: 0.4667 | O12: 0.485 | P12: 0.4943 | Q12: 0.5038 | R12: 0.4488 | T12: 0.4314 | X12: 0.4488 | AD12: 0
A13: BRAZIMIL ECONÔMICA 3,0L REFIL COR | B13: 0.485 | D13: 0.4667 | E13: 0.485 | F13: 0.4943 | G13: 0.4943 | K13: 0.5231 | N13: 0.4667 | O13: 0.485 | P13: 0.4943 | Q13: 0.5038 | R13: 0.4488 | T13: 0.4314 | X13: 0.4488 | AD13: 0
A14: BRAZIMIL ECONÔMICA 3,0L GALÃO BRANCO NEVE | B14: 0.485 | D14: 0.4667 | E14: 0.485 | F14: 0.4943 | G14: 0.4943 | K14: 0.5231 | N14: 0.4667 | O14: 0.485 | P14: 0.4943 | Q14: 0.5038 | R14: 0.4488 | T14: 0.4314 | X14: 0.4488 | AD14: 0
A15: BRAZIMIL ECONÔMICA 3,0L GALÃO COR | B15: 0.485 | D15: 0.4667 | E15: 0.485 | F15: 0.4943 | G15: 0.4943 | K15: 0.5231 | N15: 0.4667 | O15: 0.485 | P15: 0.4943 | Q15: 0.5038 | R15: 0.4488 | T15: 0.4314 | X15: 0.4488 | AD15: 0
A16: BRAZIMIL ECONÔMICA 15L
A17: BRAZIMIL ECONÔMICA 15L PPQ BRANCO NEVE | B17: 0.485 | D17: 0.4667 | E17: 0.485 | F17: 0.4943 | G17: 0.4943 | K17: 0.5231 | N17: 0.4667 | O17: 0.485 | P17: 0.4943 | Q17: 0.5038 | R17: 0.4488 | T17: 0.4314 | X17: 0.4488 | AD17: 0
A18: BRAZIMIL ECONÔMICA 12L BALDE BRANCO NEVE | B18: 0.485 | D18: 0.4667 | E18: 0.485 | F18: 0.4943 | G18: 0.4943 | K18: 0.5231 | N18: 0.4667 | O18: 0.485 | P18: 0.4943 | Q18: 0.5038 | R18: 0.4488 | T18: 0.4314 | X18: 0.4488 | AD18: 0
A19: BRAZIMIL ECONÔMICA 15L BALDE BRANCO NEVE | B19: 0.485 | D19: 0.4667 | E19: 0.485 | F19: 0.4943 | G19: 0.4943 | K19: 0.5231 | N19: 0.4667 | O19: 0.485 | P19: 0.4943 | Q19: 0.5038 | R19: 0.4488 | T19: 0.4314 | X19: 0.4488 | AD19: 0
A20: BRAZIMIL ECONÔMICA 15L BALDE COR | B20: 0.485 | D20: 0.4667 | E20: 0.485 | F20: 0.4943 | G20: 0.4943 | K20: 0.5231 | N20: 0.4667 | O20: 0.485 | P20: 0.4943 | Q20: 0.5038 | R20: 0.4488 | T20: 0.4314 | X20: 0.4488 | AD20: 0
A21: BRAZIMIL EXTERNA 3,0L
A22: BRAZIMIL EXTERNA 3,0L BALDE BRANCO NEVE | B22: 0.485 | D22: 0.4667 | E22: 0.485 | F22: 0.4943 | G22: 0.4943 | K22: 0.5231 | N22: 0.4667 | O22: 0.485 | P22: 0.4943 | Q22: 0.5038 | R22: 0.4488 | T22: 0.4314 | X22: 0.4488 | AD22: 0
A23: BRAZIMIL EXTERNA 3,0L BALDE COR | B23: 0.485 | D23: 0.4667 | E23: 0.485 | F23: 0.4943 | G23: 0.4943 | K23: 0.5231 | N23: 0.4667 | O23: 0.485 | P23: 0.4943 | Q23: 0.5038 | R23: 0.4488 | T23: 0.4314 | X23: 0.4488 | AD23: 0
A24: BRAZIMIL EXTERNA 15L
A25: BRAZIMIL EXTERNA 15L BALDE BRANCO NEVE | B25: 0.485 | D25: 0.4667 | E25: 0.485 | F25: 0.4943 | G25: 0.4943 | K25: 0.5231 | N25: 0.4667 | O25: 0.485 | P25: 0.4943 | Q25: 0.5038 | R25: 0.4488 | T25: 0.4314 | X25: 0.4488 | AD25: 0
A26: BRAZIMIL EXTERNA 15L BALDE COR | B26: 0.485 | D26: 0.4667 | E26: 0.485 | F26: 0.4943 | G26: 0.4943 | K26: 0.5231 | N26: 0.4667 | O26: 0.485 | P26: 0.4943 | Q26: 0.5038 | R26: 0.4488 | T26: 0.4314 | X26: 0.4488 | AD26: 0
A27: BRAZIMIL SEMI BRILHO 3,0L
A28: BRAZIMIL SEMI BRILHO 3,0L BALDE BRANCO NEVE | B28: 0.485 | D28: 0.4667 | E28: 0.485 | F28: 0.4943 | G28: 0.4943 | K28: 0.5231 | N28: 0.4667 | O28: 0.485 | P28: 0.4943 | Q28: 0.5038 | R28: 0.4488 | T28: 0.4314 | X28: 0.4488 | AD28: 0
A29: BRAZIMIL SEMI BRILHO 3,0L BALDE COR | B29: 0.485 | D29: 0.4667 | E29: 0.485 | F29: 0.4943 | G29: 0.4943 | K29: 0.5231 | N29: 0.4667 | O29: 0.485 | P29: 0.4943 | Q29: 0.5038 | R29: 0.4488 | T29: 0.4314 | X29: 0.4488 | AD29: 0
A30: BRAZIMIL SEMI BRILHO 15L
A31: BRAZIMIL SEMI BRILHO 12L BALDE BRANCO NEVE | B31: 0.485 | D31: 0.4667 | E31: 0.485 | F31: 0.4943 | G31: 0.4943 | K31: 0.5231 | N31: 0.4667 | O31: 0.485 | P31: 0.4943 | Q31: 0.5038 | R31: 0.4488 | T31: 0.4314 | X31: 0.4488 | AD31: 0
A32: BRAZIMIL SEMI BRILHO 15L BALDE BRANCO NEVE | B32: 0.485 | D32: 0.4667 | E32: 0.485 | F32: 0.4943 | G32: 0.4943 | K32: 0.5231 | N32: 0.4667 | O32: 0.485 | P32: 0.4943 | Q32: 0.5038 | R32: 0.4488 | T32: 0.4314 | X32: 0.4488 | AD32: 0
A33: BRAZIMIL SEMI BRILHO 15L BALDE COR | B33: 0.485 | D33: 0.4667 | E33: 0.485 | F33: 0.4943 | G33: 0.4943 | K33: 0.5231 | N33: 0.4667 | O33: 0.485 | P33: 0.4943 | Q33: 0.5038 | R33: 0.4488 | T33: 0.4314 | X33: 0.4488 | AD33: 0
A34: BRAZIMIL TINTA PISO 3,0L
A35: BRAZIMIL TINTA PISO 3,0L BALDE BRANCO NEVE | B35: 0.485 | D35: 0.4667 | E35: 0.485 | F35: 0.4943 | G35: 0.4943 | K35: 0.5231 | N35: 0.4667 | O35: 0.485 | P35: 0.4943 | Q35: 0.5038 | R35: 0.4488 | T35: 0.4314 | X35: 0.4488 | AD35: 0
A36: BRAZIMIL TINTA PISO 3,0L BALDE COR | B36: 0.485 | D36: 0.4667 | E36: 0.485 | F36: 0.4943 | G36: 0.4943 | K36: 0.5231 | N36: 0.4667 | O36: 0.485 | P36: 0.4943 | Q36: 0.5038 | R36: 0.4488 | T36: 0.4314 | X36: 0.4488 | AD36: 0
A37: BRAZIMIL TINTA PISO 15L
A38: BRAZIMIL TINTA PISO 15L BALDE BRANCO NEVE | B38: 0.485 | D38: 0.4667 | E38: 0.485 | F38: 0.4943 | G38: 0.4943 | K38: 0.5231 | N38: 0.4667 | O38: 0.485 | P38: 0.4943 | Q38: 0.5038 | R38: 0.4488 | T38: 0.4314 | X38: 0.4488 | AD38: 0
A39: BRAZIMIL TINTA PISO 15L BALDE COR | B39: 0.485 | D39: 0.4667 | E39: 0.485 | F39: 0.4943 | G39: 0.4943 | K39: 0.5231 | N39: 0.4667 | O39: 0.485 | P39: 0.4943 | Q39: 0.5038 | R39: 0.4488 | T39: 0.4314 | X39: 0.4488 | AD39: 0
A40: BRAZIMIL SELADOR ACRIL 3,0L
A41: BRAZIMIL SELADOR ACRIL 3,0L REFIL PIGMENTADO | B41: 0.485 | D41: 0.4667 | E41: 0.485 | F41: 0.4943 | G41: 0.4943 | K41: 0.5231 | N41: 0.4667 | O41: 0.485 | P41: 0.4943 | Q41: 0.5038 | R41: 0.4488 | T41: 0.4314 | X41: 0.4488 | AD41: 0
A42: BRAZIMIL SELADOR ACRIL 3,0L BALDE PIGMENTADO | B42: 0.485 | D42: 0.4667 | E42: 0.485 | F42: 0.4943 | G42: 0.4943 | K42: 0.5231 | N42: 0.4667 | O42: 0.485 | P42: 0.4943 | Q42: 0.5038 | R42: 0.4488 | T42: 0.4314 | X42: 0.4488 | AD42: 0
A43: BRAZIMIL SELADOR ACRIL 15L
A44: BRAZIMIL SELADOR ACRIL 12L PIGMENTADO | B44: 0.485 | D44: 0.4667 | E44: 0.485 | F44: 0.4943 | G44: 0.4943 | K44: 0.5231 | N44: 0.4667 | O44: 0.485 | P44: 0.4943 | Q44: 0.5038 | R44: 0.4488 | T44: 0.4314 | X44: 0.4488 | AD44: 0
A45: BRAZIMIL SELADOR ACRIL 15L BALDE PIGMENTADO | B45: 0.485 | D45: 0.4667 | E45: 0.485 | F45: 0.4943 | G45: 0.4943 | K45: 0.5231 | N45: 0.4667 | O45: 0.485 | P45: 0.4943 | Q45: 0.5038 | R45: 0.4488 | T45: 0.4314 | X45: 0.4488 | AD45: 0
...
